Workbook

Sheet Report Index
A2: Statewide Assessed Value Summary Information by County
B4: Assessed Value is the value of the property with regard to a possible Agricultural classification and any deferred amount accumulated because of Save Our Homes, Amendment 1.
B11: Assessed Value All Property Types
B13: All Property Types Assessed Value and Growth Rate
B15: Real Property Assessed Value and Growth Rate
B17: Personal Property Assessed Value and Growth Rate
B19: Centrally Assessed Property Assessed Value and Growth Rate
A25: Contact Information: | D25: Property Tax Oversight, Research & Analysis
D26: PTOResearchAnalysis@floridarevenue.com

Sheet Assessed Value All Property
A1: Assessed Value All Property Types
A2: 2026
A4: County | B4: Status | C4: 2026 Real Property Assessed Value | D4: 2026 Personal Property Assessed Value | E4: 2026 Central Assessment Assessed Value | F4: 2026 Total Assessed Value
A5: Alachua | B5: R-Prelim | C5: 34840429609 | D5: 4420026482 | E5: 35914609 | F5: 39296370700
A6: Baker | B6: R-Prelim | C6: 2280897071 | D6: 285317729 | E6: 13796624 | F6: 2580011424
A7: Bay | B7: R-Prelim | C7: 37915535497 | D7: 2687112330 | E7: 30583860 | F7: 40633231687
A8: Bradford | B8: R-Prelim | C8: 1851307814 | D8: 348512026 | E8: 20294348 | F8: 2220114188
A9: Brevard | B9: R-Prelim | C9: 92163188590 | D9: 12792815435 | E9: 134785621 | F9: 105090789646
A10: Broward | B10: R-Prelim | C10: 378586860070 | D10: 13381973237 | E10: 104719059 | F10: 392073552366
A11: Calhoun | B11: R-Prelim | C11: 730395719 | D11: 886504405 | F11: 1616900124
A12: Charlotte | B12: R-Prelim | C12: 40183752392 | D12: 2206355616 | E12: 2958202 | F12: 42393066210
A13: Citrus | B13: R-Prelim | C13: 19717975270 | D13: 2384961559 | E13: 1459025 | F13: 22104395854
A14: Clay | B14: R-Prelim | C14: 25898656441 | D14: 2378488822 | E14: 36001517 | F14: 28313146780
A15: Collier | B15: R-Prelim | C15: 181550237942 | D15: 3895364601 | E15: 224358 | F15: 185445826901
A16: Columbia | B16: R-Prelim | C16: 5785452953 | D16: 1151156244 | E16: 13665893 | F16: 6950275090
A17: Miami-Dade | B17: R-Prelim | C17: 586005952029 | D17: 25121633877 | E17: 195617719 | F17: 611323203625
A18: DeSoto | B18: R-Prelim | C18: 3012243129 | D18: 830779663 | E18: 4733310 | F18: 3847756102
A19: Dixie | B19: R-Prelim | C19: 1142813789 | D19: 138064684 | F19: 1280878473
A20: Duval | B20: R-Prelim | C20: 142728331498 | D20: 18605156425 | E20: 226994435 | F20: 161560482358
A21: Escambia | B21: R-Prelim | C21: 41576022532 | D21: 4892160437 | E21: 34168910 | F21: 46502351879
A22: Flagler | B22: R-Prelim | C22: 22015828532 | D22: 1146613952 | E22: 23937098 | F22: 23186379582
A23: Franklin | B23: R-Prelim | C23: 5179998053 | D23: 105478236 | F23: 5285476289
A24: Gadsden | B24: R-Prelim | C24: 2738232151 | D24: 984925754 | E24: 10327724 | F24: 3733485629
A25: Gilchrist | B25: R-Prelim | C25: 1548519951 | D25: 491057571 | F25: 2039577522
A26: Glades | B26: R-Prelim | C26: 2252578299 | D26: 231526004 | E26: 14421555 | F26: 2498525858
A27: Gulf | B27: R-Prelim | C27: 5067404628 | D27: 179777182 | F27: 5247181810
A28: Hamilton | B28: R-Prelim | C28: 1016942777 | D28: 704338273 | E28: 22537698 | F28: 1743818748
A29: Hardee | B29: R-Prelim | C29: 2444524955 | D29: 1244757847 | E29: 10098411 | F29: 3699381213
A30: Hendry | B30: R-Prelim | C30: 5620203574 | D30: 1905409769 | E30: 4999064 | F30: 7530612407
A31: Hernando | B31: R-Prelim | C31: 23335115777 | D31: 2556179886 | E31: 12906416 | F31: 25904202079
A32: Highlands | B32: R-Prelim | C32: 11253952758 | D32: 773819095 | E32: 35810333 | F32: 12063582186
A33: Hillsborough | B33: R-Prelim | C33: 218300966173 | D33: 14285675930 | E33: 137336207 | F33: 232723978310
A34: Holmes | B34: R-Prelim | C34: 1044471320 | D34: 144860255 | E34: 4431950 | F34: 1193763525
A35: Indian River | B35: R-Prelim | C35: 37300488983 | D35: 1613193318 | E35: 46105678 | F35: 38959787979
A36: Jackson | B36: R-Prelim | C36: 3138911563 | D36: 621876126 | E36: 27264771 | F36: 3788052460
A37: Jefferson | B37: R-Prelim | C37: 1380283256 | D37: 275524636 | E37: 3531607 | F37: 1659339499
A38: Lafayette | B38: R-Prelim | C38: 541090663 | D38: 84705720 | F38: 625796383
A39: Lake | B39: R-Prelim | C39: 56070531343 | D39: 3174722544 | E39: 5784065 | F39: 59251037952
A40: Lee | B40: R-Prelim | C40: 172297174013 | D40: 7973441775 | E40: 4978548 | F40: 180275594336
A41: Leon | B41: R-Prelim | C41: 38794904930 | D41: 2590304643 | E41: 6677452 | F41: 41391887025
...

Sheet All Property Assessed Value
A1: All Property Types Assessed Value and Growth Rate
A2: 2024-2026
A4: County | B4: Status | C4: 2026 Value | D4: Percent increase 2025-2026 | E4: 2025 Value | F4: Percent increase 2024-2025 | G4: 2024 Value
A5: Alachua | B5: ='Assessed Value All Property'!B5 -> R-Prelim | C5: 39296370700 | D5: =((C5-E5)/E5) -> 0.053112855 | E5: 37314491519 | F5: =((E5-G5)/G5) -> 0.053994899 | G5: 35402914727
A6: Baker | B6: ='Assessed Value All Property'!B6 -> R-Prelim | C6: 2580011424 | D6: =((C6-E6)/E6) -> 0.037404321 | E6: 2486987351 | F6: =((E6-G6)/G6) -> 0.077484423 | G6: 2308142279
A7: Bay | B7: ='Assessed Value All Property'!B7 -> R-Prelim | C7: 40633231687 | D7: =((C7-E7)/E7) -> 0.056918963 | E7: 38444983126 | F7: =((E7-G7)/G7) -> 0.075408109 | G7: 35749203299
A8: Bradford | B8: ='Assessed Value All Property'!B8 -> R-Prelim | C8: 2220114188 | D8: =((C8-E8)/E8) -> 0.05366055 | E8: 2107048791 | F8: =((E8-G8)/G8) -> 0.078376651 | G8: 1953908024
A9: Brevard | B9: ='Assessed Value All Property'!B9 -> R-Prelim | C9: 105090789646 | D9: =((C9-E9)/E9) -> 0.045970358 | E9: 100472053371 | F9: =((E9-G9)/G9) -> 0.070368125 | G9: 93866821187
A10: Broward | B10: ='Assessed Value All Property'!B10 -> R-Prelim | C10: 392073552366 | D10: =((C10-E10)/E10) -> 0.054235903 | E10: 371903054375 | F10: =((E10-G10)/G10) -> 0.11348315 | G10: 333999713697
A11: Calhoun | B11: ='Assessed Value All Property'!B11 -> R-Prelim | C11: 1616900124 | D11: =((C11-E11)/E11) -> 0.35997848 | E11: 1188915963 | F11: =((E11-G11)/G11) -> 0.13878464 | G11: 1044021774
A12: Charlotte | B12: ='Assessed Value All Property'!B12 -> R-Prelim | C12: 42393066210 | D12: =((C12-E12)/E12) -> 0.030511154 | E12: 41137901361 | F12: =((E12-G12)/G12) -> 0.075692571 | G12: 38243176981
A13: Citrus | B13: ='Assessed Value All Property'!B13 -> R-Prelim | C13: 22104395854 | D13: =((C13-E13)/E13) -> 0.06662086 | E13: 20723761077 | F13: =((E13-G13)/G13) -> 0.071461083 | G13: 19341590095
A14: Clay | B14: ='Assessed Value All Property'!B14 -> R-Prelim | C14: 28313146780 | D14: =((C14-E14)/E14) -> 0.05835366 | E14: 26752065821 | F14: =((E14-G14)/G14) -> 0.085935228 | G14: 24635047405
A15: Collier | B15: ='Assessed Value All Property'!B15 -> R-Prelim | C15: 185445826901 | D15: =((C15-E15)/E15) -> 0.035836921 | E15: 179029944985 | F15: =((E15-G15)/G15) -> 0.079605897 | G15: 165828980249
A16: Columbia | B16: ='Assessed Value All Property'!B16 -> R-Prelim | C16: 6950275090 | D16: =((C16-E16)/E16) -> 0.049527884 | E16: 6622287216 | F16: =((E16-G16)/G16) -> 0.093086975 | G16: 6058335126
... A71: Washington | B71: ='Assessed Value All Property'!B71 -> R-Prelim | C71: 2232118872 | D71: =((C71-E71)/E71) -> 0.084007645 | E71: 2059135728 | F71: =((E71-G71)/G71) -> 0.096301914 | G71: 1878256074
A73: Statewide | C73: =SUM(C5:C72) -> 4378567615183 | D73: =((C73-E73)/E73) -> 0.058578627 | E73: =SUM(E5:E72) -> 4136270564959 | F73: =((E73-G73)/G73) -> 0.078402322 | G73: =SUM(G5:G71) -> 3835554207524
A75: Data Extract: July 2026
A77: *Escambia, Lake, Walton, Taylor, and Sumter 2026 All Property Assessed Value has been administratively updated

Sheet Real Property Assessed Value
A1: Real Property Assessed Value and Growth Rate
A2: 2024-2026
A4: County | B4: Status | C4: 2026 Value | D4: Percent increase 2025-2026 | E4: 2025 Value | F4: Percent increase 2024-2025 | G4: 2024 Value
A5: Alachua | B5: ='Assessed Value All Property'!B5 -> R-Prelim | C5: 34840429609 | D5: =((C5-E5)/E5) -> 0.056432374 | E5: 32979327861 | F5: =((E5-G5)/G5) -> 0.061655013 | G5: 31064072104
A6: Baker | B6: ='Assessed Value All Property'!B6 -> R-Prelim | C6: 2280897071 | D6: =((C6-E6)/E6) -> 0.055869335 | E6: 2160207703 | F6: =((E6-G6)/G6) -> 0.064317081 | G6: 2029665540
A7: Bay | B7: ='Assessed Value All Property'!B7 -> R-Prelim | C7: 37915535497 | D7: =((C7-E7)/E7) -> 0.061803834 | E7: 35708606690 | F7: =((E7-G7)/G7) -> 0.080887566 | G7: 33036374752
A8: Bradford | B8: ='Assessed Value All Property'!B8 -> R-Prelim | C8: 1851307814 | D8: =((C8-E8)/E8) -> 0.072107705 | E8: 1726792752 | F8: =((E8-G8)/G8) -> 0.083914662 | G8: 1593107661
A9: Brevard | B9: ='Assessed Value All Property'!B9 -> R-Prelim | C9: 92163188590 | D9: =((C9-E9)/E9) -> 0.053856077 | E9: 87453297050 | F9: =((E9-G9)/G9) -> 0.072761156 | G9: 81521685010
A10: Broward | B10: ='Assessed Value All Property'!B10 -> R-Prelim | C10: 378586860070 | D10: =((C10-E10)/E10) -> 0.054637289 | E10: 358973520020 | F10: =((E10-G10)/G10) -> 0.075132821 | G10: 333887602420
A11: Calhoun | B11: ='Assessed Value All Property'!B11 -> R-Prelim | C11: 730395719 | D11: =((C11-E11)/E11) -> 0.082769193 | E11: 674562708 | F11: =((E11-G11)/G11) -> 0.040635128 | G11: 648222119
A12: Charlotte | B12: ='Assessed Value All Property'!B12 -> R-Prelim | C12: 40183752392 | D12: =((C12-E12)/E12) -> 0.028366075 | E12: 39075338417 | F12: =((E12-G12)/G12) -> 0.075398986 | G12: 36335666042
A13: Citrus | B13: ='Assessed Value All Property'!B13 -> R-Prelim | C13: 19717975270 | D13: =((C13-E13)/E13) -> 0.067538152 | E13: 18470511093 | F13: =((E13-G13)/G13) -> 0.072042905 | G13: 17229264803
A14: Clay | B14: ='Assessed Value All Property'!B14 -> R-Prelim | C14: 25898656441 | D14: =((C14-E14)/E14) -> 0.060394658 | E14: 24423601381 | F14: =((E14-G14)/G14) -> 0.088268368 | G14: 22442627291
A15: Collier | B15: ='Assessed Value All Property'!B15 -> R-Prelim | C15: 181550237942 | D15: =((C15-E15)/E15) -> 0.034583519 | E15: 175481471235 | F15: =((E15-G15)/G15) -> 0.080340287 | G15: 162431664641
A16: Columbia | B16: ='Assessed Value All Property'!B16 -> R-Prelim | C16: 5785452953 | D16: =((C16-E16)/E16) -> 0.065539683 | E16: 5429598771 | F16: =((E16-G16)/G16) -> 0.069891983 | G16: 5074903687
... A71: Washington | B71: ='Assessed Value All Property'!B71 -> R-Prelim | C71: 1851230989 | D71: =((C71-E71)/E71) -> 0.07299902 | E71: 1725286747 | F71: =((E71-G71)/G71) -> 0.10334894 | G71: 1563681884
A73: Statewide | C73: =SUM(C5:C72) -> 4120116389247 | D73: =((C73-E73)/E73) -> 0.059047707 | E73: =SUM(E5:E72) -> 3890397348002 | F73: =((E73-G73)/G73) -> 0.076772427 | G73: =SUM(G5:G72) -> 3613017244329
A75: Data Extract: July 2026
A77: *Escambia 2026 Real Property Assessed Value has been administratively updated

Sheet Personal Prop Assessed Value
A1: Personal Property Assessed Value and Growth Rate
A2: 2024-2026
A4: County | B4: Status | C4: 2026 Value | D4: Percent increase 2025-2026 | E4: 2025 Value | F4: Percent increase 2024-2025 | G4: 2024 Value
A5: Alachua | B5: ='Assessed Value All Property'!B5 -> R-Prelim | C5: 4420026482 | D5: =((C5-E5)/E5) -> 0.028065054 | E5: 4299364583 | F5: =((E5-G5)/G5) -> -0.0012221177 | G5: 4304625342
A6: Baker | B6: ='Assessed Value All Property'!B6 -> R-Prelim | C6: 285317729 | D6: =((C6-E6)/E6) -> -0.091285702 | E6: 313979575 | F6: =((E6-G6)/G6) -> 0.19350496 | G6: 263073540
A7: Bay | B7: ='Assessed Value All Property'!B7 -> R-Prelim | C7: 2687112330 | D7: =((C7-E7)/E7) -> -0.0077993848 | E7: 2708234896 | F7: =((E7-G7)/G7) -> 0.011280839 | G7: 2678024533
A8: Bradford | B8: ='Assessed Value All Property'!B8 -> R-Prelim | C8: 348512026 | D8: =((C8-E8)/E8) -> -0.032602014 | E8: 360257134 | F8: =((E8-G8)/G8) -> 0.054366253 | G8: 341681207
A9: Brevard | B9: ='Assessed Value All Property'!B9 -> R-Prelim | C9: 12792815435 | D9: =((C9-E9)/E9) -> -0.0062211712 | E9: 12872899950 | F9: =((E9-G9)/G9) -> 0.055283089 | G9: 12198527654
A10: Broward | B10: ='Assessed Value All Property'!B10 -> R-Prelim | C10: 13381973237 | D10: =((C10-E10)/E10) -> 0.044176741 | E10: 12815812408 | F10: =((E10-G10)/G10) -> 0.056417264 | G10: 12131392439
A11: Calhoun | B11: ='Assessed Value All Property'!B11 -> R-Prelim | C11: 886504405 | D11: =((C11-E11)/E11) -> 0.72353222 | E11: 514353255 | F11: =((E11-G11)/G11) -> 0.29952932 | G11: 395799655
A12: Charlotte | B12: ='Assessed Value All Property'!B12 -> R-Prelim | C12: 2206355616 | D12: =((C12-E12)/E12) -> 0.071374004 | E12: 2059370124 | F12: =((E12-G12)/G12) -> 0.081433809 | G12: 1904296044
A13: Citrus | B13: ='Assessed Value All Property'!B13 -> R-Prelim | C13: 2384961559 | D13: =((C13-E13)/E13) -> 0.059249935 | E13: 2251556955 | F13: =((E13-G13)/G13) -> 0.06672723 | G13: 2110714803
A14: Clay | B14: ='Assessed Value All Property'!B14 -> R-Prelim | C14: 2378488822 | D14: =((C14-E14)/E14) -> 0.036769374 | E14: 2294134917 | F14: =((E14-G14)/G14) -> 0.054752836 | G14: 2175045034
A15: Collier | B15: ='Assessed Value All Property'!B15 -> R-Prelim | C15: 3895364601 | D15: =((C15-E15)/E15) -> 0.097824626 | E15: 3548257627 | F15: =((E15-G15)/G15) -> 0.044493408 | G15: 3397108683
A16: Columbia | B16: ='Assessed Value All Property'!B16 -> R-Prelim | C16: 1151156244 | D16: =((C16-E16)/E16) -> -0.024462106 | E16: 1180022069 | F16: =((E16-G16)/G16) -> 0.21915206 | G16: 967903933
... A71: Washington | B71: ='Assessed Value All Property'!B71 -> R-Prelim | C71: 378513165 | D71: =((C71-E71)/E71) -> 0.14141863 | E71: 331616425 | F71: =((E71-G71)/G71) -> 0.061284849 | G71: 312466936
A73: Statewide | C73: =SUM(C5:C71) -> 256224652932 | D73: =((C73-E73)/E73) -> 0.051886512 | E73: =SUM(E5:E71) -> 243585833539 | F73: =((E73-G73)/G73) -> 0.048145852 | G73: =SUM(G5:G71) -> 232396887315
A75: Data Extract: July 2026
A77: *Lake, Walton, Taylor, and Sumter 2026 Personal Property Assessed Value has been administratively updated

Sheet Centrally Prop Assessed Value 
A1: Centrally Assessed Property Assessed Value and Growth Rate
A2: 2024-2026
A4: County | B4: Status | C4: 2026 Value | D4: Percent increase 2025-2026 | E4: 2025 Value | F4: Percent increase 2024-2025 | G4: 2024 Value
A5: Alachua | B5: ='Assessed Value All Property'!B5 -> R-Prelim | C5: 35914609 | D5: =((C5-E5)/E5) -> 0.0032272901 | E5: 35799075 | F5: =((E5-G5)/G5) -> 0.046227928 | G5: 34217281
A6: Baker | B6: ='Assessed Value All Property'!B6 -> R-Prelim | C6: 13796624 | D6: =((C6-E6)/E6) -> 0.077855103 | E6: 12800073 | F6: =((E6-G6)/G6) -> -0.16899905 | G6: 15403199
A7: Bay | B7: ='Assessed Value All Property'!B7 -> R-Prelim | C7: 30583860 | D7: =((C7-E7)/E7) -> 0.086787006 | E7: 28141540 | F7: =((E7-G7)/G7) -> -0.19142832 | G7: 34804014
A8: Bradford | B8: ='Assessed Value All Property'!B8 -> R-Prelim | C8: 20294348 | D8: =((C8-E8)/E8) -> 0.014772959 | E8: 19998905 | F8: =((E8-G8)/G8) -> 0.046014008 | G8: 19119156
A9: Brevard | B9: ='Assessed Value All Property'!B9 -> R-Prelim | C9: 134785621 | D9: =((C9-E9)/E9) -> -0.075901724 | E9: 145856371 | F9: =((E9-G9)/G9) -> -0.0051303429 | G9: 146608523
A10: Broward | B10: ='Assessed Value All Property'!B10 -> R-Prelim | C10: 104719059 | D10: =((C10-E10)/E10) -> -0.079165792 | E10: 113721947 | F10: =((E10-G10)/G10) -> 0.014366708 | G10: 112111277
A11: Calhoun | B11: ='Assessed Value All Property'!B11 -> R-Prelim | D11: n/a | F11: n/a
A12: Charlotte | B12: ='Assessed Value All Property'!B12 -> R-Prelim | C12: 2958202 | D12: =((C12-E12)/E12) -> -0.073483002 | E12: 3192820 | F12: =((E12-G12)/G12) -> -0.0068664762 | G12: 3214895
A13: Citrus | B13: ='Assessed Value All Property'!B13 -> R-Prelim | C13: 1459025 | D13: =((C13-E13)/E13) -> -0.13821618 | E13: 1693029 | F13: =((E13-G13)/G13) -> 0.051251514 | G13: 1610489
A14: Clay | B14: ='Assessed Value All Property'!B14 -> R-Prelim | C14: 36001517 | D14: =((C14-E14)/E14) -> 0.04870426 | E14: 34329523 | F14: =((E14-G14)/G14) -> 0.97579079 | G14: 17375080
A15: Collier | B15: ='Assessed Value All Property'!B15 -> R-Prelim | C15: 224358 | D15: =((C15-E15)/E15) -> 0.038103302 | E15: 216123 | F15: =((E15-G15)/G15) -> 0.044450888 | G15: 206925
A16: Columbia | B16: ='Assessed Value All Property'!B16 -> R-Prelim | C16: 13665893 | D16: =((C16-E16)/E16) -> 0.078911048 | E16: 12666376 | F16: =((E16-G16)/G16) -> -0.18426204 | G16: 15527506
A17: Miami-Dade | B17: ='Assessed Value All Property'!B17 -> R-Prelim | C17: 195617719 | D17: =((C17-E17)/E17) -> -0.089132896 | E17: 214759890 | F17: =((E17-G17)/G17) -> 0.0033290396 | G17: 214047318
A18: DeSoto | B18: ='Assessed Value All Property'!B18 -> R-Prelim | C18: 4733310 | D18: =((C18-E18)/E18) -> -0.022656651 | E18: 4843037 | F18: =((E18-G18)/G18) -> 0.014442552 | G18: 4774087
A19: Dixie | B19: ='Assessed Value All Property'!B19 -> R-Prelim | D19: n/a | F19: n/a
A20: Duval | B20: ='Assessed Value All Property'!B20 -> R-Prelim | C20: 226994435 | D20: =((C20-E20)/E20) -> 0.02026915 | E20: 222484856 | F20: =((E20-G20)/G20) -> 0.014557303 | G20: 219292548
A21: Escambia | B21: ='Assessed Value All Property'!B21 -> R-Prelim | C21: 34168910 | D21: =((C21-E21)/E21) -> 0.002758216 | E21: 34074924 | F21: =((E21-G21)/G21) -> 0.042162295 | G21: 32696370
A22: Flagler | B22: ='Assessed Value All Property'!B22 -> R-Prelim | C22: 23937098 | D22: =((C22-E22)/E22) -> -0.0095190798 | E22: 24167147 | F22: =((E22-G22)/G22) -> -0.018043399 | G22: 24611217
A23: Franklin | B23: ='Assessed Value All Property'!B23 -> R-Prelim | D23: n/a | E23: 0 | F23: =((E23-G23)/G23) -> -1 | G23: 689947
A24: Gadsden | B24: ='Assessed Value All Property'!B24 -> R-Prelim | C24: 10327724 | D24: =((C24-E24)/E24) -> 0.07076918 | E24: 9645145 | F24: =((E24-G24)/G24) -> 0.141579 | G24: 8448951
A25: Gilchrist | B25: ='Assessed Value All Property'!B25 -> R-Prelim | D25: n/a | F25: n/a
A26: Glades | B26: ='Assessed Value All Property'!B26 -> R-Prelim | C26: 14421555 | D26: =((C26-E26)/E26) -> 0.044664365 | E26: 13804965 | F26: =((E26-G26)/G26) -> -0.11513084 | G26: 15601137
A27: Gulf | B27: ='Assessed Value All Property'!B27 -> R-Prelim | D27: n/a | F27: =((E27-G27)/G27) -> -1 | G27: 593333
A28: Hamilton | B28: ='Assessed Value All Property'!B28 -> R-Prelim | C28: 22537698 | D28: =((C28-E28)/E28) -> 0.084126047 | E28: 20788817 | F28: =((E28-G28)/G28) -> -0.25345792 | G28: 27846812
A29: Hardee | B29: ='Assessed Value All Property'!B29 -> R-Prelim | C29: 10098411 | D29: =((C29-E29)/E29) -> 0.01919332 | E29: 9908239 | F29: =((E29-G29)/G29) -> 0.045112477 | G29: 9480548
A30: Hendry | B30: ='Assessed Value All Property'!B30 -> R-Prelim | C30: 4999064 | D30: =((C30-E30)/E30) -> 0.043364939 | E30: 4791290 | F30: =((E30-G30)/G30) -> -0.10527015 | G30: 5355013
A31: Hernando | B31: ='Assessed Value All Property'!B31 -> R-Prelim | C31: 12906416 | D31: =((C31-E31)/E31) -> 0.018286193 | E31: 12674645 | F31: =((E31-G31)/G31) -> 0.04649931 | G31: 12111470
A32: Highlands | B32: ='Assessed Value All Property'!B32 -> R-Prelim | C32: 35810333 | D32: =((C32-E32)/E32) -> 0.030531507 | E32: 34749382 | F32: =((E32-G32)/G32) -> -0.02991968 | G32: 35821139
A33: Hillsborough | B33: ='Assessed Value All Property'!B33 -> R-Prelim | C33: 137336207 | D33: =((C33-E33)/E33) -> 0.016233795 | E33: 135142334 | F33: =((E33-G33)/G33) -> 0.032621985 | G33: 130872997
A34: Holmes | B34: ='Assessed Value All Property'!B34 -> R-Prelim | C34: 4431950 | D34: =((C34-E34)/E34) -> 0.18630943 | E34: 3735914 | F34: =((E34-G34)/G34) -> -0.058287688 | G34: 3967150
A35: Indian River | B35: ='Assessed Value All Property'!B35 -> R-Prelim | C35: 46105678 | D35: =((C35-E35)/E35) -> -0.095302429 | E35: 50962531 | F35: =((E35-G35)/G35) -> 0.00050986953 | G35: 50936560
A36: Jackson | B36: ='Assessed Value All Property'!B36 -> R-Prelim | C36: 27264771 | D36: =((C36-E36)/E36) -> 0.081603665 | E36: 25207728 | F36: =((E36-G36)/G36) -> -0.11310996 | G36: 28422608
A37: Jefferson | B37: ='Assessed Value All Property'!B37 -> R-Prelim | C37: 3531607 | D37: =((C37-E37)/E37) -> 0.064816297 | E37: 3316635 | F37: =((E37-G37)/G37) -> 0.054214254 | G37: 3146073
A38: Lafayette | B38: ='Assessed Value All Property'!B38 -> R-Prelim | D38: n/a | E38: 0 | F38: n/a
A39: Lake | B39: ='Assessed Value All Property'!B39 -> R-Prelim | C39: 5784065 | D39: =((C39-E39)/E39) -> 0.080212335 | E39: 5354563 | F39: =((E39-G39)/G39) -> -0.0037885173 | G39: 5374926
A40: Lee | B40: ='Assessed Value All Property'!B40 -> R-Prelim | C40: 4978548 | D40: =((C40-E40)/E40) -> -0.061602643 | E40: 5305373 | F40: =((E40-G40)/G40) -> -0.041124637 | G40: 5532912
A41: Leon | B41: ='Assessed Value All Property'!B41 -> R-Prelim | C41: 6677452 | D41: =((C41-E41)/E41) -> 0.063389286 | E41: 6279405 | F41: =((E41-G41)/G41) -> 0.057100093 | G41: 5940218
...
