Workbook

Sheet Report Index
A2: Parcel Count Reports*
B4: State Summary by Property Type
B6: Parcel Count by Property Type
B8: Just Value by Property Type
B10: Taxable Value by Property Type
A14: * As Reported by County Property Appraiser
A16: Contact Information: | D16: Property Tax Oversight, Research & Analysis
D17: PTOResearchAnalysis@dor.state.fl.us

Sheet State Summary by Type
A1: State Summary by Property Type
A2: 2026
A4: Statewide | B4: Status | C4: Vacant Residential | D4: Single Family Residential | E4: Mobile Homes | F4: Condominiums | G4: Multi Family (Less Than 10) | H4: Multi Family (More Than 10) | I4: Cooperatives | J4: Retirement Homes & Misc. Residential | K4: Vacant Commercial | L4: Improved Commercial | M4: Vacant Industrial | N4: Industrial | O4: Agricultural | P4: Institutional | Q4: Government | R4: Leasehold Interest | S4: Misc. | T4: Non-Agricultural Acreage | U4: Total Real Property
A5: Number of Parcels | B5: R-Prelim | C5: 1276040 | D5: 6164863 | E5: 441312 | F5: 1620744 | G5: 159880 | H5: 18117 | I5: 47744 | J5: 179972 | K5: 86041 | L5: 258469 | M5: 13976 | N5: 83605 | O5: 236125 | P5: 47518 | Q5: 254380 | R5: 1978 | S5: 159526 | T5: 100463 | U5: =SUM(C5:T5) -> 11150753
A6: Pct of Total Parcels | B6: R-Prelim | C6: =C5/$U$5 -> 0.11443532 | D6: =D5/$U$5 -> 0.55286517 | E6: =E5/$U$5 -> 0.039576879 | F6: =F5/$U$5 -> 0.14534839 | G6: =G5/$U$5 -> 0.014338045 | H6: =H5/$U$5 -> 0.0016247333 | I6: =I5/$U$5 -> 0.0042816839 | J6: =J5/$U$5 -> 0.016139897 | ... U6: =U5/$U$5 -> 1
A7: Pct increase in parcels from 2025 | B7: R-Prelim | C7: -0.026316111 | D7: 0.017847481 | E7: 0.0028177207 | F7: 0.0027494896 | G7: 0.0069595339 | H7: 0.13259565 | I7: 0.021720987 | J7: 0.03666924 | K7: -0.012441894 | L7: 0.0013055336 | M7: -0.014733874 | N7: 0.013922408 | O7: -0.0028336627 | P7: -0.0037737431 | Q7: 0.0057169064 | R7: 0.0066157761 | S7: 0.0086368235 | T7: 0.014060765 | U7: -0.060085047
A9: Real Property Just Value | B9: R-Prelim | C9: 93097809690 | D9: 2897745264230 | E9: 56990305816 | F9: 603423109908 | G9: 82894657663 | H9: 231830828489 | I9: 8811529103 | J9: 13443984900 | K9: 41841421656 | L9: 489204208189 | M9: 7428255219 | N9: 195421462846 | O9: 135165326531 | P9: 94783913972 | Q9: 247801236021 | R9: 8920576670 | S9: 10887821019 | T9: 12373712602 | U9: 5232065424524
A10: Pct of Total Just Value | B10: R-Prelim | C10: =C9/$U$9 -> 0.017793701 | D10: =D9/$U$9 -> 0.55384347 | E10: =E9/$U$9 -> 0.010892506 | F10: =F9/$U$9 -> 0.11533172 | G10: =G9/$U$9 -> 0.015843582 | H10: =H9/$U$9 -> 0.04430962 | I10: =I9/$U$9 -> 0.0016841397 | J10: =J9/$U$9 -> 0.0025695368 | ... U10: =U9/$U$9 -> 1
A11: Pct Increase in Just Value from 2025 | B11: R-Prelim | C11: 0.015335266 | D11: 0.014168834 | E11: 0.011939266 | F11: -0.029876121 | G11: 0.030670964 | H11: 0.065213162 | I11: -0.012338666 | J11: 0.046917609 | K11: 0.053996104 | L11: 0.056072472 | M11: 0.066336397 | N11: 0.10844676 | O11: 0.044197679 | P11: 0.044393965 | Q11: 0.051480793 | R11: 0.10634852 | S11: 0.024617658 | T11: 0.051878705 | U11: 0.021963115
A12: Average Just Value Per Parcel | B12: R-Prelim | C12: =C9/C5 -> 72958.379 | D12: =D9/D5 -> 470042.12 | E12: =E9/E5 -> 129138.36 | F12: =F9/F5 -> 372312.41 | G12: =G9/G5 -> 518480.47 | H12: =H9/H5 -> 12796314 | I12: =I9/I5 -> 184557.83 | J12: =J9/J5 -> 74700.425 | ... U12: =U9/U5 -> 469211.85
A14: Real Property Taxable Value | B14: R-Prelim | C14: 74200404737 | D14: 1861272063453 | E14: 32213111698 | F14: 492366612041 | G14: 64680650966 | H14: 206530016950 | I14: 6623379201 | J14: 11478998034 | K14: 32773656000 | L14: 444016786693 | M14: 5389699510 | N14: 170146712923 | O14: 25535439975 | P14: 21624237041 | Q14: 1866114913 | R14: 4735426046 | S14: 6046027242 | T14: 9467671593 | U14: =SUM(C14:T14) -> 3470967009016
A15: Pct of Total Taxable Value | B15: R-Prelim | C15: =C14/$U$14 -> 0.021377445 | D15: =D14/$U$14 -> 0.53624021 | E15: =E14/$U$14 -> 0.0092807312 | F15: =F14/$U$14 -> 0.14185286 | G15: =G14/$U$14 -> 0.018634764 | H15: =H14/$U$14 -> 0.059502155 | I15: =I14/$U$14 -> 0.001908223 | J15: =J14/$U$14 -> 0.003307147 | ... U15: =U14/$U$14 -> 1
A16: Pct Increase in Taxable Value from 2025 | B16: R-Prelim | C16: 0.054358794 | D16: 0.063715894 | E16: 0.071299739 | F16: 0.02363616 | G16: 0.079606586 | H16: 0.066655416 | I16: 0.035231922 | J16: 0.065347652 | K16: 0.058611536 | L16: 0.062761808 | M16: 0.05472707 | N16: 0.12388675 | O16: 0.068641322 | P16: 0.071875191 | Q16: 0.08278752 | R16: 0.12077199 | S16: 0.015379296 | T16: 0.070731659 | U16: 0.060807903
A17: Average Taxable Value Per Parcel | B17: R-Prelim | C17: =C14/C5 -> 58148.965 | D17: =D14/D5 -> 301916.21 | E17: =E14/E5 -> 72993.963 | F17: =F14/F5 -> 303790.49 | G17: =G14/G5 -> 404557.49 | H17: =H14/H5 -> 11399791 | I17: =I14/I5 -> 138726.94 | J17: =J14/J5 -> 63782.133 | ... U17: =U14/U5 -> 311276.47
A19: Data Extract: July 2026

Sheet Parcel Ct by Type
A1: Parcel Count by Property Type
A2: 2026
A4: County | B4: Status | C4: Vacant Residential | D4: Single Family Residential | E4: Mobile Homes | F4: Condominiums | G4: Multi Family (Less Than 10) | H4: Multi Family (More Than 10) | I4: Cooperatives | J4: Retirement Homes & Misc. Residential | K4: Vacant Commercial | L4: Improved Commercial | M4: Vacant Industrial | N4: Industrial | O4: Agricultural | P4: Institutional | Q4: Government | R4: Leasehold Interest | S4: Misc. | T4: Non-Agricultural Acreage | U4: Total Real Property
A5: Alachua | B5: R-Prelim | C5: 9337 | D5: 65974 | E5: 5680 | F5: 7329 | G5: 1641 | H5: 408 | I5: 0 | J5: 1889 | K5: 1044 | L5: 3336 | M5: 319 | N5: 899 | O5: 7525 | P5: 1022 | Q5: 1938 | R5: 1 | S5: 1257 | T5: 253 | U5: =SUM(C5:T5) -> 109852
A6: Baker | B6: R-Prelim | C6: 1585 | D6: 5240 | E6: 2499 | F6: 0 | G6: 61 | H6: 6 | I6: 0 | J6: 40 | K6: 30 | L6: 328 | M6: 3 | N6: 43 | O6: 2265 | P6: 163 | Q6: 586 | R6: 34 | S6: 105 | T6: 284 | U6: =SUM(C6:T6) -> 13272
A7: Bay | B7: R-Prelim | C7: 20934 | D7: 67368 | E7: 8762 | F7: 19958 | G7: 2194 | H7: 148 | I7: 17 | J7: 1349 | K7: 2333 | L7: 3418 | M7: 76 | N7: 841 | O7: 1134 | P7: 431 | Q7: 2079 | R7: 65 | S7: 371 | T7: 193 | U7: =SUM(C7:T7) -> 131671
A8: Bradford | B8: R-Prelim | C8: 2933 | D8: 6153 | E8: 2783 | F8: 28 | G8: 29 | H8: 14 | I8: 0 | J8: 5 | K8: 77 | L8: 404 | M8: 2 | N8: 62 | O8: 2655 | P8: 232 | Q8: 284 | R8: 3 | S8: 52 | T8: 231 | U8: =SUM(C8:T8) -> 15947
A9: Brevard | B9: R-Prelim | C9: 48331 | D9: 217089 | E9: 11343 | F9: 36232 | G9: 3051 | H9: 309 | I9: 1118 | J9: 8718 | K9: 2859 | L9: 7877 | M9: 577 | N9: 2179 | O9: 1652 | P9: 902 | Q9: 8775 | R9: 0 | S9: 843 | T9: 794 | U9: =SUM(C9:T9) -> 352649
A10: Broward | B10: R-Prelim | C10: 7532 | D10: 394510 | E10: 4135 | F10: 254081 | G10: 16470 | H10: 1697 | I10: 11529 | J10: 9619 | K10: 1922 | L10: 22074 | M10: 251 | N10: 8804 | O10: 1248 | P10: 2116 | Q10: 3418 | R10: 0 | S10: 18737 | T10: 4 | U10: =SUM(C10:T10) -> 758147
A11: Calhoun | B11: R-Prelim | C11: 3235 | D11: 2683 | E11: 1190 | F11: 0 | G11: 12 | H11: 1 | I11: 0 | J11: 1 | K11: 97 | L11: 244 | M11: 0 | N11: 43 | O11: 3647 | P11: 169 | Q11: 324 | R11: 0 | S11: 1681 | T11: 36 | U11: =SUM(C11:T11) -> 13363
A12: Charlotte | B12: R-Prelim | C12: 88257 | D12: 93375 | E12: 5075 | F12: 15960 | G12: 1856 | H12: 91 | I12: 3685 | J12: 2136 | K12: 3284 | L12: 2554 | M12: 132 | N12: 1314 | O12: 1839 | P12: 202 | Q12: 992 | R12: 26 | S12: 1925 | T12: 661 | U12: =SUM(C12:T12) -> 223364
A13: Citrus | B13: R-Prelim | C13: 54739 | D13: 63370 | E13: 15881 | F13: 1608 | G13: 615 | H13: 46 | I13: 0 | J13: 33 | K13: 2037 | L13: 2135 | M13: 128 | N13: 309 | O13: 1796 | P13: 581 | Q13: 2363 | R13: 0 | S13: 1940 | T13: 912 | U13: =SUM(C13:T13) -> 148493
A14: Clay | B14: R-Prelim | C14: 13004 | D14: 70588 | E14: 9661 | F14: 2254 | G14: 292 | H14: 59 | I14: 0 | J14: 3726 | K14: 658 | L14: 1804 | M14: 20 | N14: 252 | O14: 1210 | P14: 467 | Q14: 884 | R14: 0 | S14: 1024 | T14: 389 | U14: =SUM(C14:T14) -> 106292
A15: Collier | B15: R-Prelim | C15: 15138 | D15: 113653 | E15: 3515 | F15: 102051 | G15: 1968 | H15: 139 | I15: 2654 | J15: 1002 | K15: 726 | L15: 3453 | M15: 100 | N15: 1016 | O15: 1859 | P15: 644 | Q15: 34916 | R15: 8 | S15: 8267 | T15: 7032 | U15: =SUM(C15:T15) -> 298141
A16: Columbia | B16: R-Prelim | C16: 4308 | D16: 14117 | E16: 8099 | F16: 48 | G16: 237 | H16: 39 | I16: 0 | J16: 1588 | K16: 349 | L16: 1034 | M16: 29 | N16: 189 | O16: 5327 | P16: 352 | Q16: 1089 | R16: 0 | S16: 404 | T16: 658 | U16: =SUM(C16:T16) -> 37867
... A42: Levy | B42: R-Prelim | C42: 18933 | D42: 8610 | E42: 10011 | F42: 239 | G42: 68 | H42: 12 | I42: 0 | J42: 86 | K42: 498 | L42: 819 | M42: 5 | N42: 114 | O42: 6561 | P42: 301 | Q42: 1051 | R42: 10 | S42: 105 | T42: 128 | U42: =SUM(C42:T42) -> 47551
A43: Liberty | B43: R-Prelim | C43: 1009 | D43: 1438 | E43: 853 | G43: 57 | H43: 5 | J43: 2 | K43: 13 | L43: 125 | N43: 22 | O43: 1529 | P43: 122 | Q43: 802 | S43: 36 | T43: 30 | U43: =SUM(C43:T43) -> 6043
A44: Madison | B44: R-Prelim | C44: 4161 | D44: 3342 | E44: 1823 | F44: 0 | G44: 164 | H44: 10 | I44: 0 | J44: 0 | K44: 65 | L44: 293 | M44: 1 | N44: 44 | O44: 5792 | P44: 212 | Q44: 450 | S44: 104 | T44: 157 | U44: =SUM(C44:T44) -> 16618
A45: Manatee | B45: R-Prelim | C45: 21868 | D45: 135559 | E45: 4624 | F45: 35667 | G45: 4445 | H45: 243 | I45: 6330 | J45: 14666 | K45: 1254 | L45: 4092 | M45: 305 | N45: 1626 | O45: 1999 | P45: 913 | Q45: 1976 | R45: 45 | S45: 1344 | T45: 437 | U45: =SUM(C45:T45) -> 237393
A46: Marion | B46: R-Prelim | C46: 78632 | D46: 144513 | E46: 24721 | F46: 2550 | G46: 3836 | H46: 134 | I46: 0 | J46: 2591 | K46: 3291 | L46: 4041 | M46: 368 | N46: 1275 | O46: 11351 | P46: 946 | Q46: 6144 | R46: 150 | S46: 1616 | T46: 1645 | U46: =SUM(C46:T46) -> 287804
A47: Martin | B47: R-Prelim | C47: 4841 | D47: 52459 | E47: 2956 | F47: 15044 | G47: 1080 | H47: 74 | I47: 1186 | J47: 164 | K47: 400 | L47: 2001 | M47: 132 | N47: 1108 | O47: 2353 | P47: 282 | Q47: 7190 | R47: 15 | S47: 2138 | T47: 5408 | U47: =SUM(C47:T47) -> 98831
A48: Monroe | B48: R-Prelim | C48: 6004 | D48: 30474 | E48: 4601 | F48: 7006 | G48: 1744 | H48: 55 | I48: 35 | J48: 207 | K48: 569 | L48: 4969 | M48: 8 | N48: 320 | O48: 3 | P48: 416 | Q48: 28668 | R48: 2 | S48: 1449 | T48: 3040 | U48: =SUM(C48:T48) -> 89570
A49: Nassau | B49: R-Prelim | C49: 8220 | D49: 33411 | E49: 6389 | F49: 4107 | G49: 363 | H49: 31 | I49: 0 | J49: 180 | K49: 486 | L49: 911 | M49: 78 | N49: 125 | O49: 3381 | P49: 342 | Q49: 1016 | R49: 12 | S49: 833 | T49: 170 | U49: =SUM(C49:T49) -> 60055
A50: Okaloosa | B50: R-Prelim | C50: 10018 | D50: 73078 | E50: 3451 | F50: 13587 | G50: 777 | H50: 198 | I50: 10 | J50: 723 | K50: 1176 | L50: 3507 | M50: 16 | N50: 687 | O50: 3054 | P50: 574 | Q50: 1588 | R50: 0 | S50: 1625 | T50: 600 | U50: =SUM(C50:T50) -> 114669
A51: Okeechobee | B51: R-Prelim | C51: 11844 | D51: 8007 | E51: 6021 | F51: 240 | G51: 339 | H51: 10 | I51: 0 | J51: 235 | K51: 186 | L51: 771 | M51: 61 | N51: 147 | O51: 2561 | P51: 141 | Q51: 769 | R51: 30 | S51: 129 | T51: 194 | U51: =SUM(C51:T51) -> 31685
A52: Orange | B52: R-Prelim | C52: 21130 | D52: 352007 | E52: 6257 | F52: 50523 | G52: 3993 | H52: 2984 | I52: 0 | J52: 16015 | K52: 3375 | L52: 18141 | M52: 760 | N52: 4752 | O52: 1263 | P52: 1404 | Q52: 9955 | R52: 15 | S52: 1919 | T52: 1561 | U52: =SUM(C52:T52) -> 496054
A53: Osceola | B53: R-Prelim | C53: 27471 | D53: 142263 | E53: 5465 | F53: 13631 | G53: 1076 | H53: 981 | I53: 0 | J53: 9957 | K53: 1830 | L53: 4864 | M53: 232 | N53: 491 | O53: 2344 | P53: 497 | Q53: 2635 | R53: 5 | S53: 1187 | T53: 241 | U53: =SUM(C53:T53) -> 215170
A54: Palm Beach | B54: R-Prelim | C54: 15130 | D54: 390263 | E54: 3674 | F54: 186723 | G54: 10241 | H54: 854 | I54: 4842 | J54: 10813 | K54: 2014 | L54: 13356 | M54: 305 | N54: 5486 | O54: 5085 | P54: 1695 | Q54: 8573 | R54: 193 | S54: 2578 | T54: 59 | U54: =SUM(C54:T54) -> 661884
A55: Pasco | B55: R-Prelim | C55: 32279 | D55: 206974 | E55: 29346 | F55: 11888 | G55: 3191 | H55: 262 | I55: 0 | J55: 6564 | K55: 2669 | L55: 6132 | M55: 284 | N55: 1131 | O55: 3941 | P55: 836 | Q55: 12008 | R55: 9 | S55: 19476 | T55: 1547 | U55: =SUM(C55:T55) -> 338537
A56: Pinellas | B56: R-Prelim | C56: 9848 | D56: 255710 | E56: 16973 | F56: 104508 | G56: 12792 | H56: 893 | I56: 1589 | J56: 6469 | K56: 3722 | L56: 13559 | M56: 735 | N56: 4037 | O56: 89 | P56: 1720 | Q56: 1077 | R56: 149 | S56: 3534 | T56: 151 | U56: =SUM(C56:T56) -> 437555
... A62: Sarasota | B62: R-Prelim | C62: 47944 | D62: 169825 | E62: 11609 | F62: 53935 | G62: 4971 | H62: 216 | I62: 333 | J62: 3472 | K62: 1021 | L62: 7576 | M62: 255 | N62: 2464 | O62: 627 | P62: 751 | Q62: 857 | R62: 12 | S62: 2072 | T62: 236 | U62: =SUM(C62:T62) -> 308176
A63: Seminole | B63: R-Prelim | C63: 6183 | D63: 136281 | E63: 1699 | F63: 15108 | G63: 1166 | H63: 225 | J63: 6147 | K63: 1156 | L63: 4395 | M63: 283 | N63: 1528 | O63: 796 | P63: 776 | Q63: 3314 | S63: 1643 | T63: 425 | U63: =SUM(C63:T63) -> 181125
A64: Sumter | B64: R-Prelim | C64: 10584 | D64: 77701 | E64: 6458 | F64: 509 | G64: 120 | H64: 37 | I64: 0 | J64: 205 | K64: 429 | L64: 1436 | M64: 32 | N64: 216 | O64: 5183 | P64: 399 | Q64: 1690 | R64: 0 | S64: 404 | T64: 480 | U64: =SUM(C64:T64) -> 105883
A65: Suwannee | B65: R-Prelim | C65: 9467 | D65: 6565 | E65: 7204 | F65: 0 | G65: 62 | H65: 6 | I65: 0 | J65: 3 | K65: 285 | L65: 553 | M65: 2 | N65: 80 | O65: 6776 | P65: 371 | Q65: 576 | R65: 0 | S65: 6797 | T65: 376 | U65: =SUM(C65:T65) -> 39123
A66: Taylor | B66: R-Prelim | C66: 5446 | D66: 5290 | E66: 3204 | F66: 76 | G66: 24 | H66: 12 | I66: 0 | J66: 0 | K66: 53 | L66: 385 | M66: 0 | N66: 61 | O66: 2761 | P66: 195 | Q66: 919 | R66: 4 | S66: 1063 | T66: 301 | U66: =SUM(C66:T66) -> 19794
A67: Union | B67: R-Prelim | C67: 681 | D67: 1499 | E67: 1308 | F67: 18 | G67: 1 | H67: 15 | I67: 0 | J67: 70 | K67: 37 | L67: 115 | M67: 2 | N67: 18 | O67: 3052 | P67: 110 | Q67: 125 | R67: 1 | S67: 88 | T67: 0 | U67: =SUM(C67:T67) -> 7140
A68: Volusia | B68: R-Prelim | C68: 36743 | D68: 196440 | E68: 7409 | F68: 28494 | G68: 2720 | H68: 333 | I68: 409 | J68: 4295 | K68: 4315 | L68: 8265 | M68: 655 | N68: 2251 | O68: 7854 | P68: 1391 | Q68: 8857 | R68: 155 | S68: 2520 | T68: 476 | U68: =SUM(C68:T68) -> 313582
A69: Wakulla | B69: R-Prelim | C69: 7094 | D69: 10673 | E69: 3425 | F69: 463 | G69: 30 | H69: 5 | I69: 0 | J69: 112 | K69: 273 | L69: 391 | M69: 31 | N69: 89 | O69: 2435 | P69: 167 | Q69: 1086 | S69: 431 | T69: 428 | U69: =SUM(C69:T69) -> 27133
A70: Walton | B70: R-Prelim | C70: 20438 | D70: 41423 | E70: 5694 | F70: 10918 | G70: 629 | H70: 47 | I70: 0 | J70: 1544 | K70: 311 | L70: 2054 | M70: 8 | N70: 381 | O70: 4582 | P70: 422 | Q70: 1001 | R70: 0 | S70: 4561 | T70: 980 | U70: =SUM(C70:T70) -> 94993
A71: Washington | B71: R-Prelim | C71: 27872 | D71: 5653 | E71: 2792 | F71: 0 | G71: 25 | H71: 0 | I71: 0 | J71: 32 | K71: 609 | L71: 356 | M71: 3 | N71: 51 | O71: 4808 | P71: 231 | Q71: 758 | R71: 0 | S71: 2815 | T71: 558 | U71: =SUM(C71:T71) -> 46563
...

Sheet Just Value by Type 
A1: Just Value by Property Type
A2: 2026
A4: County | B4: Status | C4: Vacant Residential | D4: Single Family Residential | E4: Mobile Homes | F4: Condominiums | G4: Multi Family (Less Than 10) | H4: Multi Family (More Than 10) | I4: Cooperatives | J4: Retirement Homes & Misc. Residential | K4: Vacant Commercial | L4: Improved Commercial | M4: Vacant Industrial | N4: Industrial | O4: Agricultural | P4: Institutional | Q4: Government | R4: Leasehold Interest | S4: Misc. | T4: Non-Agricultural Acreage | U4: Total Real Property
A5: Alachua | B5: ='Parcel Ct by Type'!B5 -> R-Prelim | C5: 589150341 | D5: 20124028518 | E5: 701194841 | F5: 1149730414 | G5: 555632825 | H5: 4993053191 | I5: 0 | J5: 101326711 | K5: 243059241 | L5: 4120490537 | M5: 40831807 | N5: 1046105674 | O5: 2524719301 | P5: 1039339884 | Q5: 5867196626 | R5: 54600 | S5: 76508328 | T5: 44688577 | U5: =SUM(C5:T5) -> 43217111416
A6: Baker | B6: ='Parcel Ct by Type'!B6 -> R-Prelim | C6: 60638701 | D6: 1403109883 | E6: 373925674 | F6: 0 | G6: 11612270 | H6: 18260735 | I6: 0 | J6: 0 | K6: 5795192 | L6: 162046863 | M6: 426083 | N6: 45754877 | O6: 715349172 | P6: 47966054 | Q6: 314882524 | R6: 4246905 | S6: 17077158 | T6: 74833702 | U6: =SUM(C6:T6) -> 3255925793
A7: Bay | B7: ='Parcel Ct by Type'!B7 -> R-Prelim | C7: 1681636195 | D7: 22036730171 | E7: 972789477 | F7: 7133798459 | G7: 748868246 | H7: 1663889297 | I7: 4533318 | J7: 13067078 | K7: 806229143 | L7: 3333370498 | M7: 12769217 | N7: 827993578 | O7: 432083809 | P7: 397505115 | Q7: 4061734223 | R7: 49709098 | S7: 33054775 | T7: 127322992 | U7: =SUM(C7:T7) -> 44337084689
A8: Bradford | B8: ='Parcel Ct by Type'!B8 -> R-Prelim | C8: 82710186 | D8: 1296461557 | E8: 341670070 | F8: 4386109 | G8: 4418333 | H8: 17179405 | I8: 0 | J8: 230182 | K8: 6457154 | L8: 141674013 | M8: 214316 | N8: 15753233 | O8: 604772081 | P8: 51916341 | Q8: 114312591 | R8: 622405 | S8: 3859923 | T8: 27965739 | U8: =SUM(C8:T8) -> 2714603638
A9: Brevard | B9: ='Parcel Ct by Type'!B9 -> R-Prelim | C9: 1866430480 | D9: 75856632830 | E9: 1264549780 | F9: 9156022660 | G9: 1373636670 | H9: 4115662940 | I9: 82586700 | J9: 206270 | K9: 566326180 | L9: 7901627600 | M9: 135197540 | N9: 2652265150 | O9: 1021888450 | P9: 2526076520 | Q9: 8632573330 | R9: 0 | S9: 84826900 | T9: 278126780 | U9: =SUM(C9:T9) -> 117514636780
A10: Broward | B10: ='Parcel Ct by Type'!B10 -> R-Prelim | C10: 3903653540 | D10: 261350349480 | E10: 827781930 | F10: 71498152030 | G10: 10665968500 | H10: 28375219870 | I10: 2680252740 | J10: 83836260 | K10: 2448899950 | L10: 51371017070 | M10: 607987210 | N10: 26853772430 | O10: 2069191060 | P10: 8521586020 | Q10: 19101327180 | R10: 0 | S10: 1676225560 | T10: 18202660 | U10: =SUM(C10:T10) -> 492053423490
A11: Calhoun | B11: ='Parcel Ct by Type'!B11 -> R-Prelim | C11: 52987893 | D11: 365781186 | E11: 71020150 | F11: 0 | G11: 2032983 | H11: 1023117 | I11: 0 | J11: 220866 | K11: 2693883 | L11: 51435272 | M11: 0 | N11: 4713209 | O11: 522289501 | P11: 33756351 | Q11: 44907076 | R11: 0 | S11: 39966007 | T11: 2199050 | U11: =SUM(C11:T11) -> 1195026544
A12: Charlotte | B12: ='Parcel Ct by Type'!B12 -> R-Prelim | C12: 2468390050 | D12: 30333744549 | E12: 581417982 | F12: 3851006677 | G12: 704462593 | H12: 506476016 | I12: 427865211 | J12: 80402514 | K12: 700060578 | L12: 3086882455 | M12: 59751754 | N12: 1018919804 | O12: 1369066916 | P12: 591158467 | Q12: 2556087703 | R12: 29776921 | S12: 222218626 | T12: 165842932 | U12: =SUM(C12:T12) -> 48753531748
A13: Citrus | B13: ='Parcel Ct by Type'!B13 -> R-Prelim | C13: 1209422703 | D13: 16862776564 | E13: 2021721340 | F13: 262832789 | G13: 163672947 | H13: 56005128 | I13: 0 | J13: 13400000 | K13: 225505333 | L13: 1421660094 | M13: 10884820 | N13: 215794211 | O13: 721843458 | P13: 557552642 | Q13: 1235576892 | R13: 0 | S13: 376973471 | T13: 124330650 | U13: =SUM(C13:T13) -> 25479953042
A14: Clay | B14: ='Parcel Ct by Type'!B14 -> R-Prelim | C14: 651575197 | D14: 23259466513 | E14: 1498990734 | F14: 384319118 | G14: 92126200 | H14: 977619518 | I14: 0 | J14: 20592549 | K14: 194647054 | L14: 2048077592 | M14: 14532824 | N14: 616542183 | O14: 1330449887 | P14: 862054964 | Q14: 1158954452 | R14: 0 | S14: 58942766 | T14: 328578782 | U14: =SUM(C14:T14) -> 33497470333
A15: Collier | B15: ='Parcel Ct by Type'!B15 -> R-Prelim | C15: 4198777165 | D15: 119821135232 | E15: 626194117 | F15: 60180612688 | G15: 955064699 | H15: 3013232437 | I15: 836039441 | J15: 2569059037 | K15: 1155999820 | L15: 10458385679 | M15: 78084590 | N15: 2256767577 | O15: 1552293296 | P15: 3184984149 | Q15: 6089665073 | R15: 28330575 | S15: 104644755 | T15: 609746872 | U15: =SUM(C15:T15) -> 217719017202
A16: Columbia | B16: ='Parcel Ct by Type'!B16 -> R-Prelim | C16: 138060632 | D16: 3300309883 | E16: 1074468982 | F16: 6552626 | G16: 49079040 | H16: 57357258 | I16: 0 | J16: 71142157 | K16: 62707766 | L16: 643610418 | M16: 4981658 | N16: 216154348 | O16: 1555535229 | P16: 222121633 | Q16: 550015081 | R16: 0 | S16: 24729505 | T16: 74558524 | U16: =SUM(C16:T16) -> 8051384740
... A42: Levy | B42: ='Parcel Ct by Type'!B42 -> R-Prelim | C42: 440300579 | D42: 2172457004 | E42: 1342130966 | F42: 38307598 | G42: 20022268 | H42: 19985584 | I42: 0 | J42: 4539427 | K42: 24500099 | L42: 282118817 | M42: 834398 | N42: 34741277 | O42: 2962064909 | P42: 89318727 | Q42: 430275210 | R42: 3399822 | S42: 19222799 | T42: 36639238 | U42: =SUM(C42:T42) -> 7920858722
A43: Liberty | B43: ='Parcel Ct by Type'!B43 -> R-Prelim | C43: 13352393 | D43: 195632057 | E43: 36906136 | G43: 5612198 | H43: 1074572 | I43: 0 | J43: 328084 | K43: 732434 | L43: 22309540 | N43: 22538904 | O43: 289014167 | P43: 23067102 | Q43: 352497800 | S43: 1758936 | T43: 1988376 | U43: =SUM(C43:T43) -> 966812699
A44: Madison | B44: ='Parcel Ct by Type'!B44 -> R-Prelim | C44: 111644348 | D44: 560965572 | E44: 212617876 | F44: 0 | G44: 32583312 | H44: 10271741 | I44: 0 | J44: 0 | K44: 3868673 | L44: 105122569 | M44: 160553 | N44: 96542333 | O44: 962279480 | P44: 65900458 | Q44: 108297459 | S44: 13158100 | T44: 25203203 | U44: =SUM(C44:T44) -> 2308615677
A45: Manatee | B45: ='Parcel Ct by Type'!B45 -> R-Prelim | C45: 2089486177 | D45: 67762525551 | E45: 508582581 | F45: 9654999398 | G45: 1979502238 | H45: 3849453067 | I45: 509415499 | J45: 151476011 | K45: 359299667 | L45: 6010861538 | M45: 103720498 | N45: 3265826577 | O45: 1866442362 | P45: 2024540462 | Q45: 2724082796 | R45: 79194840 | S45: 100670309 | T45: 434720817 | U45: =SUM(C45:T45) -> 103474800388
A46: Marion | B46: ='Parcel Ct by Type'!B46 -> R-Prelim | C46: 2114396431 | D46: 38427413616 | E46: 2820664252 | F46: 336785905 | G46: 1303124594 | H46: 1295824568 | I46: 0 | J46: 334496590 | K46: 629653069 | L46: 4383699856 | M46: 120341806 | N46: 2368952657 | O46: 8457169323 | P46: 1378964532 | Q46: 3254012354 | R46: 23890941 | S46: 78697146 | T46: 377492265 | U46: =SUM(C46:T46) -> 67705579905
A47: Martin | B47: ='Parcel Ct by Type'!B47 -> R-Prelim | C47: 2770018140 | D47: 39464545577 | E47: 432185107 | F47: 3696425227 | G47: 516810870 | H47: 799052860 | I47: 95567230 | J47: 2951450 | K47: 293580908 | L47: 3371426919 | M47: 119474100 | N47: 1381202028 | O47: 3343919278 | P47: 789712472 | Q47: 1496969592 | R47: 44786950 | S47: 70003060 | T47: 306860542 | U47: =SUM(C47:T47) -> 58995492310
A48: Monroe | B48: ='Parcel Ct by Type'!B48 -> R-Prelim | C48: 2115009499 | D48: 42487520400 | E48: 2008693905 | F48: 6836021659 | G48: 2027402903 | H48: 670445825 | I48: 18514271 | J48: 162560202 | K48: 248351794 | L48: 9792778933 | M48: 10597428 | N48: 433504326 | O48: 53561 | P48: 691294240 | Q48: 4636437129 | R48: 5053240 | S48: 150033450 | T48: 9695966 | U48: =SUM(C48:T48) -> 72303968731
A49: Nassau | B49: ='Parcel Ct by Type'!B49 -> R-Prelim | C49: 807592381 | D49: 18564600262 | E49: 1200630159 | F49: 2860646911 | G49: 285617902 | H49: 501002973 | I49: 0 | J49: 118242942 | K49: 217092538 | L49: 1617740975 | M49: 24934221 | N49: 294824782 | O49: 2597378320 | P49: 437080558 | Q49: 1463725563 | R49: 4539860 | S49: 95885231 | T49: 246913817 | U49: =SUM(C49:T49) -> 31338449395
A50: Okaloosa | B50: ='Parcel Ct by Type'!B50 -> R-Prelim | C50: 815985135 | D50: 26366068078 | E50: 424642672 | F50: 6445923475 | G50: 406533379 | H50: 1046257142 | I50: 840000 | J50: 12834088 | K50: 221119448 | L50: 3082212365 | M50: 2901976 | N50: 599643727 | O50: 610022725 | P50: 474013933 | Q50: 2548654735 | R50: 0 | S50: 55807789 | T50: 123031154 | U50: =SUM(C50:T50) -> 43236491821
A51: Okeechobee | B51: ='Parcel Ct by Type'!B51 -> R-Prelim | C51: 343129904 | D51: 2292363088 | E51: 806381414 | F51: 23755518 | G51: 100459724 | H51: 26191570 | I51: 0 | J51: 1125071 | K51: 31227117 | L51: 523678109 | M51: 11021908 | N51: 116244423 | O51: 3819323127 | P51: 140552547 | Q51: 1060237470 | R51: 9745597 | S51: 110713841 | T51: 57244474 | U51: =SUM(C51:T51) -> 9473394902
A52: Orange | B52: ='Parcel Ct by Type'!B52 -> R-Prelim | C52: 2229711729 | D52: 163839296083 | E52: 950742035 | F52: 10192382818 | G52: 1616730564 | H52: 28687051808 | I52: 0 | J52: 85965704 | K52: 2601272336 | L52: 69962930774 | M52: 646663471 | N52: 19229659708 | O52: 2862276696 | P52: 4591217891 | Q52: 31417666122 | R52: 4352322 | S52: 126535459 | T52: 715147074 | U52: =SUM(C52:T52) -> 339759602594
A53: Osceola | B53: ='Parcel Ct by Type'!B53 -> R-Prelim | C53: 1079552442 | D53: 50414301802 | E53: 978408102 | F53: 5915181681 | G53: 387005000 | H53: 5032558810 | I53: 0 | J53: 16380547 | K53: 881592368 | L53: 7392420417 | M53: 96928800 | N53: 1586314202 | O53: 3161100700 | P53: 1169398127 | Q53: 2802540920 | R53: 7879000 | S53: 198543538 | T53: 205206302 | U53: =SUM(C53:T53) -> 81325312758
A54: Palm Beach | B54: ='Parcel Ct by Type'!B54 -> R-Prelim | C54: 8875525703 | D54: 322859408747 | E54: 593546159 | F54: 71339349370 | G54: 6439884876 | H54: 17608177923 | I54: 2290081829 | J54: 3344230132 | K54: 2261753976 | L54: 43739454633 | M54: 314942752 | N54: 14405381392 | O54: 13492056844 | P54: 6889359424 | Q54: 18759654013 | R54: 1229391110 | S54: 664286513 | T54: 9649015 | U54: =SUM(C54:T54) -> 535116134411
A55: Pasco | B55: ='Parcel Ct by Type'!B55 -> R-Prelim | C55: 1448158131 | D55: 68817629046 | E55: 2997652111 | F55: 1571316393 | G55: 806308956 | H55: 3549789358 | I55: 0 | J55: 73860367 | K55: 1065762361 | L55: 6349403032 | M55: 85128540 | N55: 2157185602 | O55: 2137514463 | P55: 1290982863 | Q55: 2233506809 | R55: 269424 | S55: 73678153 | T55: 195015769 | U55: =SUM(C55:T55) -> 94853161378
A56: Pinellas | B56: ='Parcel Ct by Type'!B56 -> R-Prelim | C56: 2603629196 | D56: 116903838155 | E56: 1723476677 | F56: 31407942628 | G56: 7091767769 | H56: 10821582149 | I56: 195916522 | J56: 45386451 | K56: 1936843750 | L56: 20131932038 | M56: 234845055 | N56: 6505945781 | O56: 95061536 | P56: 5558624912 | Q56: 6413829308 | R56: 924711844 | S56: 430032334 | T56: 180798616 | U56: =SUM(C56:T56) -> 213206164721
... A62: Sarasota | B62: ='Parcel Ct by Type'!B62 -> R-Prelim | C62: 3444659500 | D62: 79911190900 | E62: 1243686700 | F62: 23929508500 | G62: 4127166700 | H62: 3746158000 | I62: 89929500 | J62: 1046654800 | K62: 987913800 | L62: 12844649300 | M62: 96642600 | N62: 3336488900 | O62: 2472142200 | P62: 3103368800 | Q62: 6130425600 | R62: 14479900 | S62: 421301100 | T62: 459149600 | U62: =SUM(C62:T62) -> 147405516400
A63: Seminole | B63: ='Parcel Ct by Type'!B63 -> R-Prelim | C63: 627821343 | D63: 56871620627 | E63: 304915415 | F63: 2432552896 | G63: 395574115 | H63: 6737943218 | I63: 0 | J63: 75996023 | K63: 646460039 | L63: 8358563008 | M63: 124999978 | N63: 3460955849 | O63: 663067639 | P63: 2332916556 | Q63: 4899248032 | S63: 86841404 | T63: 557280 | U63: =SUM(C63:T63) -> 88020033422
A64: Sumter | B64: ='Parcel Ct by Type'!B64 -> R-Prelim | C64: 334567180 | D64: 28045252245 | E64: 464567906 | F64: 91614670 | G64: 21738330 | H64: 561963930 | I64: 0 | J64: 2087664 | K64: 178115171 | L64: 2043362720 | M64: 19196080 | N64: 529848550 | O64: 1683545670 | P64: 619134210 | Q64: 768045990 | R64: 0 | S64: 54076621 | T64: 152077086 | U64: =SUM(C64:T64) -> 35569194023
A65: Suwannee | B65: ='Parcel Ct by Type'!B65 -> R-Prelim | C65: 303181549 | D65: 1388258609 | E65: 904559050 | F65: 0 | G65: 13026778 | H65: 8332026 | I65: 0 | J65: 258789 | K65: 43582181 | L65: 236144643 | M65: 66669 | N65: 112024588 | O65: 1186738637 | P65: 89861647 | Q65: 169041883 | R65: 0 | S65: 15304992 | T65: 77870326 | U65: =SUM(C65:T65) -> 4548252367
A66: Taylor | B66: ='Parcel Ct by Type'!B66 -> R-Prelim | C66: 271562288 | D66: 898517790 | E66: 333653875 | F66: 13125850 | G66: 5727060 | H66: 32645321 | I66: 0 | J66: 0 | K66: 4983240 | L66: 133636693 | M66: 0 | N66: 39654890 | O66: 726759020 | P66: 46124560 | Q66: 200158850 | R66: 150290 | S66: 13527686 | T66: 43248290 | U66: =SUM(C66:T66) -> 2763475703
A67: Union | B67: ='Parcel Ct by Type'!B67 -> R-Prelim | C67: 14004841 | D67: 208515266 | E67: 110562195 | F67: 1260000 | G67: 54507 | H67: 2147082 | I67: 0 | J67: 2462008 | K67: 1039594 | L67: 19491556 | M67: 250000 | N67: 3657459 | O67: 601454594 | P67: 17278769 | Q67: 110556422 | R67: 118587 | S67: 14205280 | T67: 0 | U67: =SUM(C67:T67) -> 1107058160
A68: Volusia | B68: ='Parcel Ct by Type'!B68 -> R-Prelim | C68: 1497222952 | D68: 66138067494 | E68: 1177360583 | F68: 8289859034 | G68: 937200687 | H68: 3375375803 | I68: 54372934 | J68: 107771 | K68: 876988866 | L68: 8504072401 | M68: 108331027 | N68: 2431005860 | O68: 2141609315 | P68: 2551432950 | Q68: 5550570355 | R68: 139147688 | S68: 91991868 | T68: 212825942 | U68: =SUM(C68:T68) -> 104077543530
A69: Wakulla | B69: ='Parcel Ct by Type'!B69 -> R-Prelim | C69: 168064816 | D69: 2610045310 | E69: 314968096 | F69: 88154119 | G69: 6113418 | H69: 11641792 | I69: 0 | J69: 84449 | K69: 29018965 | L69: 211035573 | M69: 883615 | N69: 36664797 | O69: 614419378 | P69: 42235587 | Q69: 557684102 | S69: 12700820 | T69: 30859878 | U69: =SUM(C69:T69) -> 4734574715
A70: Walton | B70: ='Parcel Ct by Type'!B70 -> R-Prelim | C70: 3492570888 | D70: 39456750624 | E70: 543655133 | F70: 7815616095 | G70: 242349797 | H70: 832030330 | I70: 0 | J70: 79777608 | K70: 148816507 | L70: 2757277503 | M70: 3253029 | N70: 397776598 | O70: 1160195586 | P70: 518226571 | Q70: 2413640043 | R70: 0 | S70: 406606335 | T70: 186407646 | U70: =SUM(C70:T70) -> 60454950293
A71: Washington | B71: ='Parcel Ct by Type'!B71 -> R-Prelim | C71: 237885734 | D71: 1017217665 | E71: 297020989 | F71: 0 | G71: 11913235 | H71: 0 | I71: 0 | J71: 65184 | K71: 12233878 | L71: 91930275 | M71: 56750 | N71: 23746005 | O71: 746267962 | P71: 62674177 | Q71: 178422526 | R71: 0 | S71: 7873479 | T71: 34528393 | U71: =SUM(C71:T71) -> 2721836252
...

Sheet Taxable Value by Type 
A1: Taxable Value by Property Type
A2: 2026
A4: County | B4: Status | C4: Vacant Residential | D4: Single Family Residential | E4: Mobile Homes | F4: Condominiums | G4: Multi Family (Less Than 10) | H4: Multi Family (More Than 10) | I4: Cooperatives | J4: Retirement Homes & Misc. Residential | K4: Vacant Commercial | L4: Improved Commercial | M4: Vacant Industrial | N4: Industrial | O4: Agricultural | P4: Institutional | Q4: Government | R4: Leasehold Interest | S4: Misc. | T4: Non-Agricultural Acreage | U4: Total Real Property
A5: Alachua | B5: ='Parcel Ct by Type'!B5 -> R-Prelim | C5: 447008584 | D5: 12710238383 | E5: 330964965 | F5: 990043793 | G5: 407254611 | H5: 4402929758 | I5: 0 | J5: 70953091 | K5: 187258681 | L5: 3325643482 | M5: 31871157 | N5: 886001915 | O5: 681227522 | P5: 419589442 | Q5: 58376155 | R5: 54600 | S5: 11393250 | T5: 24128459 | U5: =SUM(C5:T5) -> 24984937848
A6: Baker | B6: ='Parcel Ct by Type'!B6 -> R-Prelim | C6: 53428527 | D6: 766973660 | E6: 180051518 | G6: 11550294 | H6: 11320633 | I6: 0 | J6: 0 | K6: 4033272 | L6: 125403755 | M6: 303736 | N6: 45236320 | O6: 197167708 | P6: 6840535 | Q6: 1193807 | R6: 3935718 | S6: 15219678 | T6: 68737085 | U6: =SUM(C6:T6) -> 1491396246
A7: Bay | B7: ='Parcel Ct by Type'!B7 -> R-Prelim | C7: 1450867330 | D7: 16053312375 | E7: 626137484 | F7: 6598552812 | G7: 627617596 | H7: 1223305576 | I7: 3386882 | J7: 6450774 | K7: 663525823 | L7: 3130551424 | M7: 11110954 | N7: 775964915 | O7: 63152430 | P7: 155793832 | Q7: 3777556 | R7: 39862531 | S7: 32378229 | T7: 117518702 | U7: =SUM(C7:T7) -> 31583267225
A8: Bradford | B8: ='Parcel Ct by Type'!B8 -> R-Prelim | C8: 70172720 | D8: 705427299 | E8: 164087569 | F8: 2216092 | G8: 3452895 | H8: 14445576 | I8: 0 | J8: 199199 | K8: 5968114 | L8: 136142330 | M8: 214316 | N8: 15557966 | O8: 149037729 | P8: 6897082 | Q8: 5075912 | R8: 425687 | S8: 3735655 | T8: 19314325 | U8: =SUM(C8:T8) -> 1302370466
A9: Brevard | B9: ='Parcel Ct by Type'!B9 -> R-Prelim | C9: 1348049413 | D9: 44951911694 | E9: 715657057 | F9: 7165721055 | G9: 1082839422 | H9: 3525561893 | I9: 49328488 | J9: 201030 | K9: 516527100 | L9: 7448500279 | M9: 117809960 | N9: 2461609343 | O9: 209253958 | P9: 610872666 | Q9: 279924420 | R9: 0 | S9: 64807871 | T9: 248346355 | U9: =SUM(C9:T9) -> 70796922004
A10: Broward | B10: ='Parcel Ct by Type'!B10 -> R-Prelim | C10: 2842101915 | D10: 152738611628 | E10: 489999873 | F10: 55194365145 | G10: 8637692343 | H10: 25825946657 | I10: 2146620934 | J10: 44164000 | K10: 1935557060 | L10: 46922504764 | M10: 417436890 | N10: 23110502600 | O10: 519163366 | P10: 2187009480 | Q10: 85223940 | R10: 0 | S10: 394579570 | T10: 7156670 | U10: =SUM(C10:T10) -> 323498636835
A11: Calhoun | B11: ='Parcel Ct by Type'!B11 -> R-Prelim | C11: 42203462 | D11: 182459066 | E11: 30825728 | F11: 0 | G11: 1783755 | H11: 1023117 | I11: 0 | J11: 171047 | K11: 2451628 | L11: 42465849 | M11: 0 | N11: 4080671 | O11: 145964012 | P11: 2276841 | Q11: 331561 | R11: 0 | S11: 38914620 | T11: 1343487 | U11: =SUM(C11:T11) -> 496294844
A12: Charlotte | B12: ='Parcel Ct by Type'!B12 -> R-Prelim | C12: 1976350285 | D12: 21938768333 | E12: 391023887 | F12: 3278769386 | G12: 614624839 | H12: 337835223 | I12: 303476093 | J12: 69253251 | K12: 427574707 | L12: 2620502061 | M12: 43882681 | N12: 885613403 | O12: 202963954 | P12: 265426989 | Q12: 3368619 | R12: 9417622 | S12: 43278948 | T12: 115369584 | U12: =SUM(C12:T12) -> 33527499865
A13: Citrus | B13: ='Parcel Ct by Type'!B13 -> R-Prelim | C13: 818747052 | D13: 10049121252 | E13: 1072136538 | F13: 187586175 | G13: 147575570 | H13: 45511193 | I13: 0 | J13: 12954235 | K13: 205429218 | L13: 1359037619 | M13: 9846405 | N13: 203236064 | O13: 166074670 | P13: 236985737 | Q13: 12324885 | R13: 0 | S13: 362609644 | T13: 102820875 | U13: =SUM(C13:T13) -> 14991997132
A14: Clay | B14: ='Parcel Ct by Type'!B14 -> R-Prelim | C14: 561393322 | D14: 13508609969 | E14: 733235903 | F14: 285421095 | G14: 83997092 | H14: 883246209 | I14: 0 | J14: 19180135 | K14: 160157169 | L14: 1889736467 | M14: 12759615 | N14: 568455526 | O14: 142802348 | P14: 293828711 | Q14: 1264917 | R14: 0 | S14: 34281376 | T14: 261055210 | U14: =SUM(C14:T14) -> 19439425064
A15: Collier | B15: ='Parcel Ct by Type'!B15 -> R-Prelim | C15: 3396813564 | D15: 91029748318 | E15: 418660819 | F15: 51923515414 | G15: 816735574 | H15: 2542858160 | I15: 712403152 | J15: 2452371602 | K15: 989561274 | L15: 9226456222 | M15: 52329155 | N15: 2036232757 | O15: 331811640 | P15: 412772429 | Q15: 9439339 | R15: 1209653 | S15: 73891526 | T15: 424106128 | U15: =SUM(C15:T15) -> 166850916726
A16: Columbia | B16: ='Parcel Ct by Type'!B16 -> R-Prelim | C16: 111618998 | D16: 1887627305 | E16: 533077009 | F16: 4627818 | G16: 46715844 | H16: 47902229 | I16: 0 | J16: 59399976 | K16: 55528585 | L16: 626109008 | M16: 4457892 | N16: 201095894 | O16: 349835862 | P16: 104995604 | Q16: 13216833 | R16: 0 | S16: 22014544 | T16: 57969838 | U16: =SUM(C16:T16) -> 4126193239
A17: Miami-Dade | B17: ='Parcel Ct by Type'!B17 -> R-Prelim | C17: 7353360971 | D17: 170323446771 | E17: 25221126 | F17: 156799063104 | G17: 16744984516 | H17: 32459967319 | I17: 402731606 | J17: 369592790 | K17: 9301896828 | L17: 76557440664 | M17: 1797287488 | N17: 37452699107 | O17: 1565223742 | P17: 1828246021 | Q17: 179174316 | R17: 1790524897 | S17: 878422137 | T17: 1486335670 | U17: =SUM(C17:T17) -> 517315619073
A18: DeSoto | B18: ='Parcel Ct by Type'!B18 -> R-Prelim | C18: 98073609 | D18: 913136981 | E18: 201880990 | F18: 63369239 | G18: 51254442 | H18: 26772882 | I18: 0 | J18: 702024 | K18: 17531695 | L18: 221978429 | M18: 4518202 | N18: 129440708 | O18: 407266910 | P18: 10027798 | Q18: 10000 | R18: 0 | S18: 21772088 | T18: 61332603 | U18: =SUM(C18:T18) -> 2229068600
... A42: Levy | B42: ='Parcel Ct by Type'!B42 -> R-Prelim | C42: 342309915 | D42: 1198008530 | E42: 620034487 | F42: 35689901 | G42: 14643506 | H42: 5311500 | I42: 0 | J42: 4088952 | K42: 21358982 | L42: 266149764 | M42: 368753 | N42: 33089536 | O42: 523554525 | P42: 5880473 | Q42: 0 | R42: 3345310 | S42: 17790560 | T42: 26693558 | U42: =SUM(C42:T42) -> 3118318252
A43: Liberty | B43: ='Parcel Ct by Type'!B43 -> R-Prelim | C43: 11640916 | D43: 103298601 | E43: 19457220 | G43: 2497912 | H43: 318314 | J43: 274820 | K43: 723318 | L43: 17371461 | N43: 21165592 | O43: 51746672 | P43: 343529 | Q43: 0 | S43: 1368852 | T43: 1964376 | U43: =SUM(C43:T43) -> 232171583
A44: Madison | B44: ='Parcel Ct by Type'!B44 -> R-Prelim | C44: 89626785 | D44: 295637232 | E44: 87185983 | F44: 0 | G44: 19561125 | H44: 3980407 | I44: 0 | J44: 0 | K44: 3426959 | L44: 89265712 | M44: 117661 | N44: 92053287 | O44: 262282941 | P44: 16488634 | Q44: 0 | S44: 8806530 | T44: 16173765 | U44: =SUM(C44:T44) -> 984607021
A45: Manatee | B45: ='Parcel Ct by Type'!B45 -> R-Prelim | C45: 1897967886 | D45: 48776480020 | E45: 349493436 | F45: 7876467229 | G45: 1641978622 | H45: 3603177936 | I45: 386634685 | J45: 122777010 | K45: 320731224 | L45: 5674941109 | M45: 74909784 | N45: 2992691395 | O45: 413673156 | P45: 830493417 | Q45: 11119309 | R45: 25417597 | S45: 86769406 | T45: 405727740 | U45: =SUM(C45:T45) -> 75491450961
A46: Marion | B46: ='Parcel Ct by Type'!B46 -> R-Prelim | C46: 1323059965 | D46: 23595772023 | E46: 1429503754 | F46: 232384240 | G46: 899648018 | H46: 1205228437 | I46: 0 | J46: 175421182 | K46: 494914975 | L46: 4139280371 | M46: 78339876 | N46: 2207567564 | O46: 2221420707 | P46: 392675057 | Q46: 5051263 | R46: 14677970 | S46: 50056010 | T46: 296168593 | U46: =SUM(C46:T46) -> 38761170005
A47: Martin | B47: ='Parcel Ct by Type'!B47 -> R-Prelim | C47: 2538624641 | D47: 25406864019 | E47: 252864720 | F47: 2771502070 | G47: 366960271 | H47: 730389055 | I47: 50000377 | J47: 2648052 | K47: 230017832 | L47: 3169207730 | M47: 72353058 | N47: 1299891622 | O47: 549309530 | P47: 316011782 | Q47: 24876168 | R47: 33103336 | S47: 46899934 | T47: 221649958 | U47: =SUM(C47:T47) -> 38083174155
A48: Monroe | B48: ='Parcel Ct by Type'!B48 -> R-Prelim | C48: 1568571036 | D48: 32338044764 | E48: 1571102015 | F48: 5698137267 | G48: 1749775044 | H48: 532531271 | I48: 16641633 | J48: 132491289 | K48: 168653499 | L48: 8023570427 | M48: 6954369 | N48: 322838805 | O48: 53197 | P48: 120575411 | Q48: 8602502 | R48: 3832865 | S48: 40070624 | T48: 6969535 | U48: =SUM(C48:T48) -> 52309415553
A49: Nassau | B49: ='Parcel Ct by Type'!B49 -> R-Prelim | C49: 630027777 | D49: 11518142470 | E49: 595371219 | F49: 2476411599 | G49: 213599751 | H49: 463789696 | I49: 0 | J49: 108258313 | K49: 139893016 | L49: 1414307442 | M49: 16881761 | N49: 236547632 | O49: 362161098 | P49: 50092498 | Q49: 37189079 | R49: 2861527 | S49: 30691377 | T49: 192598910 | U49: =SUM(C49:T49) -> 18488825165
A50: Okaloosa | B50: ='Parcel Ct by Type'!B50 -> R-Prelim | C50: 717105956 | D50: 17602383834 | E50: 265641129 | F50: 5975202159 | G50: 362545205 | H50: 928757136 | I50: 840000 | J50: 0 | K50: 198033183 | L50: 2984318271 | M50: 2472957 | N50: 565182946 | O50: 213108668 | P50: 165747841 | Q50: 33021942 | R50: 0 | S50: 13453996 | T50: 102075406 | U50: =SUM(C50:T50) -> 30129890629
A51: Okeechobee | B51: ='Parcel Ct by Type'!B51 -> R-Prelim | C51: 251647210 | D51: 1321108682 | E51: 478715588 | F51: 17443110 | G51: 73922515 | H51: 12744773 | I51: 0 | J51: 1109749 | K51: 25867354 | L51: 496183634 | M51: 10214560 | N51: 112483314 | O51: 426669461 | P51: 38156887 | Q51: 0 | R51: 5936846 | S51: 89426542 | T51: 36638192 | U51: =SUM(C51:T51) -> 3398268417
A52: Orange | B52: ='Parcel Ct by Type'!B52 -> R-Prelim | C52: 1964185724 | D52: 109520542826 | E52: 494842653 | F52: 8298656567 | G52: 1330197970 | H52: 25515323550 | I52: 0 | J52: 83208592 | K52: 2352454553 | L52: 64742720420 | M52: 547630388 | N52: 17536220902 | O52: 408692422 | P52: 1157092834 | Q52: 762684773 | R52: 4260087 | S52: 113565152 | T52: 558814658 | U52: =SUM(C52:T52) -> 235391094071
A53: Osceola | B53: ='Parcel Ct by Type'!B53 -> R-Prelim | C53: 963814822 | D53: 37127810166 | E53: 554885481 | F53: 5619786784 | G53: 330446090 | H53: 4417754876 | I53: 0 | J53: 14949524 | K53: 739242030 | L53: 6648326940 | M53: 63798921 | N53: 1422678329 | O53: 225322143 | P53: 422830359 | Q53: 9488244 | R53: 5685241 | S53: 66226329 | T53: 165221356 | U53: =SUM(C53:T53) -> 58798267635
A54: Palm Beach | B54: ='Parcel Ct by Type'!B54 -> R-Prelim | C54: 7334741559 | D54: 202858595795 | E54: 370183180 | F54: 55150636603 | G54: 4846362486 | H54: 16372561130 | I54: 1665273364 | J54: 2661949326 | K54: 1853229259 | L54: 40372880627 | M54: 268668708 | N54: 12377409252 | O54: 3533240976 | P54: 1681717914 | Q54: 55775198 | R54: 501479182 | S54: 516490021 | T54: 8491065 | U54: =SUM(C54:T54) -> 352429685645
A55: Pasco | B55: ='Parcel Ct by Type'!B55 -> R-Prelim | C55: 1364633847 | D55: 43881480741 | E55: 1684958795 | F55: 996983880 | G55: 546516727 | H55: 3411495268 | I55: 0 | J55: 49938059 | K55: 814506006 | L55: 5631824324 | M55: 54636783 | N55: 1910010481 | O55: 398906946 | P55: 537299726 | Q55: 6984125 | R55: 269424 | S55: 67915307 | T55: 174705492 | U55: =SUM(C55:T55) -> 61533065931
A56: Pinellas | B56: ='Parcel Ct by Type'!B56 -> R-Prelim | C56: 2043664091 | D56: 68548653718 | E56: 1107157830 | F56: 24586622587 | G56: 5343833543 | H56: 9829508778 | I56: 148218529 | J56: 31808825 | K56: 1004124523 | L56: 19019101093 | M56: 172606172 | N56: 6127795902 | O56: 30162159 | P56: 1401964425 | Q56: 1773880 | R56: 145947950 | S56: 237019844 | T56: 5941225 | U56: =SUM(C56:T56) -> 139785905074
... A62: Sarasota | B62: ='Parcel Ct by Type'!B62 -> R-Prelim | C62: 3041130296 | D62: 60097767606 | E62: 939655202 | F62: 20871387905 | G62: 3281051604 | H62: 3569656849 | I62: 86223702 | J62: 819679067 | K62: 835817122 | L62: 11169787057 | M62: 62453278 | N62: 2788793877 | O62: 157789363 | P62: 937088813 | Q62: 28303644 | R62: 1287290 | S62: 116225259 | T62: 395558872 | U62: =SUM(C62:T62) -> 109199656806
A63: Seminole | B63: ='Parcel Ct by Type'!B63 -> R-Prelim | C63: 506330480 | D63: 35674447955 | E63: 164403142 | F63: 1790876748 | G63: 329745178 | H63: 6384350556 | I63: 0 | J63: 62275790 | K63: 566545996 | L63: 7556296838 | M63: 109275707 | N63: 3078914556 | O63: 50336094 | P63: 881103513 | Q63: 2682340 | S63: 71273627 | T63: 525850 | U63: =SUM(C63:T63) -> 57229384370
A64: Sumter | B64: ='Parcel Ct by Type'!B64 -> R-Prelim | C64: 288294219 | D64: 20339566486 | E64: 266355768 | F64: 49875196 | G64: 16786007 | H64: 525194140 | I64: 0 | J64: 1989850 | K64: 137789721 | L64: 1839202898 | M64: 15845660 | N64: 451879920 | O64: 378603579 | P64: 352877659 | Q64: 3794960 | R64: 0 | S64: 34434041 | T64: 131683755 | U64: =SUM(C64:T64) -> 24834173859
A65: Suwannee | B65: ='Parcel Ct by Type'!B65 -> R-Prelim | C65: 232450135 | D65: 706449955 | E65: 442823648 | F65: 0 | G65: 9643905 | H65: 8239003 | I65: 0 | J65: 237596 | K65: 38269218 | L65: 209062166 | M65: 43827 | N65: 110115996 | O65: 396427362 | P65: 19252577 | Q65: 3910346 | R65: 0 | S65: 14248769 | T65: 53661960 | U65: =SUM(C65:T65) -> 2244836463
A66: Taylor | B66: ='Parcel Ct by Type'!B66 -> R-Prelim | C66: 206290843 | D66: 517948920 | E66: 176312183 | F66: 11836709 | G66: 4422067 | H66: 26153521 | I66: 0 | J66: 0 | K66: 3829299 | L66: 120860120 | M66: 0 | N66: 31500624 | O66: 222883856 | P66: 2890120 | Q66: 774517 | R66: 150290 | S66: 6268456 | T66: 23301256 | U66: =SUM(C66:T66) -> 1355422781
A67: Union | B67: ='Parcel Ct by Type'!B67 -> R-Prelim | C67: 11207820 | D67: 114323590 | E67: 50553950 | F67: 1170000 | G67: 54507 | H67: 2143307 | I67: 0 | J67: 1960185 | K67: 931614 | L67: 17983174 | M67: 250000 | N67: 3492599 | O67: 110249323 | P67: 1428599 | Q67: 76927 | R67: 118587 | S67: 11736435 | T67: 0 | U67: =SUM(C67:T67) -> 327680617
A68: Volusia | B68: ='Parcel Ct by Type'!B68 -> R-Prelim | C68: 1174365732 | D68: 39208543024 | E68: 624963190 | F68: 7053470129 | G68: 801657382 | H68: 3005800516 | I68: 41909022 | J68: 107771 | K68: 760106885 | L68: 7915426036 | M68: 80685456 | N68: 2375789205 | O68: 471461834 | P68: 623928532 | Q68: 76784200 | R68: 106614643 | S68: 75020402 | T68: 154332140 | U68: =SUM(C68:T68) -> 64550966099
A69: Wakulla | B69: ='Parcel Ct by Type'!B69 -> R-Prelim | C69: 132867117 | D69: 1637902255 | E69: 153455093 | F69: 71444176 | G69: 5395960 | H69: 9203537 | I69: 0 | J69: 76922 | K69: 26405910 | L69: 177803461 | M69: 824808 | N69: 32096072 | O69: 153241920 | P69: 4664570 | Q69: 83803 | S69: 4483795 | T69: 23986421 | U69: =SUM(C69:T69) -> 2433935820
...
