Workbook

Sheet Report Index
A2: Statewide Taxable Value Summary Information by County
B4: Taxable Value is the value of the property that is subject to taxes. Taxable Value is the Assessed Value minus all Exemption Amounts.
B11: Taxable Value All Property Types
B13: All Property Types Taxable Value and Growth Rate
B15: Real Property Taxable Value and Growth Rate
B17: Personal Property Taxable Value and Growth Rate
B19: Centrally Assessed Property Taxable Value and Growth Rate
A25: Contact Information: | D25: Property Tax Oversight, Research & Analysis
D26: PTOResearchAnalysis@floridarevenue.com

Sheet Taxable Value All Property
A1: Taxable Value All Property Types
A2: 2026
A4: County | B4: Status | C4: 2026 Real Property Taxable Value | D4: 2026 Personal Property Taxable Value | E4: 2026 Central Assessment Taxable Value | F4: 2026 Total Taxable Value
A5: Alachua | B5: R-Prelim | C5: 24984937848 | D5: 1834912685 | E5: 34303595 | F5: 26854154128
A6: Baker | B6: R-Prelim | C6: 1491396246 | D6: 261288818 | E6: 12935918 | F6: 1765620982
A7: Bay | B7: R-Prelim | C7: 31583267225 | D7: 2021274008 | E7: 30048586 | F7: 33634589819
A8: Bradford | B8: R-Prelim | C8: 1302370466 | D8: 338821578 | E8: 19011301 | F8: 1660203345
A9: Brevard | B9: R-Prelim | C9: 70796922004 | D9: 5472928883 | E9: 133170242 | F9: 76403021129
A10: Broward | B10: R-Prelim | C10: 323498636835 | D10: 12334321522 | E10: 102997418 | F10: 335935955775
A11: Calhoun | B11: R-Prelim | C11: 496294844 | D11: 330947244 | F11: 827242088
A12: Charlotte | B12: R-Prelim | C12: 33527499865 | D12: 1687398858 | E12: 2569215 | F12: 35217467938
A13: Citrus | B13: R-Prelim | C13: 14991997132 | D13: 2209781933 | E13: 952202 | F13: 17202731267
A14: Clay | B14: R-Prelim | C14: 19439425064 | D14: 1610660395 | E14: 34476820 | F14: 21084562279
A15: Collier | B15: R-Prelim | C15: 166850916726 | D15: 3428109701 | E15: 89915 | F15: 170279116342
A16: Columbia | B16: R-Prelim | C16: 4126193239 | D16: 860736555 | E16: 12811609 | F16: 4999741403
A17: Miami-Dade | B17: R-Prelim | C17: 517315619073 | D17: 22627690074 | E17: 193946998 | F17: 540137256145
A18: DeSoto | B18: R-Prelim | C18: 2229068600 | D18: 717284372 | E18: 4188494 | F18: 2950541466
A19: Dixie | B19: R-Prelim | C19: 758677117 | D19: 135001266 | F19: 893678383
A20: Duval | B20: R-Prelim | C20: 114573427448 | D20: 9484213268 | E20: 224878009 | F20: 124282518725
A21: Escambia | B21: R-Prelim | C21: 30333583327 | D21: 4163342388 | E21: 32777979 | F21: 34529703694
A22: Flagler | B22: R-Prelim | C22: 18134585556 | D22: 708458209 | E22: 22985158 | F22: 18866028923
A23: Franklin | B23: R-Prelim | C23: 3968007954 | D23: 100512891 | F23: 4068520845
A24: Gadsden | B24: R-Prelim | C24: 1962839965 | D24: 629141090 | E24: 9718016 | F24: 2601699071
A25: Gilchrist | B25: R-Prelim | C25: 1095768409 | D25: 484184898 | F25: 1579953307
A26: Glades | B26: R-Prelim | C26: 1021409287 | D26: 196604914 | E26: 14004551 | F26: 1232018752
A27: Gulf | B27: R-Prelim | C27: 4155495260 | D27: 169303286 | F27: 4324798546
A28: Hamilton | B28: R-Prelim | C28: 657923871 | D28: 696399584 | E28: 21586919 | F28: 1375910374
A29: Hardee | B29: R-Prelim | C29: 1873005658 | D29: 1220217202 | E29: 9231645 | F29: 3102454505
A30: Hendry | B30: R-Prelim | C30: 3550889482 | D30: 1634757746 | E30: 4718991 | F30: 5190366219
A31: Hernando | B31: R-Prelim | C31: 17572471350 | D31: 1863524652 | E31: 11972769 | F31: 19447968771
A32: Highlands | B32: R-Prelim | C32: 8511143297 | D32: 654007301 | E32: 34524211 | F32: 9199674809
A33: Hillsborough | B33: R-Prelim | C33: 174872419451 | D33: 11484448635 | E33: 135439671 | F33: 186492307757
A34: Holmes | B34: R-Prelim | C34: 652914924 | D34: 125936600 | E34: 3923159 | F34: 782774683
A35: Indian River | B35: R-Prelim | C35: 32365991932 | D35: 1473431737 | E35: 44944531 | F35: 33884368200
A36: Jackson | B36: R-Prelim | C36: 2001338181 | D36: 552170555 | E36: 26561482 | F36: 2580070218
A37: Jefferson | B37: R-Prelim | C37: 973410213 | D37: 256013579 | E37: 3137317 | F37: 1232561109
A38: Lafayette | B38: R-Prelim | C38: 339227082 | D38: 77306861 | F38: 416533943
A39: Lake | B39: R-Prelim | C39: 46176093611 | D39: 2533013751 | E39: 4940180 | F39: 48714047542
A40: Lee | B40: R-Prelim | C40: 149219122905 | D40: 7120179880 | E40: 4542884 | F40: 156343845669
A41: Leon | B41: R-Prelim | C41: 27214712780 | D41: 1514537009 | E41: 6172685 | F41: 28735422474
...

Sheet All Property Taxable Value
A1: All Property Types Taxable Value and Growth Rate
A2: 2024-2026
A4: County | B4: Status | C4: 2026 Value | D4: Percent increase 2025-2026 | E4: 2025 Value | F4: Percent increase 2024-2025 | G4: 2024 Value
A5: Alachua | B5: ='Taxable Value All Property'!B5 -> R-Prelim | C5: 26854154128 | D5: =((C5-E5)/E5) -> 0.075229504 | E5: 24975276470 | F5: =((E5-G5)/G5) -> 0.074835342 | G5: 23236374449
A6: Baker | B6: ='Taxable Value All Property'!B6 -> R-Prelim | C6: 1765620982 | D6: =((C6-E6)/E6) -> 0.038797835 | E6: 1699677187 | F6: =((E6-G6)/G6) -> 0.093293288 | G6: 1554639735
A7: Bay | B7: ='Taxable Value All Property'!B7 -> R-Prelim | C7: 33634589819 | D7: =((C7-E7)/E7) -> 0.055308332 | E7: 31871813002 | F7: =((E7-G7)/G7) -> 0.077049679 | G7: 29591776137
A8: Bradford | B8: ='Taxable Value All Property'!B8 -> R-Prelim | C8: 1660203345 | D8: =((C8-E8)/E8) -> 0.05284387 | E8: 1576875159 | F8: =((E8-G8)/G8) -> 0.090977157 | G8: 1445378713
A9: Brevard | B9: ='Taxable Value All Property'!B9 -> R-Prelim | C9: 76403021129 | D9: =((C9-E9)/E9) -> 0.045650721 | E9: 73067439828 | F9: =((E9-G9)/G9) -> 0.07530826 | G9: 67950226532
A10: Broward | B10: ='Taxable Value All Property'!B10 -> R-Prelim | C10: 335935955775 | D10: =((C10-E10)/E10) -> 0.055055718 | E10: 318405890883 | F10: =((E10-G10)/G10) -> 0.080990793 | G10: 294550048850
A11: Calhoun | B11: ='Taxable Value All Property'!B11 -> R-Prelim | C11: 827242088 | D11: =((C11-E11)/E11) -> 0.16256421 | E11: 711566792 | F11: =((E11-G11)/G11) -> 0.086927155 | G11: 654659136
A12: Charlotte | B12: ='Taxable Value All Property'!B12 -> R-Prelim | C12: 35217467938 | D12: =((C12-E12)/E12) -> 0.02175117 | E12: 34467753973 | F12: =((E12-G12)/G12) -> 0.079143721 | G12: 31939910605
A13: Citrus | B13: ='Taxable Value All Property'!B13 -> R-Prelim | C13: 17202731267 | D13: =((C13-E13)/E13) -> 0.069900634 | E13: 16078812113 | F13: =((E13-G13)/G13) -> 0.078134345 | G13: 14913551528
A14: Clay | B14: ='Taxable Value All Property'!B14 -> R-Prelim | C14: 21084562279 | D14: =((C14-E14)/E14) -> 0.053927337 | E14: 20005707736 | F14: =((E14-G14)/G14) -> 0.084858213 | G14: 18440850153
A15: Collier | B15: ='Taxable Value All Property'!B15 -> R-Prelim | C15: 170279116342 | D15: =((C15-E15)/E15) -> 0.03498896 | E15: 164522640259 | F15: =((E15-G15)/G15) -> 0.082131203 | G15: 152035760421
A16: Columbia | B16: ='Taxable Value All Property'!B16 -> R-Prelim | C16: 4999741403 | D16: =((C16-E16)/E16) -> 0.060355461 | E16: 4715155990 | F16: =((E16-G16)/G16) -> 0.086412626 | G16: 4340115237
... A71: Washington | B71: ='Taxable Value All Property'!B71 -> R-Prelim | C71: 1638995866 | D71: =((C71-E71)/E71) -> 0.10115163 | E71: 1488437945 | F71: =((E71-G71)/G71) -> 0.10852813 | G71: 1342715544
A73: Statewide | C73: =SUM(C4:C71) -> 3672580670613 | D73: =((C73-E73)/E73) -> 0.060489929 | E73: =SUM(E5:E71) -> 3463098112584 | F73: =((E73-G73)/G73) -> 0.0789097 | G73: =SUM(G5:G71) -> 3209812750807
A75: Data Extract: July 2026

Sheet Real Property Taxable Value
A1: Real Property Taxable Value and Growth Rate
A2: 2024-2026
A4: County | B4: Status | C4: 2026 Value | D4: Percent increase 2025-2026 | E4: 2025 Value | F4: Percent increase 2024-2025 | G4: 2024 Value
A5: Alachua | B5: ='Taxable Value All Property'!B5 -> R-Prelim | C5: 24984937848 | D5: =((C5-E5)/E5) -> 0.075020649 | E5: 23241356230 | F5: =((E5-G5)/G5) -> 0.07919466 | G5: 21535833229
A6: Baker | B6: ='Taxable Value All Property'!B6 -> R-Prelim | C6: 1491396246 | D6: =((C6-E6)/E6) -> 0.066115701 | E6: 1398906558 | F6: =((E6-G6)/G6) -> 0.073456898 | G6: 1303179066
A7: Bay | B7: ='Taxable Value All Property'!B7 -> R-Prelim | C7: 31583267225 | D7: =((C7-E7)/E7) -> 0.060059854 | E7: 29793852771 | F7: =((E7-G7)/G7) -> 0.081899503 | G7: 27538466088
A8: Bradford | B8: ='Taxable Value All Property'!B8 -> R-Prelim | C8: 1302370466 | D8: =((C8-E8)/E8) -> 0.078118418 | E8: 1208003170 | F8: =((E8-G8)/G8) -> 0.10281977 | G8: 1095376786
A9: Brevard | B9: ='Taxable Value All Property'!B9 -> R-Prelim | C9: 70796922004 | D9: =((C9-E9)/E9) -> 0.051454915 | E9: 67332342087 | F9: =((E9-G9)/G9) -> 0.075475176 | G9: 62607063009
A10: Broward | B10: ='Taxable Value All Property'!B10 -> R-Prelim | C10: 323498636835 | D10: =((C10-E10)/E10) -> 0.055346956 | E10: 306532970166 | F10: =((E10-G10)/G10) -> 0.081860973 | G10: 283338596980
A11: Calhoun | B11: ='Taxable Value All Property'!B11 -> R-Prelim | C11: 496294844 | D11: =((C11-E11)/E11) -> 0.065249985 | E11: 465895190 | F11: =((E11-G11)/G11) -> 0.041642121 | G11: 447269922
A12: Charlotte | B12: ='Taxable Value All Property'!B12 -> R-Prelim | C12: 33527499865 | D12: =((C12-E12)/E12) -> 0.020922744 | E12: 32840388818 | F12: =((E12-G12)/G12) -> 0.077647716 | G12: 30474141337
A13: Citrus | B13: ='Taxable Value All Property'!B13 -> R-Prelim | C13: 14991997132 | D13: =((C13-E13)/E13) -> 0.073741836 | E13: 13962385214 | F13: =((E13-G13)/G13) -> 0.079150845 | G13: 12938307256
A14: Clay | B14: ='Taxable Value All Property'!B14 -> R-Prelim | C14: 19439425064 | D14: =((C14-E14)/E14) -> 0.055344984 | E14: 18419972006 | F14: =((E14-G14)/G14) -> 0.085372153 | G14: 16971111672
A15: Collier | B15: ='Taxable Value All Property'!B15 -> R-Prelim | C15: 166850916726 | D15: =((C15-E15)/E15) -> 0.033541896 | E15: 161436045708 | F15: =((E15-G15)/G15) -> 0.082767867 | G15: 149095711652
A16: Columbia | B16: ='Taxable Value All Property'!B16 -> R-Prelim | C16: 4126193239 | D16: =((C16-E16)/E16) -> 0.076769055 | E16: 3832013208 | F16: =((E16-G16)/G16) -> 0.078136305 | G16: 3554293822
... A71: Washington | B71: ='Taxable Value All Property'!B71 -> R-Prelim | C71: 1268672607 | D71: =((C71-E71)/E71) -> 0.088997967 | E71: 1164990795 | F71: =((E71-G71)/G71) -> 0.12175362 | G71: 1038544267
A73: Statewide | C73: =SUM(C5:C71) -> 3470967695716 | D73: =((C73-E73)/E73) -> 0.060808017 | E73: =SUM(E5:E71) -> 3272003642175 | F73: =((E73-G73)/G73) -> 0.080633652 | G73: =SUM(G5:G71) -> 3027856513495
A75: Data Extract: July 2026

Sheet Personal Property Taxable Value
A1: Personal Property Taxable Value and Growth Rate
A2: 2024-2026
A4: County | B4: Status | C4: 2026 Value | D4: Percent increase 2025-2026 | E4: 2025 Value | F4: Percent increase 2024-2025 | G4: 2024 Value
A5: Alachua | B5: ='Taxable Value All Property'!B5 -> R-Prelim | C5: 1834912685 | D5: =((C5-E5)/E5) -> 0.079497206 | E5: 1699784561 | F5: =((E5-G5)/G5) -> 0.019017333 | G5: 1668062462
A6: Baker | B6: ='Taxable Value All Property'!B6 -> R-Prelim | C6: 261288818 | D6: =((C6-E6)/E6) -> -0.095333967 | E6: 288823509 | F6: =((E6-G6)/G6) -> 0.21893116 | G6: 236948172
A7: Bay | B7: ='Taxable Value All Property'!B7 -> R-Prelim | C7: 2021274008 | D7: =((C7-E7)/E7) -> -0.014206955 | E7: 2050404006 | F7: =((E7-G7)/G7) -> 0.015482796 | G7: 2019142042
A8: Bradford | B8: ='Taxable Value All Property'!B8 -> R-Prelim | C8: 338821578 | D8: =((C8-E8)/E8) -> -0.032332181 | E8: 350142447 | F8: =((E8-G8)/G8) -> 0.053944065 | G8: 332221091
A9: Brevard | B9: ='Taxable Value All Property'!B9 -> R-Prelim | C9: 5472928883 | D9: =((C9-E9)/E9) -> -0.021081247 | E9: 5590789704 | F9: =((E9-G9)/G9) -> 0.075547894 | G9: 5198085308
A10: Broward | B10: ='Taxable Value All Property'!B10 -> R-Prelim | C10: 12334321522 | D10: =((C10-E10)/E10) -> 0.048761268 | E10: 11760847677 | F10: =((E10-G10)/G10) -> 0.05943591 | G10: 11101046857
A11: Calhoun | B11: ='Taxable Value All Property'!B11 -> R-Prelim | C11: 330947244 | D11: =((C11-E11)/E11) -> 0.34711233 | E11: 245671602 | F11: =((E11-G11)/G11) -> 0.18459199 | G11: 207389214
A12: Charlotte | B12: ='Taxable Value All Property'!B12 -> R-Prelim | C12: 1687398858 | D12: =((C12-E12)/E12) -> 0.038624644 | E12: 1624647430 | F12: =((E12-G12)/G12) -> 0.11049879 | G12: 1462988923
A13: Citrus | B13: ='Taxable Value All Property'!B13 -> R-Prelim | C13: 2209781933 | D13: =((C13-E13)/E13) -> 0.04467628 | E13: 2115279130 | F13: =((E13-G13)/G13) -> 0.071450892 | G13: 1974219393
A14: Clay | B14: ='Taxable Value All Property'!B14 -> R-Prelim | C14: 1610660395 | D14: =((C14-E14)/E14) -> 0.037228226 | E14: 1552850525 | F14: =((E14-G14)/G14) -> 0.068267318 | G14: 1453616056
A15: Collier | B15: ='Taxable Value All Property'!B15 -> R-Prelim | C15: 3428109701 | D15: =((C15-E15)/E15) -> 0.11067392 | E15: 3086513175 | F15: =((E15-G15)/G15) -> 0.049845972 | G15: 2939967632
A16: Columbia | B16: ='Taxable Value All Property'!B16 -> R-Prelim | C16: 860736555 | D16: =((C16-E16)/E16) -> -0.012149927 | E16: 871323067 | F16: =((E16-G16)/G16) -> 0.12986185 | G16: 771176645
... A71: Washington | B71: ='Taxable Value All Property'!B71 -> R-Prelim | C71: 368293543 | D71: =((C71-E71)/E71) -> 0.14518949 | E71: 321600527 | F71: =((E71-G71)/G71) -> 0.06314661 | G71: 302498756
A73: Statewide | C73: =SUM(C5:C71) -> 199442821246 | D73: =((C73-E73)/E73) -> 0.056015349 | E73: =SUM(E5:E71) -> 188863562909 | F73: =((E73-G73)/G73) -> 0.050736675 | G73: =SUM(G5:G71) -> 179743952392
A75: Data Extract: July 2026

Sheet Central Assessed Taxable Value 
A1: Centrally Assessed Property Taxable Value and Growth Rate
A2: 2024-2026
A4: County | B4: Status | C4: 2026 Value | D4: Percent increase 2025-2026 | E4: 2025 Value | F4: Percent increase 2024-2025 | G4: 2024 Value
A5: Alachua | B5: ='Taxable Value All Property'!B5 -> R-Prelim | C5: 34303595 | D5: =((C5-E5)/E5) -> 0.004919076 | E5: 34135679 | F5: =((E5-G5)/G5) -> 0.051015528 | G5: 32478758
A6: Baker | B6: ='Taxable Value All Property'!B6 -> R-Prelim | C6: 12935918 | D6: =((C6-E6)/E6) -> 0.082764549 | E6: 11947120 | F6: =((E6-G6)/G6) -> -0.1767702 | G6: 14512497
A7: Bay | B7: ='Taxable Value All Property'!B7 -> R-Prelim | C7: 30048586 | D7: =((C7-E7)/E7) -> 0.090446387 | E7: 27556225 | F7: =((E7-G7)/G7) -> -0.19350798 | G7: 34168007
A8: Bradford | B8: ='Taxable Value All Property'!B8 -> R-Prelim | C8: 19011301 | D8: =((C8-E8)/E8) -> 0.015043561 | E8: 18729542 | F8: =((E8-G8)/G8) -> 0.053355534 | G8: 17780836
A9: Brevard | B9: ='Taxable Value All Property'!B9 -> R-Prelim | C9: 133170242 | D9: =((C9-E9)/E9) -> -0.077180698 | E9: 144308037 | F9: =((E9-G9)/G9) -> -0.0053087088 | G9: 145078215
A10: Broward | B10: ='Taxable Value All Property'!B10 -> R-Prelim | C10: 102997418 | D10: =((C10-E10)/E10) -> -0.080979529 | E10: 112073040 | F10: =((E10-G10)/G10) -> 0.015108254 | G10: 110405013
A11: Calhoun | B11: ='Taxable Value All Property'!B11 -> R-Prelim | D11: n/a | F11: n/a
A12: Charlotte | B12: ='Taxable Value All Property'!B12 -> R-Prelim | C12: 2569215 | D12: =((C12-E12)/E12) -> -0.05464497 | E12: 2717725 | F12: =((E12-G12)/G12) -> -0.022522385 | G12: 2780345
A13: Citrus | B13: ='Taxable Value All Property'!B13 -> R-Prelim | C13: 952202 | D13: =((C13-E13)/E13) -> -0.17038882 | E13: 1147769 | F13: =((E13-G13)/G13) -> 0.11990684 | G13: 1024879
A14: Clay | B14: ='Taxable Value All Property'!B14 -> R-Prelim | C14: 34476820 | D14: =((C14-E14)/E14) -> 0.048399121 | E14: 32885205 | F14: =((E14-G14)/G14) -> 1.0397183 | G14: 16122425
A15: Collier | B15: ='Taxable Value All Property'!B15 -> R-Prelim | C15: 89915 | D15: =((C15-E15)/E15) -> 0.10493266 | E15: 81376 | F15: =((E15-G15)/G15) -> 0.0029456352 | G15: 81137
A16: Columbia | B16: ='Taxable Value All Property'!B16 -> R-Prelim | C16: 12811609 | D16: =((C16-E16)/E16) -> 0.083918605 | E16: 11819715 | F16: =((E16-G16)/G16) -> -0.19290539 | G16: 14644770
A17: Miami-Dade | B17: ='Taxable Value All Property'!B17 -> R-Prelim | C17: 193946998 | D17: =((C17-E17)/E17) -> -0.090104591 | E17: 213153068 | F17: =((E17-G17)/G17) -> 0.0036791528 | G17: 212371720
A18: DeSoto | B18: ='Taxable Value All Property'!B18 -> R-Prelim | C18: 4188494 | D18: =((C18-E18)/E18) -> -0.015055551 | E18: 4252518 | F18: =((E18-G18)/G18) -> 0.015742327 | G18: 4186611
A19: Dixie | B19: ='Taxable Value All Property'!B19 -> R-Prelim | D19: n/a | F19: n/a
A20: Duval | B20: ='Taxable Value All Property'!B20 -> R-Prelim | C20: 224878009 | D20: =((C20-E20)/E20) -> 0.019980242 | E20: 220472907 | F20: =((E20-G20)/G20) -> 0.014809599 | G20: 217255441
A21: Escambia | B21: ='Taxable Value All Property'!B21 -> R-Prelim | C21: 32777979 | D21: =((C21-E21)/E21) -> 0.0025282213 | E21: 32695318 | F21: =((E21-G21)/G21) -> 0.047156394 | G21: 31222956
A22: Flagler | B22: ='Taxable Value All Property'!B22 -> R-Prelim | C22: 22985158 | D22: =((C22-E22)/E22) -> -0.01184433 | E22: 23260665 | F22: =((E22-G22)/G22) -> -0.018212606 | G22: 23692161
A23: Franklin | B23: ='Taxable Value All Property'!B23 -> R-Prelim | D23: n/a | F23: =((E23-G23)/G23) -> -1 | G23: 606482
A24: Gadsden | B24: ='Taxable Value All Property'!B24 -> R-Prelim | C24: 9718016 | D24: =((C24-E24)/E24) -> 0.079223635 | E24: 9004636 | F24: =((E24-G24)/G24) -> 0.16513843 | G24: 7728383
A25: Gilchrist | B25: ='Taxable Value All Property'!B25 -> R-Prelim | D25: n/a | F25: n/a
A26: Glades | B26: ='Taxable Value All Property'!B26 -> R-Prelim | C26: 14004551 | D26: =((C26-E26)/E26) -> 0.052818686 | E26: 13301959 | F26: =((E26-G26)/G26) -> -0.11779818 | G26: 15078136
A27: Gulf | B27: ='Taxable Value All Property'!B27 -> R-Prelim | D27: n/a | F27: =((E27-G27)/G27) -> -1 | G27: 514934
A28: Hamilton | B28: ='Taxable Value All Property'!B28 -> R-Prelim | C28: 21586919 | D28: =((C28-E28)/E28) -> 0.087249274 | E28: 19854618 | F28: =((E28-G28)/G28) -> -0.26154528 | G28: 26886710
A29: Hardee | B29: ='Taxable Value All Property'!B29 -> R-Prelim | C29: 9231645 | D29: =((C29-E29)/E29) -> 0.020003083 | E29: 9050605 | F29: =((E29-G29)/G29) -> 0.057947819 | G29: 8554869
A30: Hendry | B30: ='Taxable Value All Property'!B30 -> R-Prelim | C30: 4718991 | D30: =((C30-E30)/E30) -> 0.059441066 | E30: 4454227 | F30: =((E30-G30)/G30) -> -0.10528226 | G30: 4978360
A31: Hernando | B31: ='Taxable Value All Property'!B31 -> R-Prelim | C31: 11972769 | D31: =((C31-E31)/E31) -> 0.019267794 | E31: 11746441 | F31: =((E31-G31)/G31) -> 0.056685077 | G31: 11116312
A32: Highlands | B32: ='Taxable Value All Property'!B32 -> R-Prelim | C32: 34524211 | D32: =((C32-E32)/E32) -> 0.032200272 | E32: 33447202 | F32: =((E32-G32)/G32) -> -0.029343669 | G32: 34458336
A33: Hillsborough | B33: ='Taxable Value All Property'!B33 -> R-Prelim | C33: 135439671 | D33: =((C33-E33)/E33) -> 0.01666503 | E33: 133219563 | F33: =((E33-G33)/G33) -> 0.033774306 | G33: 128867164
A34: Holmes | B34: ='Taxable Value All Property'!B34 -> R-Prelim | C34: 3923159 | D34: =((C34-E34)/E34) -> 0.2056468 | E34: 3253987 | F34: =((E34-G34)/G34) -> -0.04033188 | G34: 3390742
A35: Indian River | B35: ='Taxable Value All Property'!B35 -> R-Prelim | C35: 44944531 | D35: =((C35-E35)/E35) -> -0.098805006 | E35: 49872149 | F35: =((E35-G35)/G35) -> 0.00022071295 | G35: 49861144
A36: Jackson | B36: ='Taxable Value All Property'!B36 -> R-Prelim | C36: 26561482 | D36: =((C36-E36)/E36) -> 0.086446187 | E36: 24448042 | F36: =((E36-G36)/G36) -> -0.11388135 | G36: 27590032
A37: Jefferson | B37: ='Taxable Value All Property'!B37 -> R-Prelim | C37: 3137317 | D37: =((C37-E37)/E37) -> 0.089463828 | E37: 2879689 | F37: =((E37-G37)/G37) -> 0.08731969 | G37: 2648429
A38: Lafayette | B38: ='Taxable Value All Property'!B38 -> R-Prelim | D38: n/a | E38: 0 | F38: n/a
A39: Lake | B39: ='Taxable Value All Property'!B39 -> R-Prelim | C39: 4940180 | D39: =((C39-E39)/E39) -> 0.10323343 | E39: 4477910 | F39: =((E39-G39)/G39) -> 0.0071298943 | G39: 4446209
A40: Lee | B40: ='Taxable Value All Property'!B40 -> R-Prelim | C40: 4542884 | D40: =((C40-E40)/E40) -> -0.048114504 | E40: 4772511 | F40: =((E40-G40)/G40) -> -0.054636628 | G40: 5048335
A41: Leon | B41: ='Taxable Value All Property'!B41 -> R-Prelim | C41: 6172685 | D41: =((C41-E41)/E41) -> 0.075619584 | E41: 5738725 | F41: =((E41-G41)/G41) -> 0.077212973 | G41: 5327382
...
