Workbook

Sheet Report Index
A2: 2008 Constitutional Amendment Impact Report
B4: Summary of 2008 Constitutional Amendment Impact: 2021
B6: 2008 Constitutional Amendment Impact to Taxable Value: 2009-2021
B8: 2008 Constitutional Amendment Impact in 2021
B10: 2008 Constitutional Amendment Impact by Category: 2009-2021
B12: Additional $25K Homestead Exemption for Non-School Levies: 2009-2021
B14: $25K Tangible Personal Property Exemption: 2009-2021
B16: 10% Non-Homestead Assessment Increase Limitation: 2009-2021
B18: 10% Non-Homestead Assessment Increase Limitation (School Taxable Value > '0'): 2010-2021
B20: Homestead Portability Impact: 2009-2021
A26: Contact Information: | D26: Property Tax Oversight, Research & Analysis
D27: PTOResearchAnalysis@floridarevenue

Sheet Amendment 1 Summary
A1: Summary of 2008 Constitutional Amendment Impact
A2: 2021
A4: County | B4: Status | C4: Total | D4: Additional $25K Exemption | E4: TPP $25K Exemption | F4: 10% Cap | G4: Portability
A5: Alachua | B5: R-NVAB | C5: =D5+E5+F5+G5 -> 2270008972 | D5: 1136734402 | E5: 78153825 | F5: 1017545800 | G5: 37574945
A6: Baker | B6: R-Final | C6: =D6+E6+F6+G6 -> 143032458 | D6: 118697611 | E6: 6989627 | F6: 13101813 | G6: 4243407
A7: Bay | B7: R-NVAB | C7: =D7+E7+F7+G7 -> 1621589936 | D7: 798569920 | E7: 82026463 | F7: 727632472 | G7: 13361081
A8: Bradford | B8: R-Final | C8: =D8+E8+F8+G8 -> 121450078 | D8: 102353370 | E8: 9169201 | F8: 8043434 | G8: 1884073
A9: Brevard | B9: R-NVAB | C9: =D9+E9+F9+G9 -> 5353890537 | D9: 3505410815 | E9: 166343003 | F9: 1458250839 | G9: 223885880
A10: Broward | B10: R-NVAB | C10: =D10+E10+F10+G10 -> 16513189016 | D10: 9083807510 | E10: 807147296 | F10: 6117417380 | G10: 504816830
A11: Calhoun | B11: R-Final | C11: =D11+E11+F11+G11 -> 43910653 | D11: 36464601 | E11: 5024378 | F11: 2051855 | G11: 369819
A12: Charlotte | B12: R-NVAB | C12: =D12+E12+F12+G12 -> 2232637319 | D12: 1292277461 | E12: 98597856 | F12: 767536640 | G12: 74225362
A13: Citrus | B13: R-NVAB | C13: =D13+E13+F13+G13 -> 1303200477 | D13: 895834284 | E13: 55066060 | F13: 293630977 | G13: 58669156
A14: Clay | B14: R-NVAB | C14: =D14+E14+F14+G14 -> 1429946378 | D14: 1189837997 | E14: 50600521 | F14: 146773834 | G14: 42734026
A15: Collier | B15: R-NVAB | C15: =D15+E15+F15+G15 -> 5147522079 | D15: 2363885539 | E15: 162820987 | F15: 2433941918 | G15: 186873635
A16: Columbia | B16: R-Final | C16: =D16+E16+F16+G16 -> 326476747 | D16: 267598414 | E16: 23196763 | F16: 25912636 | G16: 9768934
... A71: Washington | B71: R-Final | C71: =D71+E71+F71+G71 -> 106318655 | D71: 80834699 | E71: 9713303 | F71: 14446749 | G71: 1323904
A73: Statewide | B73: Final | C73: =SUM(D73:G73) -> 200285917241 | D73: =SUM(D5:D71) -> 104297499940 | E73: =SUM(E5:E71) -> 7780543600 | F73: 82697686688 | G73: =SUM(G5:G71) -> 5510187013
A75: Data Extract: November 2021

Sheet Amendment 1 Impact
A1: 2008 Constitutional Amendment Impact to Taxable Value
A2: 2009-2021
C3: 2021 | F3: 2020 | I3: 2019 | L3: 2018 | O3: 2017 | R3: 2016 | U3: 2015 | X3: 2014 | AA3: 2013 | AD3: 2012 | AG3: 2011 | AJ3: 2010 | AM3: 2009
A4: County | B4: Status | C4: Taxable Value | D4: Amendment 1 Impact | E4: Percent Impact | F4: Taxable Value | G4: Amendment 1 Impact | H4: Percent Impact | I4: Taxable Value | J4: Amendment 1 Impact | K4: Percent Impact | L4: Taxable Value | M4: Amendment 1 Impact | N4: Percent Impact | O4: Taxable Value | P4: Amendment 1 Impact | Q4: Percent Impact | R4: Taxable Value | S4: Amendment 1 Impact | T4: Percent Impact | U4: Taxable Value | V4: Amendment 1 Impact | W4: Percent Impact | X4: Taxable Value | Y4: Amendment 1 Impact | Z4: Percent Impact | AA4: Taxable Value | AB4: Amendment 1 Impact | AC4: Percent Impact | AD4: Taxable Value | AE4: Amendment 1 Impact | AF4: Percent Impact | AG4: Taxable Value | AH4: Amendment 1 Impact | AI4: Percent Impact | AJ4: Taxable Value | AK4: Amendment 1 Impact | AL4: Percent Impact | AM4: Taxable Value | AN4: Amendment 1 Impact | AO4: Percent Impact
A5: Alachua | B5: R-NVAB | C5: 17228900917 | D5: =SUM('Additional 25K H_EX'!C5+'25K TPP EX'!C5+'10% Non-Homestead'!C5+'Portability Impact'!C5) -> 2270008972 | E5: =D5/C5 -> 0.13175588 | F5: 16184501452 | G5: =SUM('Additional 25K H_EX'!E5+'25K TPP EX'!E5+'10% Non-Homestead'!E5+'Portability Impact'!E5) -> 1957074006 | H5: =G5/F5 -> 0.12092272 | I5: 15257672680 | J5: =SUM('Additional 25K H_EX'!G5+'25K TPP EX'!G5+'10% Non-Homestead'!G5+'Portability Impact'!G5) -> 2143566962 | K5: =J5/I5 -> 0.14049108 | L5: 14253438005 | M5: =SUM('Additional 25K H_EX'!I5+'25K TPP EX'!I5+'10% Non-Homestead'!I5+'Portability Impact'!I5) -> 2068993158 | N5: =M5/L5 -> 0.14515748 | O5: 13581048400 | P5: =SUM('Additional 25K H_EX'!K5+'25K TPP EX'!K5+'10% Non-Homestead'!K5+'Portability Impact'!K5) -> 1825595523 | Q5: =P5/O5 -> 0.13442228 | R5: 12606261456 | S5: =SUM('Additional 25K H_EX'!M5+'25K TPP EX'!M5+'10% Non-Homestead'!M5+'Portability Impact'!M5) -> 1313390230 | T5: =S5/R5 -> 0.10418555 | U5: 12103270196 | V5: =SUM('Additional 25K H_EX'!O5+'25K TPP EX'!O5+'10% Non-Homestead'!O5+'Portability Impact'!O5) -> 1167928679 | W5: =V5/U5 -> 0.096496952 | X5: 11791403268 | Y5: =SUM('Additional 25K H_EX'!Q5+'25K TPP EX'!Q5+'10% Non-Homestead'!Q5+'Portability Impact'!Q5) -> 1145830953 | Z5: =Y5/X5 -> 0.097175114 | AA5: 11239983061 | AB5: =SUM('Additional 25K H_EX'!S5+'25K TPP EX'!S5+'10% Non-Homestead'!S5+'Portability Impact'!S5) -> 1260002052 | AC5: =AB5/AA5 -> 0.1121 | AD5: 11186774393 | AE5: =SUM('Additional 25K H_EX'!U5+'25K TPP EX'!U5+'10% Non-Homestead'!U5+'Portability Impact'!U5) -> 1119158527 | AF5: =AE5/AD5 -> 0.10004301 | AG5: 11610636972 | AH5: =SUM('Additional 25K H_EX'!W5+'25K TPP EX'!W5+'10% Non-Homestead'!W5+'Portability Impact'!W5) -> 1151346710 | AI5: =AH5/AG5 -> 0.099163096 | AJ5: 12052898624 | AK5: =SUM('Additional 25K H_EX'!Y5+'25K TPP EX'!Y5+'10% Non-Homestead'!Y5+'Portability Impact'!Y5) -> 1215353145 | AL5: =AK5/AJ5 -> 0.10083493 | AM5: 12558830292 | AN5: =SUM('Additional 25K H_EX'!AA5+'25K TPP EX'!AA5+'10% Non-Homestead'!AA5+'Portability Impact'!AA5) -> 1275091360 | AO5: =AN5/AM5 -> 0.10152947
A6: Baker | B6: R-Final | C6: 1124579841 | D6: =SUM('Additional 25K H_EX'!C6+'25K TPP EX'!C6+'10% Non-Homestead'!C6+'Portability Impact'!C6) -> 143032458 | E6: =D6/C6 -> 0.12718746 | F6: 1026085614 | G6: =SUM('Additional 25K H_EX'!E6+'25K TPP EX'!E6+'10% Non-Homestead'!E6+'Portability Impact'!E6) -> 136356591 | H6: =G6/F6 -> 0.13289007 | I6: 952001327 | J6: =SUM('Additional 25K H_EX'!G6+'25K TPP EX'!G6+'10% Non-Homestead'!G6+'Portability Impact'!G6) -> 124055087 | K6: =J6/I6 -> 0.13030978 | L6: 890720067 | M6: =SUM('Additional 25K H_EX'!I6+'25K TPP EX'!I6+'10% Non-Homestead'!I6+'Portability Impact'!I6) -> 115616304 | N6: =M6/L6 -> 0.12980094 | O6: 840223080 | P6: =SUM('Additional 25K H_EX'!K6+'25K TPP EX'!K6+'10% Non-Homestead'!K6+'Portability Impact'!K6) -> 109253281 | Q6: =P6/O6 -> 0.1300289 | R6: 807691673 | S6: =SUM('Additional 25K H_EX'!M6+'25K TPP EX'!M6+'10% Non-Homestead'!M6+'Portability Impact'!M6) -> 104384602 | T6: =S6/R6 -> 0.12923818 | U6: 777186107 | V6: =SUM('Additional 25K H_EX'!O6+'25K TPP EX'!O6+'10% Non-Homestead'!O6+'Portability Impact'!O6) -> 100463876 | W6: =V6/U6 -> 0.12926618 | X6: 770117554 | Y6: =SUM('Additional 25K H_EX'!Q6+'25K TPP EX'!Q6+'10% Non-Homestead'!Q6+'Portability Impact'!Q6) -> 100688284 | Z6: =Y6/X6 -> 0.13074404 | AA6: 749596354 | AB6: =SUM('Additional 25K H_EX'!S6+'25K TPP EX'!S6+'10% Non-Homestead'!S6+'Portability Impact'!S6) -> 97650802 | AC6: =AB6/AA6 -> 0.13027118 | AD6: 745566250 | AE6: =SUM('Additional 25K H_EX'!U6+'25K TPP EX'!U6+'10% Non-Homestead'!U6+'Portability Impact'!U6) -> 98198058 | AF6: =AE6/AD6 -> 0.13170937 | AG6: 775833785 | AH6: =SUM('Additional 25K H_EX'!W6+'25K TPP EX'!W6+'10% Non-Homestead'!W6+'Portability Impact'!W6) -> 104636652 | AI6: =AH6/AG6 -> 0.13486993 | AJ6: 802336380 | AK6: =SUM('Additional 25K H_EX'!Y6+'25K TPP EX'!Y6+'10% Non-Homestead'!Y6+'Portability Impact'!Y6) -> 103715736 | AL6: =AK6/AJ6 -> 0.12926715 | AM6: 807815246 | AN6: =SUM('Additional 25K H_EX'!AA6+'25K TPP EX'!AA6+'10% Non-Homestead'!AA6+'Portability Impact'!AA6) -> 107274484 | AO6: =AN6/AM6 -> 0.13279582
A7: Bay | B7: R-NVAB | C7: 19438620300 | D7: =SUM('Additional 25K H_EX'!C7+'25K TPP EX'!C7+'10% Non-Homestead'!C7+'Portability Impact'!C7) -> 1621589936 | E7: =D7/C7 -> 0.083421041 | F7: 17527161860 | G7: =SUM('Additional 25K H_EX'!E7+'25K TPP EX'!E7+'10% Non-Homestead'!E7+'Portability Impact'!E7) -> 1361552088 | H7: =G7/F7 -> 0.077682405 | I7: 16050988505 | J7: =SUM('Additional 25K H_EX'!G7+'25K TPP EX'!G7+'10% Non-Homestead'!G7+'Portability Impact'!G7) -> 1156684986 | K7: =J7/I7 -> 0.072063162 | L7: 16433018703 | M7: =SUM('Additional 25K H_EX'!I7+'25K TPP EX'!I7+'10% Non-Homestead'!I7+'Portability Impact'!I7) -> 1157314535 | N7: =M7/L7 -> 0.070426168 | O7: 15615281639 | P7: =SUM('Additional 25K H_EX'!K7+'25K TPP EX'!K7+'10% Non-Homestead'!K7+'Portability Impact'!K7) -> 1096177878 | Q7: =P7/O7 -> 0.070199046 | R7: 15129564922 | S7: =SUM('Additional 25K H_EX'!M7+'25K TPP EX'!M7+'10% Non-Homestead'!M7+'Portability Impact'!M7) -> 1023402411 | T7: =S7/R7 -> 0.067642554 | U7: 14637979228 | V7: =SUM('Additional 25K H_EX'!O7+'25K TPP EX'!O7+'10% Non-Homestead'!O7+'Portability Impact'!O7) -> 1039002580 | W7: =V7/U7 -> 0.070979919 | X7: 14190043326 | Y7: =SUM('Additional 25K H_EX'!Q7+'25K TPP EX'!Q7+'10% Non-Homestead'!Q7+'Portability Impact'!Q7) -> 1022696958 | Z7: =Y7/X7 -> 0.072071447 | AA7: 13944111814 | AB7: =SUM('Additional 25K H_EX'!S7+'25K TPP EX'!S7+'10% Non-Homestead'!S7+'Portability Impact'!S7) -> 982103345 | AC7: =AB7/AA7 -> 0.070431402 | AD7: 13720932291 | AE7: =SUM('Additional 25K H_EX'!U7+'25K TPP EX'!U7+'10% Non-Homestead'!U7+'Portability Impact'!U7) -> 983300528 | AF7: =AE7/AD7 -> 0.071664265 | AG7: 14237124084 | AH7: =SUM('Additional 25K H_EX'!W7+'25K TPP EX'!W7+'10% Non-Homestead'!W7+'Portability Impact'!W7) -> 990468690 | AI7: =AH7/AG7 -> 0.069569436 | AJ7: 15070375927 | AK7: =SUM('Additional 25K H_EX'!Y7+'25K TPP EX'!Y7+'10% Non-Homestead'!Y7+'Portability Impact'!Y7) -> 1066267726 | AL7: =AK7/AJ7 -> 0.070752563 | AM7: 16100957751 | AN7: =SUM('Additional 25K H_EX'!AA7+'25K TPP EX'!AA7+'10% Non-Homestead'!AA7+'Portability Impact'!AA7) -> 1031809347 | AO7: =AN7/AM7 -> 0.064083725
A8: Bradford | B8: R-Final | C8: 1086979460 | D8: =SUM('Additional 25K H_EX'!C8+'25K TPP EX'!C8+'10% Non-Homestead'!C8+'Portability Impact'!C8) -> 121450078 | E8: =D8/C8 -> 0.11173171 | F8: 1033358392 | G8: =SUM('Additional 25K H_EX'!E8+'25K TPP EX'!E8+'10% Non-Homestead'!E8+'Portability Impact'!E8) -> 111513720 | H8: =G8/F8 -> 0.10791389 | I8: 960788697 | J8: =SUM('Additional 25K H_EX'!G8+'25K TPP EX'!G8+'10% Non-Homestead'!G8+'Portability Impact'!G8) -> 106317372 | K8: =J8/I8 -> 0.11065635 | L8: 929061310 | M8: =SUM('Additional 25K H_EX'!I8+'25K TPP EX'!I8+'10% Non-Homestead'!I8+'Portability Impact'!I8) -> 102205670 | N8: =M8/L8 -> 0.11000961 | O8: 895134697 | P8: =SUM('Additional 25K H_EX'!K8+'25K TPP EX'!K8+'10% Non-Homestead'!K8+'Portability Impact'!K8) -> 98113015 | Q8: =P8/O8 -> 0.10960698 | R8: 875631893 | S8: =SUM('Additional 25K H_EX'!M8+'25K TPP EX'!M8+'10% Non-Homestead'!M8+'Portability Impact'!M8) -> 93735045 | T8: =S8/R8 -> 0.10704846 | U8: 855802803 | V8: =SUM('Additional 25K H_EX'!O8+'25K TPP EX'!O8+'10% Non-Homestead'!O8+'Portability Impact'!O8) -> 91673785 | W8: =V8/U8 -> 0.10712022 | X8: 829117834 | Y8: =SUM('Additional 25K H_EX'!Q8+'25K TPP EX'!Q8+'10% Non-Homestead'!Q8+'Portability Impact'!Q8) -> 91780857 | Z8: =Y8/X8 -> 0.110697 | AA8: 817407350 | AB8: =SUM('Additional 25K H_EX'!S8+'25K TPP EX'!S8+'10% Non-Homestead'!S8+'Portability Impact'!S8) -> 90224350 | AC8: =AB8/AA8 -> 0.11037869 | AD8: 817229276 | AE8: =SUM('Additional 25K H_EX'!U8+'25K TPP EX'!U8+'10% Non-Homestead'!U8+'Portability Impact'!U8) -> 93170893 | AF8: =AE8/AD8 -> 0.11400827 | AG8: 830580274 | AH8: =SUM('Additional 25K H_EX'!W8+'25K TPP EX'!W8+'10% Non-Homestead'!W8+'Portability Impact'!W8) -> 95708377 | AI8: =AH8/AG8 -> 0.11523074 | AJ8: 846871177 | AK8: =SUM('Additional 25K H_EX'!Y8+'25K TPP EX'!Y8+'10% Non-Homestead'!Y8+'Portability Impact'!Y8) -> 97779769 | AL8: =AK8/AJ8 -> 0.11546003 | AM8: 856965433 | AN8: =SUM('Additional 25K H_EX'!AA8+'25K TPP EX'!AA8+'10% Non-Homestead'!AA8+'Portability Impact'!AA8) -> 97784657 | AO8: =AN8/AM8 -> 0.11410572
A9: Brevard | B9: R-NVAB | C9: 46975130599 | D9: =SUM('Additional 25K H_EX'!C9+'25K TPP EX'!C9+'10% Non-Homestead'!C9+'Portability Impact'!C9) -> 5353890537 | E9: =D9/C9 -> 0.11397287 | F9: 43803472075 | G9: =SUM('Additional 25K H_EX'!E9+'25K TPP EX'!E9+'10% Non-Homestead'!E9+'Portability Impact'!E9) -> 5816520031 | H9: =G9/F9 -> 0.13278673 | I9: 40742328549 | J9: =SUM('Additional 25K H_EX'!G9+'25K TPP EX'!G9+'10% Non-Homestead'!G9+'Portability Impact'!G9) -> 5077779529 | K9: =J9/I9 -> 0.12463155 | L9: 37698498609 | M9: =SUM('Additional 25K H_EX'!I9+'25K TPP EX'!I9+'10% Non-Homestead'!I9+'Portability Impact'!I9) -> 4855982360 | N9: =M9/L9 -> 0.12881103 | O9: 34564221486 | P9: =SUM('Additional 25K H_EX'!K9+'25K TPP EX'!K9+'10% Non-Homestead'!K9+'Portability Impact'!K9) -> 4634778421 | Q9: =P9/O9 -> 0.13409179 | R9: 31906496454 | S9: =SUM('Additional 25K H_EX'!M9+'25K TPP EX'!M9+'10% Non-Homestead'!M9+'Portability Impact'!M9) -> 3828787071 | T9: =S9/R9 -> 0.12000023 | U9: 29651180137 | V9: =SUM('Additional 25K H_EX'!O9+'25K TPP EX'!O9+'10% Non-Homestead'!O9+'Portability Impact'!O9) -> 3464540573 | W9: =V9/U9 -> 0.11684326 | X9: 27982368405 | Y9: =SUM('Additional 25K H_EX'!Q9+'25K TPP EX'!Q9+'10% Non-Homestead'!Q9+'Portability Impact'!Q9) -> 3229920243 | Z9: =Y9/X9 -> 0.11542698 | AA9: 25739437801 | AB9: =SUM('Additional 25K H_EX'!S9+'25K TPP EX'!S9+'10% Non-Homestead'!S9+'Portability Impact'!S9) -> 2919342960 | AC9: =AB9/AA9 -> 0.11341906 | AD9: 24622309982 | AE9: =SUM('Additional 25K H_EX'!U9+'25K TPP EX'!U9+'10% Non-Homestead'!U9+'Portability Impact'!U9) -> 2802155215 | AF9: =AE9/AD9 -> 0.11380554 | AG9: 24875931599 | AH9: =SUM('Additional 25K H_EX'!W9+'25K TPP EX'!W9+'10% Non-Homestead'!W9+'Portability Impact'!W9) -> 2897108973 | AI9: =AH9/AG9 -> 0.11646233 | AJ9: 29075661832 | AK9: =SUM('Additional 25K H_EX'!Y9+'25K TPP EX'!Y9+'10% Non-Homestead'!Y9+'Portability Impact'!Y9) -> 3289137207 | AL9: =AK9/AJ9 -> 0.11312338 | AM9: 33298150445 | AN9: =SUM('Additional 25K H_EX'!AA9+'25K TPP EX'!AA9+'10% Non-Homestead'!AA9+'Portability Impact'!AA9) -> 3449370171 | AO9: =AN9/AM9 -> 0.10359044
A10: Broward | B10: R-NVAB | C10: 221522571655 | D10: =SUM('Additional 25K H_EX'!C10+'25K TPP EX'!C10+'10% Non-Homestead'!C10+'Portability Impact'!C10) -> 16513189016 | E10: =D10/C10 -> 0.074544047 | F10: 209533224342 | G10: =SUM('Additional 25K H_EX'!E10+'25K TPP EX'!E10+'10% Non-Homestead'!E10+'Portability Impact'!E10) -> 16110845563 | H10: =G10/F10 -> 0.076889217 | I10: 199031547482 | J10: =SUM('Additional 25K H_EX'!G10+'25K TPP EX'!G10+'10% Non-Homestead'!G10+'Portability Impact'!G10) -> 16762280471 | K10: =J10/I10 -> 0.084219214 | L10: 187787051235 | M10: =SUM('Additional 25K H_EX'!I10+'25K TPP EX'!I10+'10% Non-Homestead'!I10+'Portability Impact'!I10) -> 16328303187 | N10: =M10/L10 -> 0.086951167 | O10: 177102876979 | P10: =SUM('Additional 25K H_EX'!K10+'25K TPP EX'!K10+'10% Non-Homestead'!K10+'Portability Impact'!K10) -> 17227899572 | Q10: =P10/O10 -> 0.097276226 | R10: 162143969028 | S10: =SUM('Additional 25K H_EX'!M10+'25K TPP EX'!M10+'10% Non-Homestead'!M10+'Portability Impact'!M10) -> 16636339804 | T10: =S10/R10 -> 0.10260227 | U10: 149774682202 | V10: =SUM('Additional 25K H_EX'!O10+'25K TPP EX'!O10+'10% Non-Homestead'!O10+'Portability Impact'!O10) -> 14972784356 | W10: =V10/U10 -> 0.099968727 | X10: 139401195926 | Y10: =SUM('Additional 25K H_EX'!Q10+'25K TPP EX'!Q10+'10% Non-Homestead'!Q10+'Portability Impact'!Q10) -> 13452480240 | Z10: =Y10/X10 -> 0.0965019 | AA10: 130735966888 | AB10: =SUM('Additional 25K H_EX'!S10+'25K TPP EX'!S10+'10% Non-Homestead'!S10+'Portability Impact'!S10) -> 10761022187 | AC10: =AB10/AA10 -> 0.082311107 | AD10: 125760535139 | AE10: =SUM('Additional 25K H_EX'!U10+'25K TPP EX'!U10+'10% Non-Homestead'!U10+'Portability Impact'!U10) -> 10365548894 | AF10: =AE10/AD10 -> 0.082422907 | AG10: 124478201073 | AH10: =SUM('Additional 25K H_EX'!W10+'25K TPP EX'!W10+'10% Non-Homestead'!W10+'Portability Impact'!W10) -> 10121399616 | AI10: =AH10/AG10 -> 0.081310619 | AJ10: 126976299960 | AK10: =SUM('Additional 25K H_EX'!Y10+'25K TPP EX'!Y10+'10% Non-Homestead'!Y10+'Portability Impact'!Y10) -> 10008251518 | AL10: =AK10/AJ10 -> 0.078819839 | AM10: 145942238249 | AN10: =SUM('Additional 25K H_EX'!AA10+'25K TPP EX'!AA10+'10% Non-Homestead'!AA10+'Portability Impact'!AA10) -> 10784005968 | AO10: =AN10/AM10 -> 0.073892288
A11: Calhoun | B11: R-Final | C11: 450980818 | D11: =SUM('Additional 25K H_EX'!C11+'25K TPP EX'!C11+'10% Non-Homestead'!C11+'Portability Impact'!C11) -> 43910653 | E11: =D11/C11 -> 0.097367008 | F11: 427733108 | G11: =SUM('Additional 25K H_EX'!E11+'25K TPP EX'!E11+'10% Non-Homestead'!E11+'Portability Impact'!E11) -> 42032107 | H11: =G11/F11 -> 0.098267135 | I11: 385521820 | J11: =SUM('Additional 25K H_EX'!G11+'25K TPP EX'!G11+'10% Non-Homestead'!G11+'Portability Impact'!G11) -> 36880050 | K11: =J11/I11 -> 0.095662679 | L11: 409020225 | M11: =SUM('Additional 25K H_EX'!I11+'25K TPP EX'!I11+'10% Non-Homestead'!I11+'Portability Impact'!I11) -> 40551802 | N11: =M11/L11 -> 0.099143758 | O11: 407951961 | P11: =SUM('Additional 25K H_EX'!K11+'25K TPP EX'!K11+'10% Non-Homestead'!K11+'Portability Impact'!K11) -> 39677362 | Q11: =P11/O11 -> 0.097259888 | R11: 407447269 | S11: =SUM('Additional 25K H_EX'!M11+'25K TPP EX'!M11+'10% Non-Homestead'!M11+'Portability Impact'!M11) -> 39052170 | T11: =S11/R11 -> 0.095845949 | U11: 404735692 | V11: =SUM('Additional 25K H_EX'!O11+'25K TPP EX'!O11+'10% Non-Homestead'!O11+'Portability Impact'!O11) -> 38823752 | W11: =V11/U11 -> 0.095923717 | X11: 393306434 | Y11: =SUM('Additional 25K H_EX'!Q11+'25K TPP EX'!Q11+'10% Non-Homestead'!Q11+'Portability Impact'!Q11) -> 38504535 | Z11: =Y11/X11 -> 0.097899581 | AA11: 390232987 | AB11: =SUM('Additional 25K H_EX'!S11+'25K TPP EX'!S11+'10% Non-Homestead'!S11+'Portability Impact'!S11) -> 39099034 | AC11: =AB11/AA11 -> 0.10019408 | AD11: 400395519 | AE11: =SUM('Additional 25K H_EX'!U11+'25K TPP EX'!U11+'10% Non-Homestead'!U11+'Portability Impact'!U11) -> 39590152 | AF11: =AE11/AD11 -> 0.09887761 | AG11: 364441318 | AH11: =SUM('Additional 25K H_EX'!W11+'25K TPP EX'!W11+'10% Non-Homestead'!W11+'Portability Impact'!W11) -> 39021816 | AI11: =AH11/AG11 -> 0.10707297 | AJ11: 363788518 | AK11: =SUM('Additional 25K H_EX'!Y11+'25K TPP EX'!Y11+'10% Non-Homestead'!Y11+'Portability Impact'!Y11) -> 38615886 | AL11: =AK11/AJ11 -> 0.10614927 | AM11: 357344105 | AN11: =SUM('Additional 25K H_EX'!AA11+'25K TPP EX'!AA11+'10% Non-Homestead'!AA11+'Portability Impact'!AA11) -> 35930484 | AO11: =AN11/AM11 -> 0.1005487
A12: Charlotte | B12: R-NVAB | C12: 20179714013 | D12: =SUM('Additional 25K H_EX'!C12+'25K TPP EX'!C12+'10% Non-Homestead'!C12+'Portability Impact'!C12) -> 2232637319 | E12: =D12/C12 -> 0.11063771 | F12: 18838045279 | G12: =SUM('Additional 25K H_EX'!E12+'25K TPP EX'!E12+'10% Non-Homestead'!E12+'Portability Impact'!E12) -> 2004268510 | H12: =G12/F12 -> 0.10639472 | I12: 17643668832 | J12: =SUM('Additional 25K H_EX'!G12+'25K TPP EX'!G12+'10% Non-Homestead'!G12+'Portability Impact'!G12) -> 1978479927 | K12: =J12/I12 -> 0.1121354 | L12: 16435814856 | M12: =SUM('Additional 25K H_EX'!I12+'25K TPP EX'!I12+'10% Non-Homestead'!I12+'Portability Impact'!I12) -> 2055643099 | N12: =M12/L12 -> 0.12507096 | O12: 15214557093 | P12: =SUM('Additional 25K H_EX'!K12+'25K TPP EX'!K12+'10% Non-Homestead'!K12+'Portability Impact'!K12) -> 1944909271 | Q12: =P12/O12 -> 0.12783213 | R12: 14004316687 | S12: =SUM('Additional 25K H_EX'!M12+'25K TPP EX'!M12+'10% Non-Homestead'!M12+'Portability Impact'!M12) -> 1834295069 | T12: =S12/R12 -> 0.13098069 | U12: 13139696755 | V12: =SUM('Additional 25K H_EX'!O12+'25K TPP EX'!O12+'10% Non-Homestead'!O12+'Portability Impact'!O12) -> 1666104601 | W12: =V12/U12 -> 0.12679932 | X12: 12492377154 | Y12: =SUM('Additional 25K H_EX'!Q12+'25K TPP EX'!Q12+'10% Non-Homestead'!Q12+'Portability Impact'!Q12) -> 1533404165 | Z12: =Y12/X12 -> 0.12274719 | AA12: 12005148792 | AB12: =SUM('Additional 25K H_EX'!S12+'25K TPP EX'!S12+'10% Non-Homestead'!S12+'Portability Impact'!S12) -> 1307705633 | AC12: =AB12/AA12 -> 0.10892873 | AD12: 11749734126 | AE12: =SUM('Additional 25K H_EX'!U12+'25K TPP EX'!U12+'10% Non-Homestead'!U12+'Portability Impact'!U12) -> 1166668838 | AF12: =AE12/AD12 -> 0.099293212 | AG12: 12395018451 | AH12: =SUM('Additional 25K H_EX'!W12+'25K TPP EX'!W12+'10% Non-Homestead'!W12+'Portability Impact'!W12) -> 1124302687 | AI12: =AH12/AG12 -> 0.090706012 | AJ12: 13379662397 | AK12: =SUM('Additional 25K H_EX'!Y12+'25K TPP EX'!Y12+'10% Non-Homestead'!Y12+'Portability Impact'!Y12) -> 1210829440 | AL12: =AK12/AJ12 -> 0.090497757 | AM12: 15588648694 | AN12: =SUM('Additional 25K H_EX'!AA12+'25K TPP EX'!AA12+'10% Non-Homestead'!AA12+'Portability Impact'!AA12) -> 1238837158 | AO12: =AN12/AM12 -> 0.079470465
A13: Citrus | B13: R-NVAB | C13: 11195416635 | D13: =SUM('Additional 25K H_EX'!C13+'25K TPP EX'!C13+'10% Non-Homestead'!C13+'Portability Impact'!C13) -> 1303200477 | E13: =D13/C13 -> 0.11640482 | F13: 10655493324 | G13: =SUM('Additional 25K H_EX'!E13+'25K TPP EX'!E13+'10% Non-Homestead'!E13+'Portability Impact'!E13) -> 1223458497 | H13: =G13/F13 -> 0.11481951 | I13: 10160817278 | J13: =SUM('Additional 25K H_EX'!G13+'25K TPP EX'!G13+'10% Non-Homestead'!G13+'Portability Impact'!G13) -> 1190761744 | K13: =J13/I13 -> 0.11719153 | L13: 9091226499 | M13: =SUM('Additional 25K H_EX'!I13+'25K TPP EX'!I13+'10% Non-Homestead'!I13+'Portability Impact'!I13) -> 1107244259 | N13: =M13/L13 -> 0.12179262 | O13: 8642427953 | P13: =SUM('Additional 25K H_EX'!K13+'25K TPP EX'!K13+'10% Non-Homestead'!K13+'Portability Impact'!K13) -> 1000530687 | Q13: =P13/O13 -> 0.11576963 | R13: 8292626815 | S13: =SUM('Additional 25K H_EX'!M13+'25K TPP EX'!M13+'10% Non-Homestead'!M13+'Portability Impact'!M13) -> 954873408 | T13: =S13/R13 -> 0.11514728 | U13: 8083820200 | V13: =SUM('Additional 25K H_EX'!O13+'25K TPP EX'!O13+'10% Non-Homestead'!O13+'Portability Impact'!O13) -> 855001720 | W13: =V13/U13 -> 0.10576704 | X13: 7856463122 | Y13: =SUM('Additional 25K H_EX'!Q13+'25K TPP EX'!Q13+'10% Non-Homestead'!Q13+'Portability Impact'!Q13) -> 823397101 | Z13: =Y13/X13 -> 0.10480506 | AA13: 8160777743 | AB13: =SUM('Additional 25K H_EX'!S13+'25K TPP EX'!S13+'10% Non-Homestead'!S13+'Portability Impact'!S13) -> 828607954 | AC13: =AB13/AA13 -> 0.10153541 | AD13: 9032362268 | AE13: =SUM('Additional 25K H_EX'!U13+'25K TPP EX'!U13+'10% Non-Homestead'!U13+'Portability Impact'!U13) -> 847653387 | AF13: =AE13/AD13 -> 0.093846257 | AG13: 9316089786 | AH13: =SUM('Additional 25K H_EX'!W13+'25K TPP EX'!W13+'10% Non-Homestead'!W13+'Portability Impact'!W13) -> 878495080 | AI13: =AH13/AG13 -> 0.094298692 | AJ13: 9559999106 | AK13: =SUM('Additional 25K H_EX'!Y13+'25K TPP EX'!Y13+'10% Non-Homestead'!Y13+'Portability Impact'!Y13) -> 922164390 | AL13: =AK13/AJ13 -> 0.096460719 | AM13: 10024972585 | AN13: =SUM('Additional 25K H_EX'!AA13+'25K TPP EX'!AA13+'10% Non-Homestead'!AA13+'Portability Impact'!AA13) -> 988793570 | AO13: =AN13/AM13 -> 0.098633045
A14: Clay | B14: R-NVAB | C14: 13020087703 | D14: =SUM('Additional 25K H_EX'!C14+'25K TPP EX'!C14+'10% Non-Homestead'!C14+'Portability Impact'!C14) -> 1429946378 | E14: =D14/C14 -> 0.10982617 | F14: 12194592179 | G14: =SUM('Additional 25K H_EX'!E14+'25K TPP EX'!E14+'10% Non-Homestead'!E14+'Portability Impact'!E14) -> 1369940663 | H14: =G14/F14 -> 0.11234001 | I14: 11379535331 | J14: =SUM('Additional 25K H_EX'!G14+'25K TPP EX'!G14+'10% Non-Homestead'!G14+'Portability Impact'!G14) -> 1347220481 | K14: =J14/I14 -> 0.11838976 | L14: 10614446287 | M14: =SUM('Additional 25K H_EX'!I14+'25K TPP EX'!I14+'10% Non-Homestead'!I14+'Portability Impact'!I14) -> 1335503259 | N14: =M14/L14 -> 0.1258194 | O14: 9919301689 | P14: =SUM('Additional 25K H_EX'!K14+'25K TPP EX'!K14+'10% Non-Homestead'!K14+'Portability Impact'!K14) -> 1281057558 | Q14: =P14/O14 -> 0.12914796 | R14: 9293061431 | S14: =SUM('Additional 25K H_EX'!M14+'25K TPP EX'!M14+'10% Non-Homestead'!M14+'Portability Impact'!M14) -> 1231051521 | T14: =S14/R14 -> 0.13246996 | U14: 8806329297 | V14: =SUM('Additional 25K H_EX'!O14+'25K TPP EX'!O14+'10% Non-Homestead'!O14+'Portability Impact'!O14) -> 1125847529 | W14: =V14/U14 -> 0.12784527 | X14: 8451515994 | Y14: =SUM('Additional 25K H_EX'!Q14+'25K TPP EX'!Q14+'10% Non-Homestead'!Q14+'Portability Impact'!Q14) -> 1110257724 | Z14: =Y14/X14 -> 0.13136788 | AA14: 8093876706 | AB14: =SUM('Additional 25K H_EX'!S14+'25K TPP EX'!S14+'10% Non-Homestead'!S14+'Portability Impact'!S14) -> 1091365811 | AC14: =AB14/AA14 -> 0.13483845 | AD14: 7925816942 | AE14: =SUM('Additional 25K H_EX'!U14+'25K TPP EX'!U14+'10% Non-Homestead'!U14+'Portability Impact'!U14) -> 1098257779 | AF14: =AE14/AD14 -> 0.13856714 | AG14: 8119776938 | AH14: =SUM('Additional 25K H_EX'!W14+'25K TPP EX'!W14+'10% Non-Homestead'!W14+'Portability Impact'!W14) -> 1119432137 | AI14: =AH14/AG14 -> 0.13786489 | AJ14: 8598848683 | AK14: =SUM('Additional 25K H_EX'!Y14+'25K TPP EX'!Y14+'10% Non-Homestead'!Y14+'Portability Impact'!Y14) -> 1157252035 | AL14: =AK14/AJ14 -> 0.13458221 | AM14: 9356682433 | AN14: =SUM('Additional 25K H_EX'!AA14+'25K TPP EX'!AA14+'10% Non-Homestead'!AA14+'Portability Impact'!AA14) -> 1174858481 | AO14: =AN14/AM14 -> 0.12556357
A15: Collier | B15: R-NVAB | C15: 104679006577 | D15: =SUM('Additional 25K H_EX'!C15+'25K TPP EX'!C15+'10% Non-Homestead'!C15+'Portability Impact'!C15) -> 5147522079 | E15: =D15/C15 -> 0.04917435 | F15: 99159595002 | G15: =SUM('Additional 25K H_EX'!E15+'25K TPP EX'!E15+'10% Non-Homestead'!E15+'Portability Impact'!E15) -> 5267638006 | H15: =G15/F15 -> 0.053122827 | I15: 93175403621 | J15: =SUM('Additional 25K H_EX'!G15+'25K TPP EX'!G15+'10% Non-Homestead'!G15+'Portability Impact'!G15) -> 5373066732 | K15: =J15/I15 -> 0.057666149 | L15: 88274604097 | M15: =SUM('Additional 25K H_EX'!I15+'25K TPP EX'!I15+'10% Non-Homestead'!I15+'Portability Impact'!I15) -> 4625870473 | N15: =M15/L15 -> 0.052403186 | O15: 83597615791 | P15: =SUM('Additional 25K H_EX'!K15+'25K TPP EX'!K15+'10% Non-Homestead'!K15+'Portability Impact'!K15) -> 5518518072 | Q15: =P15/O15 -> 0.066012864 | R15: 77115163725 | S15: =SUM('Additional 25K H_EX'!M15+'25K TPP EX'!M15+'10% Non-Homestead'!M15+'Portability Impact'!M15) -> 5860464402 | T15: =S15/R15 -> 0.075996265 | U15: 70086389131 | V15: =SUM('Additional 25K H_EX'!O15+'25K TPP EX'!O15+'10% Non-Homestead'!O15+'Portability Impact'!O15) -> 4770530276 | W15: =V15/U15 -> 0.06806643 | X15: 64595296747 | Y15: =SUM('Additional 25K H_EX'!Q15+'25K TPP EX'!Q15+'10% Non-Homestead'!Q15+'Portability Impact'!Q15) -> 3478656726 | Z15: =Y15/X15 -> 0.053853096 | AA15: 60637773315 | AB15: =SUM('Additional 25K H_EX'!S15+'25K TPP EX'!S15+'10% Non-Homestead'!S15+'Portability Impact'!S15) -> 2551641076 | AC15: =AB15/AA15 -> 0.042080059 | AD15: 58492762303 | AE15: =SUM('Additional 25K H_EX'!U15+'25K TPP EX'!U15+'10% Non-Homestead'!U15+'Portability Impact'!U15) -> 2356068640 | AF15: =AE15/AD15 -> 0.040279661 | AG15: 58202570727 | AH15: =SUM('Additional 25K H_EX'!W15+'25K TPP EX'!W15+'10% Non-Homestead'!W15+'Portability Impact'!W15) -> 2216781839 | AI15: =AH15/AG15 -> 0.038087353 | AJ15: 61436197437 | AK15: =SUM('Additional 25K H_EX'!Y15+'25K TPP EX'!Y15+'10% Non-Homestead'!Y15+'Portability Impact'!Y15) -> 2235988056 | AL15: =AK15/AJ15 -> 0.036395287 | AM15: 69976749096 | AN15: =SUM('Additional 25K H_EX'!AA15+'25K TPP EX'!AA15+'10% Non-Homestead'!AA15+'Portability Impact'!AA15) -> 2251720030 | AO15: =AN15/AM15 -> 0.032178117
A16: Columbia | B16: R-Final | C16: 3222399320 | D16: =SUM('Additional 25K H_EX'!C16+'25K TPP EX'!C16+'10% Non-Homestead'!C16+'Portability Impact'!C16) -> 326476747 | E16: =D16/C16 -> 0.1013148 | F16: 3035433227 | G16: =SUM('Additional 25K H_EX'!E16+'25K TPP EX'!E16+'10% Non-Homestead'!E16+'Portability Impact'!E16) -> 303657345 | H16: =G16/F16 -> 0.10003756 | I16: 2853296809 | J16: =SUM('Additional 25K H_EX'!G16+'25K TPP EX'!G16+'10% Non-Homestead'!G16+'Portability Impact'!G16) -> 297693413 | K16: =J16/I16 -> 0.10433314 | L16: 2564315570 | M16: =SUM('Additional 25K H_EX'!I16+'25K TPP EX'!I16+'10% Non-Homestead'!I16+'Portability Impact'!I16) -> 275270109 | N16: =M16/L16 -> 0.10734642 | O16: 2409508240 | P16: =SUM('Additional 25K H_EX'!K16+'25K TPP EX'!K16+'10% Non-Homestead'!K16+'Portability Impact'!K16) -> 262007112 | Q16: =P16/O16 -> 0.10873883 | R16: 2336755919 | S16: =SUM('Additional 25K H_EX'!M16+'25K TPP EX'!M16+'10% Non-Homestead'!M16+'Portability Impact'!M16) -> 256596103 | T16: =S16/R16 -> 0.10980869 | U16: 2308305124 | V16: =SUM('Additional 25K H_EX'!O16+'25K TPP EX'!O16+'10% Non-Homestead'!O16+'Portability Impact'!O16) -> 252587129 | W16: =V16/U16 -> 0.10942536 | X16: 2284703454 | Y16: =SUM('Additional 25K H_EX'!Q16+'25K TPP EX'!Q16+'10% Non-Homestead'!Q16+'Portability Impact'!Q16) -> 251685395 | Z16: =Y16/X16 -> 0.11016108 | AA16: 2225505761 | AB16: =SUM('Additional 25K H_EX'!S16+'25K TPP EX'!S16+'10% Non-Homestead'!S16+'Portability Impact'!S16) -> 249220976 | AC16: =AB16/AA16 -> 0.11198397 | AD16: 2211416344 | AE16: =SUM('Additional 25K H_EX'!U16+'25K TPP EX'!U16+'10% Non-Homestead'!U16+'Portability Impact'!U16) -> 255840667 | AF16: =AE16/AD16 -> 0.11569086 | AG16: 2261716683 | AH16: =SUM('Additional 25K H_EX'!W16+'25K TPP EX'!W16+'10% Non-Homestead'!W16+'Portability Impact'!W16) -> 254375130 | AI16: =AH16/AG16 -> 0.11246994 | AJ16: 2446401713 | AK16: =SUM('Additional 25K H_EX'!Y16+'25K TPP EX'!Y16+'10% Non-Homestead'!Y16+'Portability Impact'!Y16) -> 258713810 | AL16: =AK16/AJ16 -> 0.10575279 | AM16: 2547547990 | AN16: =SUM('Additional 25K H_EX'!AA16+'25K TPP EX'!AA16+'10% Non-Homestead'!AA16+'Portability Impact'!AA16) -> 261824829 | AO16: =AN16/AM16 -> 0.10277523
... A71: Washington | B71: R-Final | C71: 997414597 | D71: =SUM('Additional 25K H_EX'!C71+'25K TPP EX'!C71+'10% Non-Homestead'!C71+'Portability Impact'!C71) -> 106318655 | E71: =D71/C71 -> 0.10659424 | F71: 936556912 | G71: =SUM('Additional 25K H_EX'!E71+'25K TPP EX'!E71+'10% Non-Homestead'!E71+'Portability Impact'!E71) -> 91848292 | H71: =G71/F71 -> 0.098070166 | I71: 860691689 | J71: =SUM('Additional 25K H_EX'!G71+'25K TPP EX'!G71+'10% Non-Homestead'!G71+'Portability Impact'!G71) -> 85291270 | K71: =J71/I71 -> 0.099096193 | L71: 851873553 | M71: =SUM('Additional 25K H_EX'!I71+'25K TPP EX'!I71+'10% Non-Homestead'!I71+'Portability Impact'!I71) -> 82880658 | N71: =M71/L71 -> 0.097292207 | O71: 836870735 | P71: =SUM('Additional 25K H_EX'!K71+'25K TPP EX'!K71+'10% Non-Homestead'!K71+'Portability Impact'!K71) -> 78849434 | Q71: =P71/O71 -> 0.094219371 | R71: 829513556 | S71: =SUM('Additional 25K H_EX'!M71+'25K TPP EX'!M71+'10% Non-Homestead'!M71+'Portability Impact'!M71) -> 76498887 | T71: =S71/R71 -> 0.092221383 | U71: 831313165 | V71: =SUM('Additional 25K H_EX'!O71+'25K TPP EX'!O71+'10% Non-Homestead'!O71+'Portability Impact'!O71) -> 74866186 | W71: =V71/U71 -> 0.090057741 | X71: 820800444 | Y71: =SUM('Additional 25K H_EX'!Q71+'25K TPP EX'!Q71+'10% Non-Homestead'!Q71+'Portability Impact'!Q71) -> 73580660 | Z71: =Y71/X71 -> 0.089645005 | AA71: 840623582 | AB71: =SUM('Additional 25K H_EX'!S71+'25K TPP EX'!S71+'10% Non-Homestead'!S71+'Portability Impact'!S71) -> 76784011 | AC71: =AB71/AA71 -> 0.091341729 | AD71: 862044528 | AE71: =SUM('Additional 25K H_EX'!U71+'25K TPP EX'!U71+'10% Non-Homestead'!U71+'Portability Impact'!U71) -> 77410628 | AF71: =AE71/AD71 -> 0.089798874 | AG71: 840210861 | AH71: =SUM('Additional 25K H_EX'!W71+'25K TPP EX'!W71+'10% Non-Homestead'!W71+'Portability Impact'!W71) -> 79257626 | AI71: =AH71/AG71 -> 0.094330637 | AJ71: 932940830 | AK71: =SUM('Additional 25K H_EX'!Y71+'25K TPP EX'!Y71+'10% Non-Homestead'!Y71+'Portability Impact'!Y71) -> 82398133 | AL71: =AK71/AJ71 -> 0.088320856 | AM71: 984696500 | AN71: =SUM('Additional 25K H_EX'!AA71+'25K TPP EX'!AA71+'10% Non-Homestead'!AA71+'Portability Impact'!AA71) -> 75821372 | AO71: =AN71/AM71 -> 0.076999737
A73: Statewide | C73: =SUM(C5:C71) -> 2264115402885 | D73: =SUM(D5:D71) -> 200285917241 | E73: =D73/C73 -> 0.088461002 | F73: =SUM(F5:F71) -> 2120877139351 | G73: =SUM(G5:G71) -> 189911443957 | H73: =G73/F73 -> 0.089543821 | I73: =SUM(I5:I71) -> 1987278938783 | J73: =SUM(J5:J71) -> 191966421525 | K73: =J73/I73 -> 0.096597623 | L73: =SUM(L5:L71) -> 1854829137409 | M73: =SUM(M5:M71) -> 184905847954 | N73: =M73/L73 -> 0.099688885 | O73: =SUM(O5:O71) -> 1729759530907 | P73: =SUM(P5:P71) -> 181030253983 | Q73: =P73/O73 -> 0.10465631 | R73: =SUM(R5:R71) -> 1601817154769 | S73: =SUM(S5:S71) -> 176120810676 | T73: =S73/R73 -> 0.10995063 | U73: =SUM(U5:U71) -> 1487885231904 | V73: =SUM(V5:V71) -> 161874247936 | W73: =V73/U73 -> 0.10879485 | X73: =SUM(X5:X71) -> 1384296817456 | Y73: =SUM(Y5:Y71) -> 134219486721 | Z73: =Y73/X73 -> 0.096958604 | AA73: =SUM(AA5:AA71) -> 1303247963809 | AB73: =SUM(AB5:AB71) -> 111756447044 | AC73: =AB73/AA73 -> 0.085752251 | AD73: =SUM(AD5:AD71) -> 1264228016026 | AE73: =SUM(AE5:AE71) -> 104038479741 | AF73: =AE73/AD73 -> 0.082294079 | AG73: =SUM(AG5:AG71) -> 1275430021160 | AH73: =SUM(AH5:AH71) -> 102234039946 | AI73: =AH73/AG73 -> 0.080156526 | AJ73: =SUM(AJ5:AJ71) -> 1331000184069 | AK73: =SUM(AK5:AK71) -> 104767650017 | AL73: =AK73/AJ73 -> 0.078713475 | AM73: =SUM(AM5:AM71) -> 1499312226307 | AN73: =SUM(AN5:AN71) -> 109763958199 | AO73: =AN73/AM73 -> 0.07320954
A75: Data Extract: November 2021

Sheet Chart1
B1: Summary of 2008 Constitutional Amendment Impact
B2: 2021 Final NAL
B4: County | C4: Status | D4: Total | E4: Additional $25K Exemption | F4: TPP $25K Exemption | G4: 10% Cap | H4: Portability
B5: Statewide | C5: Final | D5: =SUM(E5:H5) -> 200285917241 | E5: ='Amendment 1 Summary'!D73 -> 104297499940 | F5: ='Amendment 1 Summary'!E73 -> 7780543600 | G5: ='Amendment 1 Summary'!F73 -> 82697686688 | H5: ='Amendment 1 Summary'!G73 -> 5510187013
C6: Billions | D6: =D5/1000000000 -> 200.28592 | E6: =E5/1000000000 -> 104.2975 | F6: =F5/1000000000 -> 7.7805436 | G6: =G5/1000000000 -> 82.697687 | H6: =H5/1000000000 -> 5.510187
C7: % | E7: =E5/D5 -> 0.52074305 | F7: =F5/D5 -> 0.038847183 | G7: =G5/D5 -> 0.41289816 | H7: =H5/D5 -> 0.027511605
B8: Data Extract: November 2021

Sheet Chart2
B2: Year | C2: 2009 | D2: 2010 | E2: 2011 | F2: 2012 | G2: 2013 | H2: 2014 | I2: 2015 | J2: 2016 | K2: 2017 | L2: 2018 | M2: 2019 | N2: 2020 | O2: 2021
B3: Total | C3: =SUM(C4:C7) -> 109763958199 | D3: =SUM(D4:D7) -> 104767650017 | E3: =SUM(E4:E7) -> 102234039946 | F3: =SUM(F4:F7) -> 104038479741 | G3: =SUM(G4:G7) -> 111756447044 | H3: =SUM(H4:H7) -> 134219486721 | I3: =SUM(I4:I7) -> 161874247936 | J3: =SUM(J4:J7) -> 176120810676 | ... O3: =SUM(O4:O7) -> 200285917241
B4: Additional $25K Exemption | C4: ='Additional 25K H_EX'!AA73 -> 91832647069 | D4: ='Additional 25K H_EX'!Y73 -> 87962853837 | E4: ='Additional 25K H_EX'!W73 -> 84198498206 | F4: ='Additional 25K H_EX'!U73 -> 81251969966 | G4: ='Additional 25K H_EX'!S73 -> 80691798384 | H4: ='Additional 25K H_EX'!Q73 -> 81390121038 | I4: ='Additional 25K H_EX'!O73 -> 82828511565 | J4: ='Additional 25K H_EX'!M73 -> 85550292030 | K4: ='Additional 25K H_EX'!K73 -> 89053943966 | L4: ='Additional 25K H_EX'!I73 -> 92819831879 | M4: ='Additional 25K H_EX'!G73 -> 96658642921 | N4: ='Additional 25K H_EX'!E73 -> 100699133910 | O4: ='Additional 25K H_EX'!C73 -> 104297499940
B5: TPP $25K Exemption | C5: ='25K TPP EX'!AA73 -> 8448822519 | D5: ='25K TPP EX'!Y73 -> 8098463300 | E5: ='25K TPP EX'!W73 -> 7765836667 | F5: ='25K TPP EX'!U73 -> 7705343193 | G5: ='25K TPP EX'!S73 -> 7716750591 | H5: ='25K TPP EX'!Q73 -> 7772183186 | I5: ='25K TPP EX'!O73 -> 7828525706 | J5: ='25K TPP EX'!M73 -> 7813927621 | K5: ='25K TPP EX'!K73 -> 7775073167 | L5: ='25K TPP EX'!I73 -> 7768664613 | M5: ='25K TPP EX'!G73 -> 7812219947 | N5: ='25K TPP EX'!E73 -> 7860095811 | O5: ='25K TPP EX'!C73 -> 7780543600
B6: 10% Cap | C6: ='10% Non-Homestead'!AA73 -> 7205266094 | D6: ='10% Non-Homestead'!Y73 -> 7671415627 | E6: ='10% Non-Homestead'!W73 -> 9707982064 | F6: ='10% Non-Homestead'!U73 -> 14615646273 | G6: ='10% Non-Homestead'!S73 -> 22840323397 | H6: ='10% Non-Homestead'!Q73 -> 44158789416 | I6: ='10% Non-Homestead'!O73 -> 69462507954 | J6: ='10% Non-Homestead'!M73 -> 79900415651 | K6: ='10% Non-Homestead'!K73 -> 80593934236 | L6: ='10% Non-Homestead'!I73 -> 80107473356 | M6: ='10% Non-Homestead'!G73 -> 82653094157 | N6: ='10% Non-Homestead'!E73 -> 76168336911 | O6: ='10% Non-Homestead'!C73 -> 82697686688
B7: Portability | C7: ='Portability Impact'!AA73 -> 2277222517 | D7: ='Portability Impact'!Y73 -> 1034917253 | E7: ='Portability Impact'!W73 -> 561723009 | F7: ='Portability Impact'!U73 -> 465520309 | G7: ='Portability Impact'!S73 -> 507574672 | H7: ='Portability Impact'!Q73 -> 898393081 | I7: ='Portability Impact'!O73 -> 1754702711 | J7: ='Portability Impact'!M73 -> 2856175374 | K7: ='Portability Impact'!K73 -> 3607302614 | L7: ='Portability Impact'!I73 -> 4209878106 | M7: ='Portability Impact'!G73 -> 4842464500 | N7: ='Portability Impact'!E73 -> 5183877325 | O7: ='Portability Impact'!C73 -> 5510187013
B8: Data Extract: November 2021

Sheet Additional 25K H_EX
A1: Additional $25K Homestead Exemption for Non-School Levies
A2: 2009-2021
A4: County | B4: Status | C4: 2021 Value | D4: Percent increase 2020-2021 | E4: 2020 Value | F4: Percent increase 2019-2020 | G4: 2019 Value | H4: Percent increase 2018-2019 | I4: 2018 Value | J4: Percent increase 2017-2018 | K4: 2017 Value | L4: Percent increase 2016-2017 | M4: 2016 Value | N4: Percent increase 2015-2016 | O4: 2015 Value | P4: Percent increase 2014-2015 | Q4: 2014 Value | R4: Percent increase 2013-2014 | S4: 2013 Value | T4: Percent increase 2012-2013 | U4: 2012 Value | V4: Percent increase 2011-2012 | W4: 2011 Value | X4: Percent increase 2010-2011 | Y4: 2010 Value | Z4: Percent increase 2009-2010 | AA4: 2009 Value
A5: Alachua | B5: R-NVAB | C5: 1136734402 | D5: =C5/E5-1 -> 0.024802819 | E5: 1109222556 | F5: =E5/G5-1 -> 0.032537481 | G5: 1074268563 | H5: =G5/I5-1 -> 0.029505718 | I5: 1043479938 | J5: =I5/K5-1 -> 0.03196404 | K5: 1011159205 | L5: =K5/M5-1 -> 0.035347735 | M5: 976637289 | N5: =M5/O5-1 -> 0.022490572 | O5: 955155300 | P5: =O5/Q5-1 -> 0.008605054 | Q5: 947006260 | R5: =Q5/S5-1 -> -0.0011128184 | S5: 948061280 | T5: =S5/U5-1 -> -0.022976459 | U5: 970356640 | V5: =U5/W5-1 -> -0.018754657 | W5: 988903180 | X5: =W5/Y5-1 -> -0.021338643 | Y5: 1010465135 | Z5: =Y5/AA5-1 -> 0.0084135781 | AA5: 1002034440
A6: Baker | B6: R-Final | C6: 118697611 | D6: =C6/E6-1 -> 0.045710448 | E6: 113509061 | F6: =E6/G6-1 -> 0.050282192 | G6: 108074822 | H6: =G6/I6-1 -> 0.04707638 | I6: 103215796 | J6: =I6/K6-1 -> 0.047853772 | K6: 98502099 | L6: =K6/M6-1 -> 0.04516226 | M6: 94245748 | N6: =M6/O6-1 -> 0.023031569 | O6: 92123988 | P6: =O6/Q6-1 -> 0.0067977875 | Q6: 91501977 | R6: =Q6/S6-1 -> 0.019779312 | S6: 89727234 | T6: =S6/U6-1 -> 0.0022947146 | U6: 89521807 | V6: =U6/W6-1 -> -0.028821263 | W6: 92178508 | X6: =W6/Y6-1 -> 0.009835738 | Y6: 91280695 | Z6: =Y6/AA6-1 -> 0.018260071 | AA6: 89643793
A7: Bay | B7: R-NVAB | C7: 798569920 | D7: =C7/E7-1 -> 0.050158651 | E7: 760427883 | F7: =E7/G7-1 -> 0.019699827 | G7: 745736993 | H7: =G7/I7-1 -> -0.049503795 | I7: 784576508 | J7: =I7/K7-1 -> 0.02981624 | K7: 761860687 | L7: =K7/M7-1 -> 0.025127151 | M7: 743186527 | N7: =M7/O7-1 -> 0.016646177 | O7: 731017874 | P7: =O7/Q7-1 -> 0.0091450325 | Q7: 724393274 | R7: =Q7/S7-1 -> -0.0045340241 | S7: 727692650 | T7: =S7/U7-1 -> -0.015481198 | U7: 739135351 | V7: =U7/W7-1 -> -0.0021640206 | W7: 740738324 | X7: =W7/Y7-1 -> -0.013719499 | Y7: 751042247 | Z7: =Y7/AA7-1 -> -0.0022661234 | AA7: 752748067
A8: Bradford | B8: R-Final | C8: 102353370 | D8: =C8/E8-1 -> 0.054408337 | E8: 97071852 | F8: =E8/G8-1 -> 0.048161288 | G8: 92611560 | H8: =G8/I8-1 -> 0.050209845 | I8: 88183862 | J8: =I8/K8-1 -> 0.049783711 | K8: 84001934 | L8: =K8/M8-1 -> 0.042200933 | M8: 80600517 | N8: =M8/O8-1 -> 0.02347682 | O8: 78751678 | P8: =O8/Q8-1 -> 0.012178725 | Q8: 77804123 | R8: =Q8/S8-1 -> -0.0015895059 | S8: 77927990 | T8: =S8/U8-1 -> -0.038364152 | U8: 81036902 | V8: =U8/W8-1 -> -0.015340019 | W8: 82299376 | X8: =W8/Y8-1 -> -0.021262106 | Y8: 84087248 | Z8: =Y8/AA8-1 -> 0.018746617 | AA8: 82539904
A9: Brevard | B9: R-NVAB | C9: 3505410815 | D9: =C9/E9-1 -> 0.035741003 | E9: 3384447275 | F9: =E9/G9-1 -> 0.043404103 | G9: 3243659160 | H9: =G9/I9-1 -> 0.049876822 | I9: 3089561645 | J9: =I9/K9-1 -> 0.052339425 | K9: 2935898410 | L9: =K9/M9-1 -> 0.049596904 | M9: 2797167560 | N9: =M9/O9-1 -> 0.032369221 | O9: 2709464310 | P9: =O9/Q9-1 -> 0.026887743 | Q9: 2638520450 | R9: =Q9/S9-1 -> 0.020894482 | S9: 2584518280 | T9: =S9/U9-1 -> 0.0064568903 | U9: 2567937390 | V9: =U9/W9-1 -> -0.052133103 | W9: 2709175095 | X9: =W9/Y9-1 -> -0.11322136 | Y9: 3055074830 | Z9: =Y9/AA9-1 -> -0.02792983 | AA9: 3142854215
A10: Broward | B10: R-NVAB | C10: 9083807510 | D10: =C10/E10-1 -> 0.021309977 | E10: 8894270800 | F10: =E10/G10-1 -> 0.029596275 | G10: 8638600410 | H10: =G10/I10-1 -> 0.031851178 | I10: 8371944130 | J10: =I10/K10-1 -> 0.03253422 | K10: 8108151740 | L10: =K10/M10-1 -> 0.029428778 | M10: 7876360090 | N10: =M10/O10-1 -> 0.021468209 | O10: 7710822540 | P10: =O10/Q10-1 -> 0.0087064727 | Q10: 7644267930 | R10: =Q10/S10-1 -> 0.0017707801 | S10: 7630755540 | T10: =S10/U10-1 -> -0.0062426824 | U10: 7678691170 | V10: =U10/W10-1 -> -0.026010305 | W10: 7883749910 | X10: =W10/Y10-1 -> -0.03669245 | Y10: 8184042480 | Z10: =Y10/AA10-1 -> -0.079141959 | AA10: 8887409480
A11: Calhoun | B11: R-Final | C11: 36464601 | D11: =C11/E11-1 -> 0.056968486 | E11: 34499232 | F11: =E11/G11-1 -> 0.11109833 | G11: 31049666 | H11: =G11/I11-1 -> -0.10175049 | I11: 34566861 | J11: =I11/K11-1 -> 0.033564134 | K11: 33444331 | L11: =K11/M11-1 -> 0.02152431 | M11: 32739633 | N11: =M11/O11-1 -> 0.011466995 | O11: 32368464 | P11: =O11/Q11-1 -> 0.011783413 | Q11: 31991495 | R11: =Q11/S11-1 -> -0.012817407 | S11: 32406867 | T11: =S11/U11-1 -> -0.014046855 | U11: 32868567 | V11: =U11/W11-1 -> 0.015596748 | W11: 32363797 | X11: =W11/Y11-1 -> 0.016084048 | Y11: 31851496 | Z11: =Y11/AA11-1 -> 0.075258046 | AA11: 29622188
A12: Charlotte | B12: R-NVAB | C12: 1292277461 | D12: =C12/E12-1 -> 0.057064612 | E12: 1222515110 | F12: =E12/G12-1 -> 0.061025602 | G12: 1152201330 | H12: =G12/I12-1 -> 0.057984949 | I12: 1089052667 | J12: =I12/K12-1 -> 0.060398932 | K12: 1027021656 | L12: =K12/M12-1 -> 0.062094262 | M12: 966977878 | N12: =M12/O12-1 -> 0.061089389 | O12: 911306708 | P12: =O12/Q12-1 -> 0.037391139 | Q12: 878460085 | R12: =Q12/S12-1 -> 0.022146283 | S12: 859426972 | T12: =S12/U12-1 -> -0.0030003423 | U12: 862013307 | V12: =U12/W12-1 -> -0.028045168 | W12: 886886179 | X12: =W12/Y12-1 -> -0.081087524 | Y12: 965147609 | Z12: =Y12/AA12-1 -> -0.080612618 | AA12: 1049772520
A13: Citrus | B13: R-NVAB | C13: 895834284 | D13: =C13/E13-1 -> 0.0544463 | E13: 849577910 | F13: =E13/G13-1 -> 0.068380328 | G13: 795201753 | H13: =G13/I13-1 -> 0.063025756 | I13: 748055020 | J13: =I13/K13-1 -> 0.0554491 | K13: 708755183 | L13: =K13/M13-1 -> 0.050260329 | M13: 674837622 | N13: =M13/O13-1 -> 0.028618891 | O13: 656061859 | P13: =O13/Q13-1 -> 0.0011927385 | Q13: 655280281 | R13: =Q13/S13-1 -> -0.01333146 | S13: 664134159 | T13: =S13/U13-1 -> -0.048242903 | U13: 697797958 | V13: =U13/W13-1 -> -0.072144087 | W13: 752054223 | X13: =W13/Y13-1 -> -0.044364987 | Y13: 786968050 | Z13: =Y13/AA13-1 -> -0.02132556 | AA13: 804116280
A14: Clay | B14: R-NVAB | C14: 1189837997 | D14: =C14/E14-1 -> 0.023274734 | E14: 1162774725 | F14: =E14/G14-1 -> 0.020854411 | G14: 1139021111 | H14: =G14/I14-1 -> 0.024932783 | I14: 1111312986 | J14: =I14/K14-1 -> 0.029711287 | K14: 1079247164 | L14: =K14/M14-1 -> 0.035407787 | M14: 1042340204 | N14: =M14/O14-1 -> 0.019124779 | O14: 1022779767 | P14: =O14/Q14-1 -> 0.0089297893 | Q14: 1013727395 | R14: =Q14/S14-1 -> 0.001369048 | S14: 1012341451 | T14: =S14/U14-1 -> -0.0091334026 | U14: 1021672800 | V14: =U14/W14-1 -> -0.013893076 | W14: 1036066957 | X14: =W14/Y14-1 -> -0.023865091 | Y14: 1061397300 | Z14: =Y14/AA14-1 -> 0.0022089803 | AA14: 1059057862
A15: Collier | B15: R-NVAB | C15: 2363885539 | D15: =C15/E15-1 -> 0.033391585 | E15: 2287502214 | F15: =E15/G15-1 -> 0.03876192 | G15: 2202142926 | H15: =G15/I15-1 -> 0.034622595 | I15: 2128450448 | J15: =I15/K15-1 -> 0.039335684 | K15: 2047895094 | L15: =K15/M15-1 -> 0.02865586 | M15: 1990845698 | N15: =M15/O15-1 -> 0.035356804 | O15: 1922859530 | P15: =O15/Q15-1 -> 0.024466358 | Q15: 1876937700 | R15: =Q15/S15-1 -> 0.014897367 | S15: 1849386707 | T15: =S15/U15-1 -> -0.001622502 | U15: 1852392217 | V15: =U15/W15-1 -> -0.01125676 | W15: 1873481549 | X15: =W15/Y15-1 -> -0.022239239 | Y15: 1916094022 | Z15: =Y15/AA15-1 -> -0.01264713 | AA15: 1940637516
A16: Columbia | B16: R-Final | C16: 267598414 | D16: =C16/E16-1 -> 0.034198919 | E16: 258749462 | F16: =E16/G16-1 -> 0.043667443 | G16: 247923286 | H16: =G16/I16-1 -> 0.05442352 | I16: 235126855 | J16: =I16/K16-1 -> 0.043547802 | K16: 225314887 | L16: =K16/M16-1 -> 0.021771264 | M16: 220514018 | N16: =M16/O16-1 -> 0.0099296937 | O16: 218345910 | P16: =O16/Q16-1 -> 0.0015131503 | Q16: 218016019 | R16: =Q16/S16-1 -> -0.012416662 | S16: 220757085 | T16: =S16/U16-1 -> 0.00060352473 | U16: 220623933 | V16: =U16/W16-1 -> -0.013821156 | W16: 223715946 | X16: =W16/Y16-1 -> -0.010152908 | Y16: 226010611 | Z16: =Y16/AA16-1 -> 0.013390156 | AA16: 223024281
... A71: Washington | B71: R-Final | C71: 80834699 | D71: =C71/E71-1 -> 0.065207675 | E71: 75886328 | F71: =E71/G71-1 -> 0.064139756 | G71: 71312370 | H71: =G71/I71-1 -> 0.033419256 | I71: 69006233 | J71: =I71/K71-1 -> 0.045569564 | K71: 65998701 | L71: =K71/M71-1 -> 0.029324488 | M71: 64118460 | N71: =M71/O71-1 -> 0.015421587 | O71: 63144669 | P71: =O71/Q71-1 -> 0.013372251 | Q71: 62311425 | R71: =Q71/S71-1 -> -0.034059409 | S71: 64508548 | T71: =S71/U71-1 -> -0.0089672432 | U71: 65092246 | V71: =U71/W71-1 -> -0.020399429 | W71: 66447742 | X71: =W71/Y71-1 -> 0.0048303359 | Y71: 66128320 | Z71: =Y71/AA71-1 -> 0.054064708 | AA71: 62736490
A73: Statewide | C73: =SUM(C5:C71) -> 104297499940 | D73: =C73/E73-1 -> 0.035733833 | E73: =SUM(E5:E71) -> 100699133910 | F73: =E73/G73-1 -> 0.041801652 | G73: =SUM(G5:G71) -> 96658642921 | H73: =G73/I73-1 -> 0.04135766 | I73: =SUM(I5:I71) -> 92819831879 | J73: =I73/K73-1 -> 0.042287716 | K73: =SUM(K5:K71) -> 89053943966 | L73: =K73/M73-1 -> 0.040954295 | M73: =SUM(M5:M71) -> 85550292030 | N73: =M73/O73-1 -> 0.03286043 | O73: =SUM(O5:O71) -> 82828511565 | P73: =O73/Q73-1 -> 0.01767279 | Q73: =SUM(Q5:Q71) -> 81390121038 | R73: =Q73/S73-1 -> 0.0086541962 | S73: =SUM(S5:S71) -> 80691798384 | T73: =S73/U73-1 -> -0.0068942523 | U73: =SUM(U5:U71) -> 81251969966 | V73: =U73/W73-1 -> -0.034995021 | W73: =SUM(W5:W71) -> 84198498206 | X73: =W73/Y73-1 -> -0.042794833 | Y73: =SUM(Y5:Y71) -> 87962853837 | Z73: =Y73/AA73-1 -> -0.042139624 | AA73: =SUM(AA5:AA71) -> 91832647069
A75: Data Extract: November 2021

Sheet 25K TPP EX
A1: $25K Tangible Personal Property Exemption
A2: 2009-2021
A4: County | B4: Status | C4: 2021 Value | D4: Percent increase 2020-2021 | E4: 2020 Value | F4: Percent increase 2019-2020 | G4: 2019 Value | H4: Percent increase 2018-2019 | I4: 2018 Value | J4: Percent increase 2017-2018 | K4: 2017 Value | L4: Percent increase 2016-2017 | M4: 2016 Value | N4: Percent increase 2015-2016 | O4: 2015 Value | P4: Percent increase 2014-2015 | Q4: 2014 Value | R4: Percent increase 2013-2014 | S4: 2013 Value | T4: Percent increase 2012-2013 | U4: 2012 Value | V4: Percent increase 2011-2012 | W4: 2011 Value | X4: Percent increase 2010-2011 | Y4: 2010 Value | Z4: Percent increase 2009-2010 | AA4: 2009 Value
A5: Alachua | B5: R-NVAB | C5: 78153825 | D5: =C5/E5-1 -> 0.024741087 | E5: 76266899 | F5: =E5/G5-1 -> -0.028896662 | G5: 78536337 | H5: =G5/I5-1 -> -0.018991004 | I5: 80056694 | J5: =I5/K5-1 -> -0.011990203 | K5: 81028239 | L5: =K5/M5-1 -> 0.0098338494 | M5: 80239179 | N5: =M5/O5-1 -> -0.009179018 | O5: 80982519 | P5: =O5/Q5-1 -> -3.2771431e-05 | Q5: 80985173 | R5: =Q5/S5-1 -> -0.0064718617 | S5: 81512712 | T5: =S5/U5-1 -> 0.0048616625 | U5: 81118342 | V5: =U5/W5-1 -> -0.077316571 | W5: 87915681 | X5: =W5/Y5-1 -> -0.032782804 | Y5: 90895490 | Z5: =Y5/AA5-1 -> -0.079249699 | AA5: 98718936
A6: Baker | B6: R-Final | C6: 6989627 | D6: =C6/E6-1 -> 0.0065059176 | E6: 6944447 | F6: =E6/G6-1 -> -0.072207138 | G6: 7484911 | H6: =G6/I6-1 -> -0.056184486 | I6: 7930481 | J6: =I6/K6-1 -> 0.032584059 | K6: 7680228 | L6: =K6/M6-1 -> 0.022889265 | M6: 7508367 | N6: =M6/O6-1 -> 0.030685132 | O6: 7284831 | P6: =O6/Q6-1 -> 0.0558658 | Q6: 6899391 | R6: =Q6/S6-1 -> -0.01528962 | S6: 7006518 | T6: =S6/U6-1 -> -0.0030357778 | U6: 7027853 | V6: =U6/W6-1 -> -0.32459793 | W6: 10405436 | X6: =W6/Y6-1 -> -0.019326886 | Y6: 10610504 | Z6: =Y6/AA6-1 -> -0.019826463 | AA6: 10825128
A7: Bay | B7: R-NVAB | C7: 82026463 | D7: =C7/E7-1 -> -0.03336873 | E7: 84858069 | F7: =E7/G7-1 -> -0.017403232 | G7: 86361030 | H7: =G7/I7-1 -> -0.062404325 | I7: 92109032 | J7: =I7/K7-1 -> 0.008714869 | K7: 91313249 | L7: =K7/M7-1 -> 0.0093889062 | M7: 90463892 | N7: =M7/O7-1 -> -0.027489024 | O7: 93020947 | P7: =O7/Q7-1 -> 0.014500956 | Q7: 91691335 | R7: =Q7/S7-1 -> -0.046805236 | S7: 96193704 | T7: =S7/U7-1 -> -0.0031142387 | U7: 96494210 | V7: =U7/W7-1 -> -0.018371661 | W7: 98300147 | X7: =W7/Y7-1 -> -0.097029816 | Y7: 108863115 | Z7: =Y7/AA7-1 -> -0.033027096 | AA7: 112581350
A8: Bradford | B8: R-Final | C8: 9169201 | D8: =C8/E8-1 -> -0.0074944487 | E8: 9238438 | F8: =E8/G8-1 -> 0.024777065 | G8: 9015071 | H8: =G8/I8-1 -> 0.021617552 | I8: 8824311 | J8: =I8/K8-1 -> 0.045522958 | K8: 8440093 | L8: =K8/M8-1 -> 0.10126316 | M8: 7664011 | N8: =M8/O8-1 -> -0.046935855 | O8: 8041443 | P8: =O8/Q8-1 -> 0.026507086 | Q8: 7833792 | R8: =Q8/S8-1 -> -0.26968137 | S8: 10726540 | T8: =S8/U8-1 -> -0.058086843 | U8: 11388035 | V8: =U8/W8-1 -> -0.023973262 | W8: 11667749 | X8: =W8/Y8-1 -> -0.026752698 | Y8: 11988473 | Z8: =Y8/AA8-1 -> -0.040665596 | AA8: 12496657
A9: Brevard | B9: R-NVAB | C9: 166343003 | D9: =C9/E9-1 -> -0.0016830945 | E9: 166623446 | F9: =E9/G9-1 -> -0.0054517391 | G9: 167536813 | H9: =G9/I9-1 -> 0.014665127 | I9: 165115375 | J9: =I9/K9-1 -> 0.011428098 | K9: 163249741 | L9: =K9/M9-1 -> -0.016022198 | M9: 165907951 | N9: =M9/O9-1 -> -0.024960915 | O9: 170155180 | P9: =O9/Q9-1 -> -0.0034023622 | Q9: 170736086 | R9: =Q9/S9-1 -> -0.012677639 | S9: 172928410 | T9: =S9/U9-1 -> 0.010351657 | U9: 171156655 | V9: =U9/W9-1 -> 0.051614947 | W9: 162756012 | X9: =W9/Y9-1 -> -0.13216707 | Y9: 187543024 | Z9: =Y9/AA9-1 -> -0.1174121 | AA9: 212492177
A10: Broward | B10: R-NVAB | C10: 807147296 | D10: =C10/E10-1 -> -0.01518762 | E10: 819594993 | F10: =E10/G10-1 -> -0.0032057032 | G10: 822230821 | H10: =G10/I10-1 -> 0.003809001 | I10: 819110827 | J10: =I10/K10-1 -> 0.019644617 | K10: 803329722 | L10: =K10/M10-1 -> -0.0046005899 | M10: 807042594 | N10: =M10/O10-1 -> 0.021863289 | O10: 789775504 | P10: =O10/Q10-1 -> 0.036495842 | Q10: 761966881 | R10: =Q10/S10-1 -> 0.056822055 | S10: 720998277 | T10: =S10/U10-1 -> 0.013494541 | U10: 711398284 | V10: =U10/W10-1 -> -0.017329065 | W10: 723943549 | X10: =W10/Y10-1 -> -0.01384514 | Y10: 734107368 | Z10: =Y10/AA10-1 -> -0.031038743 | AA10: 757623035
A11: Calhoun | B11: R-Final | C11: 5024378 | D11: =C11/E11-1 -> -0.068345028 | E11: 5392960 | F11: =E11/G11-1 -> 0.012308281 | G11: 5327389 | H11: =G11/I11-1 -> 0.0050791751 | I11: 5300467 | J11: =I11/K11-1 -> -0.058364698 | K11: 5629002 | L11: =K11/M11-1 -> 0.015608136 | M11: 5542494 | N11: =M11/O11-1 -> 0.027031003 | O11: 5396618 | P11: =O11/Q11-1 -> -0.0003039869 | Q11: 5398259 | R11: =Q11/S11-1 -> -0.019760378 | S11: 5507081 | T11: =S11/U11-1 -> 0.0011674965 | U11: 5500659 | V11: =U11/W11-1 -> -0.042359212 | W11: 5743969 | X11: =W11/Y11-1 -> 0.015812379 | Y11: 5654557 | Z11: =Y11/AA11-1 -> 0.006478993 | AA11: 5618157
A12: Charlotte | B12: R-NVAB | C12: 98597856 | D12: =C12/E12-1 -> -0.013888788 | E12: 99986548 | F12: =E12/G12-1 -> -0.020340775 | G12: 102062580 | H12: =G12/I12-1 -> -0.016742726 | I12: 103800483 | J12: =I12/K12-1 -> 0.03047744 | K12: 100730476 | L12: =K12/M12-1 -> -0.00065299027 | M12: 100796295 | N12: =M12/O12-1 -> -0.034849227 | O12: 104435802 | P12: =O12/Q12-1 -> 0.004559164 | Q12: 103961823 | R12: =Q12/S12-1 -> -0.17727624 | S12: 126362976 | T12: =S12/U12-1 -> -0.0074524381 | U12: 127311759 | V12: =U12/W12-1 -> 0.015625734 | W12: 125353026 | X12: =W12/Y12-1 -> -0.0096026013 | Y12: 126568412 | Z12: =Y12/AA12-1 -> -0.029813737 | AA12: 130457848
A13: Citrus | B13: R-NVAB | C13: 55066060 | D13: =C13/E13-1 -> 0.051486683 | E13: 52369717 | F13: =E13/G13-1 -> 0.029193 | G13: 50884253 | H13: =G13/I13-1 -> -0.046801935 | I13: 53382665 | J13: =I13/K13-1 -> 0.01792096 | K13: 52442839 | L13: =K13/M13-1 -> -0.0061600339 | M13: 52767891 | N13: =M13/O13-1 -> -0.018763856 | O13: 53776954 | P13: =O13/Q13-1 -> -0.0047433753 | Q13: 54033254 | R13: =Q13/S13-1 -> -0.033957591 | S13: 55932590 | T13: =S13/U13-1 -> -0.057669537 | U13: 59355600 | V13: =U13/W13-1 -> -0.10140971 | W13: 66054130 | X13: =W13/Y13-1 -> -0.061978258 | Y13: 70418549 | Z13: =Y13/AA13-1 -> -0.10474853 | AA13: 78657842
A14: Clay | B14: R-NVAB | C14: 50600521 | D14: =C14/E14-1 -> 0.011947861 | E14: 50003091 | F14: =E14/G14-1 -> 0.0040806125 | G14: 49799877 | H14: =G14/I14-1 -> -0.041240082 | I14: 51941968 | J14: =I14/K14-1 -> 0.026418262 | K14: 50605070 | L14: =K14/M14-1 -> 0.032803744 | M14: 48997760 | N14: =M14/O14-1 -> 0.0079851917 | O14: 48609603 | P14: =O14/Q14-1 -> 0.0006767644 | Q14: 48576728 | R14: =Q14/S14-1 -> 0.0028444467 | S14: 48438946 | T14: =S14/U14-1 -> -0.016339557 | U14: 49243564 | V14: =U14/W14-1 -> -0.027012094 | W14: 50610664 | X14: =W14/Y14-1 -> -0.040006999 | Y14: 52719826 | Z14: =Y14/AA14-1 -> -0.054412685 | AA14: 55753525
A15: Collier | B15: R-NVAB | C15: 162820987 | D15: =C15/E15-1 -> -0.031750114 | E15: 168160089 | F15: =E15/G15-1 -> -0.0085860553 | G15: 169616425 | H15: =G15/I15-1 -> -0.0070090295 | I15: 170813663 | J15: =I15/K15-1 -> -0.052213404 | K15: 180223759 | L15: =K15/M15-1 -> -0.0019383214 | M15: 180573769 | N15: =M15/O15-1 -> -0.0092088051 | O15: 182252093 | P15: =O15/Q15-1 -> -0.015545921 | Q15: 185130111 | R15: =Q15/S15-1 -> -0.075925283 | S15: 200341063 | T15: =S15/U15-1 -> -0.035812489 | U15: 207782263 | V15: =U15/W15-1 -> -0.012072417 | W15: 210321350 | X15: =W15/Y15-1 -> -0.036127706 | Y15: 218204581 | Z15: =Y15/AA15-1 -> -0.045155023 | AA15: 228523568
A16: Columbia | B16: R-Final | C16: 23196763 | D16: =C16/E16-1 -> 0.0048538615 | E16: 23084713 | F16: =E16/G16-1 -> -0.0043629157 | G16: 23185871 | H16: =G16/I16-1 -> -0.0070375417 | I16: 23350199 | J16: =I16/K16-1 -> 0.014414953 | K16: 23018390 | L16: =K16/M16-1 -> 0.0098694663 | M16: 22793431 | N16: =M16/O16-1 -> -0.010393 | O16: 23032811 | P16: =O16/Q16-1 -> -0.0016226961 | Q16: 23070247 | R16: =Q16/S16-1 -> -0.016811575 | S16: 23464726 | T16: =S16/U16-1 -> -0.01621163 | U16: 23851396 | V16: =U16/W16-1 -> -0.02356897 | W16: 24427118 | X16: =W16/Y16-1 -> -0.015416852 | Y16: 24809604 | Z16: =Y16/AA16-1 -> -0.047464478 | AA16: 26045857
... A71: Washington | B71: R-Final | C71: 9713303 | D71: =C71/E71-1 -> -0.0067594085 | E71: 9779406 | F71: =E71/G71-1 -> -0.030633832 | G71: 10088454 | H71: =G71/I71-1 -> -0.0076343207 | I71: 10166065 | J71: =I71/K71-1 -> 0.0078312128 | K71: 10087071 | L71: =K71/M71-1 -> 0.029634945 | M71: 9796745 | N71: =M71/O71-1 -> -0.007867591 | O71: 9874433 | P71: =O71/Q71-1 -> 0.031193434 | Q71: 9575733 | R71: =Q71/S71-1 -> -0.093062473 | S71: 10558316 | T71: =S71/U71-1 -> 0.0021416601 | U71: 10535752 | V71: =U71/W71-1 -> -0.0036591988 | W71: 10574446 | X71: =W71/Y71-1 -> 0.028738576 | Y71: 10279041 | Z71: =Y71/AA71-1 -> -0.0015699543 | AA71: 10295204
A73: Statewide | C73: =SUM(C5:C71) -> 7780543600 | D73: =C73/E73-1 -> -0.010121023 | E73: =SUM(E5:E71) -> 7860095811 | F73: =E73/G73-1 -> 0.0061283303 | G73: =SUM(G5:G71) -> 7812219947 | H73: =G73/I73-1 -> 0.0056065407 | I73: =SUM(I5:I71) -> 7768664613 | J73: =I73/K73-1 -> -0.00082424356 | K73: =SUM(K5:K71) -> 7775073167 | L73: =K73/M73-1 -> -0.0049724615 | M73: =SUM(M5:M71) -> 7813927621 | N73: =M73/O73-1 -> -0.0018647298 | O73: =SUM(O5:O71) -> 7828525706 | P73: =O73/Q73-1 -> 0.0072492527 | Q73: =SUM(Q5:Q71) -> 7772183186 | R73: =Q73/S73-1 -> 0.0071834115 | S73: =SUM(S5:S71) -> 7716750591 | T73: =S73/U73-1 -> 0.0014804529 | U73: =SUM(U5:U71) -> 7705343193 | V73: =U73/W73-1 -> -0.0077896918 | W73: =SUM(W5:W71) -> 7765836667 | X73: =W73/Y73-1 -> -0.041072809 | Y73: =SUM(Y5:Y71) -> 8098463300 | Z73: =Y73/AA73-1 -> -0.041468408 | AA73: =SUM(AA5:AA71) -> 8448822519
A75: Data Extract: November 2021

Sheet 10% Non-Homestead
A1: 10% Non-Homestead Assessment Increase Limitation
A2: 2009-2021
A4: County | B4: Status | C4: 2021 Value | D4: Percent increase 2021-2019 | E4: 2020 Value | F4: Percent increase 2019-2020 | G4: 2019 Value | H4: Percent increase 2018-2019 | I4: 2018 Value | J4: Percent increase 2017-2018 | K4: 2017 Value | L4: Percent increase 2016-2017 | M4: 2016 Value | N4: Percent increase 2015-2016 | O4: 2015 Value | P4: Percent increase 2014-2015 | Q4: 2014 Value | R4: Percent increase 2013-2014 | S4: 2013 Value | T4: Percent increase 2012-2013 | U4: 2012 Value | V4: Percent increase 2011-2012 | W4: 2011 Value | X4: Percent increase 2010-2011 | Y4: 2010 Value | Z4: Percent increase 2009-2010 | AA4: 2009 Value
A5: Alachua | B5: R-NVAB | C5: 1017545800 | D5: =C5/E5-1 -> 0.38862651 | E5: 732771407 | F5: =E5/G5-1 -> -0.23374412 | G5: 956301190 | H5: =G5/I5-1 -> 0.044429634 | I5: 915620506 | J5: =I5/K5-1 -> 0.27999131 | K5: 715333379 | L5: =K5/M5-1 -> 1.9416115 | M5: 243177381 | N5: =M5/O5-1 -> 0.92921319 | O5: 126050030 | P5: =O5/Q5-1 -> 0.11521904 | Q5: 113027150 | R5: =Q5/S5-1 -> -0.49861198 | S5: 225428500 | T5: =S5/U5-1 -> 2.58911 | U5: 62809025 | V5: =U5/W5-1 -> -0.036755 | W5: 65205659 | X5: =W5/Y5-1 -> -0.33933936 | Y5: 98697660 | Z5: =Y5/AA5-1 -> -0.33505556 | AA5: 148429934
A6: Baker | B6: R-Final | C6: 13101813 | D6: =C6/E6-1 -> -0.014093873 | E6: 13289108 | F6: =E6/G6-1 -> 1.2093453 | G6: 6014953 | H6: =G6/I6-1 -> 1.0250185 | I6: 2970320 | J6: =I6/K6-1 -> 0.49737257 | K6: 1983688 | L6: =K6/M6-1 -> 0.042368103 | M6: 1903059 | N6: =M6/O6-1 -> 2.0468005 | O6: 624609 | P6: =O6/Q6-1 -> -0.68020281 | Q6: 1953141 | R6: =Q6/S6-1 -> 2.4656828 | S6: 563566 | T6: =S6/U6-1 -> -0.52991116 | U6: 1198850 | V6: =U6/W6-1 -> 0.37758631 | W6: 870254 | X6: =W6/Y6-1 -> 0.30977135 | Y6: 664432 | Z6: =Y6/AA6-1 -> -0.83365704 | AA6: 3994350
A7: Bay | B7: R-NVAB | C7: 727632472 | D7: =C7/E7-1 -> 0.43692792 | E7: 506380633 | F7: =E7/G7-1 -> 0.60047844 | G7: 316393286 | H7: =G7/I7-1 -> 0.16698232 | I7: 271120891 | J7: =I7/K7-1 -> 0.15436123 | K7: 234866594 | L7: =K7/M7-1 -> 0.28214867 | M7: 183182028 | N7: =M7/O7-1 -> -0.12834537 | O7: 210154369 | P7: =O7/Q7-1 -> 0.040718448 | Q7: 201932011 | R7: =Q7/S7-1 -> 0.31434988 | S7: 153636421 | T7: =S7/U7-1 -> 0.070970372 | U7: 143455342 | V7: =U7/W7-1 -> -0.0089062126 | W7: 144744467 | X7: =W7/Y7-1 -> -0.26651911 | Y7: 197339112 | Z7: =Y7/AA7-1 -> 0.31708053 | AA7: 149830711
