Workbook

Sheet Report Index
A2: Statewide Assessed Value Summary Information by County
B4: Assessed Value is the value of the property with regard to a possible Agricultural classification and any deferred amount accumulated because of Save Our Homes, Amendment 1.
B11: Assessed Value All Property Types
B13: All Property Types Assessed Value and Growth Rate
B15: Real Property Assessed Value and Growth Rate
B17: Personal Property Assessed Value and Growth Rate
B19: Centrally Assessed Property Assessed Value and Growth Rate
A25: Contact Information: | D25: Property Tax Oversight, Research & Analysis
D26: PTOResearchAnalysis@floridarevenue.com

Sheet Assessed Value All Property
A1: Assessed Value All Property Types
A2: 2022
A4: County | B4: Status | C4: 2022 Real Property Assessed Value | D4: 2022 Personal Property Assessed Value | E4: 2022 Central Assessment Assessed Value | F4: 2022 Total Assessed Value
A5: Alachua | B5: R-NVAB | C5: 26685054444 | D5: 4017481347 | E5: 34378880 | F5: 30736914671
A6: Baker | B6: R-Final | C6: 1724620159 | D6: 232449160 | E6: 15120905 | F6: 1972190224
A7: Bay | B7: R-NVAB | C7: 25733447313 | D7: 2150454429 | E7: 36413543 | F7: 27920315285
A8: Bradford | B8: R-Final | C8: 1340206268 | D8: 339661189 | E8: 18871537 | F8: 1698738994
A9: Brevard | B9: R-NVAB | C9: 66811306480 | D9: 10577764678 | E9: 91053009 | F9: 77480124167
A10: Broward | B10: R-NVAB | C10: 282687824110 | D10: 10480265271 | E10: 102789696 | F10: 293270879077
A11: Calhoun | B11: R-Final | C11: 547767097 | D11: 135274404 | E11: 0 | F11: 683041501
A12: Charlotte | B12: R-NVAB | C12: 27699304384 | D12: 1570192818 | E12: 3156640 | F12: 29272653842
A13: Citrus | B13: R-NVAB | C13: 14055532380 | D13: 1966400804 | E13: 1979472 | F13: 16023912656
A14: Clay | B14: R-NVAB | C14: 18261337269 | D14: 1623346507 | E14: 17164212 | F14: 19901847988
A15: Collier | B15: R-NVAB | C15: 131498501684 | D15: 3052292848 | E15: 200286 | F15: 134550994818
A16: Columbia | B16: R-NVAB | C16: 4309602274 | D16: 828685808 | E16: 15263179 | F16: 5153551261
... A71: Washington | B71: R-Final | C71: 1297713936 | D71: 277904053 | E71: 2026994 | F71: 1577644983
A73: Statewide | C73: =SUM(C5:C71) -> 2952234078391 | D73: =SUM(D5:D71) -> 201202778147 | E73: =SUM(E5:E71) -> 1973470795 | F73: =SUM(F5:F71) -> 3155410327333
A75: Data Extract:

Sheet All Property Assessed Value
A1: All Property Types Assessed Value and Growth Rate
A2: 2020-2022
A4: County | B4: Status | C4: 2022 Value | D4: Percent increase 2021-2022 | E4: 2021 Value | F4: Percent increase 2020-2021 | G4: 2020 Value
A5: Alachua | B5: ='Assessed Value All Property'!B5 -> R-NVAB | C5: ='Assessed Value All Property'!F5 -> 30736914671 | D5: =((C5-E5)/E5) -> 0.071677718 | E5: 28681117622 | F5: =((E5-G5)/G5) -> 0.038362956 | G5: 27621476153
A6: Baker | B6: ='Assessed Value All Property'!B6 -> R-Final | C6: ='Assessed Value All Property'!F6 -> 1972190224 | D6: =((C6-E6)/E6) -> 0.11618749 | E6: 1766898692 | F6: =((E6-G6)/G6) -> 0.067385959 | G6: 1655351260
A7: Bay | B7: ='Assessed Value All Property'!B7 -> R-NVAB | C7: ='Assessed Value All Property'!F7 -> 27920315285 | D7: =((C7-E7)/E7) -> 0.13580825 | E7: 24581891590 | F7: =((E7-G7)/G7) -> 0.096191153 | G7: 22424822087
A8: Bradford | B8: ='Assessed Value All Property'!B8 -> R-Final | C8: ='Assessed Value All Property'!F8 -> 1698738994 | D8: =((C8-E8)/E8) -> 0.10911694 | E8: 1531613969 | F8: =((E8-G8)/G8) -> 0.045448008 | G8: 1465031218
A9: Brevard | B9: ='Assessed Value All Property'!B9 -> R-NVAB | C9: ='Assessed Value All Property'!F9 -> 77480124167 | D9: =((C9-E9)/E9) -> 0.11924853 | E9: 69225129520 | F9: =((E9-G9)/G9) -> 0.058888635 | G9: 65375269172
A10: Broward | B10: ='Assessed Value All Property'!B10 -> R-NVAB | C10: ='Assessed Value All Property'!F10 -> 293270879077 | D10: =((C10-E10)/E10) -> 0.10007233 | E10: 266592360661 | F10: =((E10-G10)/G10) -> 0.045409771 | G10: 255012309956
A11: Calhoun | B11: ='Assessed Value All Property'!B11 -> R-Final | C11: ='Assessed Value All Property'!F11 -> 683041501 | D11: =((C11-E11)/E11) -> 0.063022502 | E11: 642546606 | F11: =((E11-G11)/G11) -> 0.043603878 | G11: 615699711
A12: Charlotte | B12: ='Assessed Value All Property'!B12 -> R-NVAB | C12: ='Assessed Value All Property'!F12 -> 29272653842 | D12: =((C12-E12)/E12) -> 0.15807978 | E12: 25276888898 | F12: =((E12-G12)/G12) -> 0.063525231 | G12: 23767079669
A13: Citrus | B13: ='Assessed Value All Property'!B13 -> R-NVAB | C13: ='Assessed Value All Property'!F13 -> 16023912656 | D13: =((C13-E13)/E13) -> 0.079021032 | E13: 14850417349 | F13: =((E13-G13)/G13) -> 0.04474781 | G13: 14214356046
A14: Clay | B14: ='Assessed Value All Property'!B14 -> R-NVAB | C14: ='Assessed Value All Property'!F14 -> 19901847988 | D14: =((C14-E14)/E14) -> 0.11028737 | E14: 17924952139 | F14: =((E14-G14)/G14) -> 0.060740809 | G14: 16898522234
A15: Collier | B15: ='Assessed Value All Property'!B15 -> R-NVAB | C15: ='Assessed Value All Property'!F15 -> 134550994818 | D15: =((C15-E15)/E15) -> 0.15693563 | E15: 116299465171 | F15: =((E15-G15)/G15) -> 0.054575883 | G15: 110280793466
A16: Columbia | B16: ='Assessed Value All Property'!B16 -> R-NVAB | C16: ='Assessed Value All Property'!F16 -> 5153551261 | D16: =((C16-E16)/E16) -> 0.10145603 | E16: 4678853388 | F16: =((E16-G16)/G16) -> 0.073345106 | G16: 4359132364
... A71: Washington | B71: ='Assessed Value All Property'!B71 -> R-Final | C71: ='Assessed Value All Property'!F71 -> 1577644983 | D71: =((C71-E71)/E71) -> 0.086480624 | E71: 1452069138 | F71: =((E71-G71)/G71) -> 0.051260486 | G71: 1381264832
A73: Statewide | C73: =SUM(C5:C72) -> 3155410327333 | D73: =((C73-E73)/E73) -> 0.12973547 | E73: =SUM(E5:E72) -> 2793052364227 | F73: =((E73-G73)/G73) -> 0.058070449 | G73: =SUM(G5:G71) -> 2639760298159
A75: Data Extract:

Sheet Real Property Assessed Value
A1: Real Property Assessed Value and Growth Rate
A2: 2020-2022
A4: County | B4: Status | C4: 2022 Value | D4: Percent increase 2021-2022 | E4: 2021 Value | F4: Percent increase 2020-2021 | G4: 2020 Value
A5: Alachua | B5: ='Assessed Value All Property'!B5 -> R-NVAB | C5: ='Assessed Value All Property'!C5 -> 26685054444 | D5: =((C5-E5)/E5) -> 0.079317364 | E5: 24724011066 | F5: =((E5-G5)/G5) -> 0.045564371 | G5: 23646569968
A6: Baker | B6: ='Assessed Value All Property'!B6 -> R-Final | C6: ='Assessed Value All Property'!C6 -> 1724620159 | D6: =((C6-E6)/E6) -> 0.11981578 | E6: 1540092747 | F6: =((E6-G6)/G6) -> 0.058836825 | G6: 1454513774
A7: Bay | B7: ='Assessed Value All Property'!B7 -> R-NVAB | C7: ='Assessed Value All Property'!C7 -> 25733447313 | D7: =((C7-E7)/E7) -> 0.14617985 | E7: 22451491665 | F7: =((E7-G7)/G7) -> 0.1026315 | G7: 20361736105
A8: Bradford | B8: ='Assessed Value All Property'!B8 -> R-Final | C8: ='Assessed Value All Property'!C8 -> 1340206268 | D8: =((C8-E8)/E8) -> 0.086363081 | E8: 1233663304 | F8: =((E8-G8)/G8) -> 0.042319457 | G8: 1183575051
A9: Brevard | B9: ='Assessed Value All Property'!B9 -> R-NVAB | C9: ='Assessed Value All Property'!C9 -> 66811306480 | D9: =((C9-E9)/E9) -> 0.13390029 | E9: 58921676660 | F9: =((E9-G9)/G9) -> 0.064354268 | G9: 55359083370
A10: Broward | B10: ='Assessed Value All Property'!B10 -> R-NVAB | C10: ='Assessed Value All Property'!C10 -> 282687824110 | D10: =((C10-E10)/E10) -> 0.10232062 | E10: 256447914810 | F10: =((E10-G10)/G10) -> 0.047625597 | G10: 244789661050
A11: Calhoun | B11: ='Assessed Value All Property'!B11 -> R-Final | C11: ='Assessed Value All Property'!C11 -> 547767097 | D11: =((C11-E11)/E11) -> 0.075817903 | E11: 509163396 | F11: =((E11-G11)/G11) -> 0.038778386 | G11: 490155940
A12: Charlotte | B12: ='Assessed Value All Property'!B12 -> R-NVAB | C12: ='Assessed Value All Property'!C12 -> 27699304384 | D12: =((C12-E12)/E12) -> 0.16135257 | E12: 23850900354 | F12: =((E12-G12)/G12) -> 0.07065103 | G12: 22277006867
A13: Citrus | B13: ='Assessed Value All Property'!B13 -> R-NVAB | C13: ='Assessed Value All Property'!C13 -> 14055532380 | D13: =((C13-E13)/E13) -> 0.10914007 | E13: 12672459278 | F13: =((E13-G13)/G13) -> 0.055508393 | G13: 12006024171
A14: Clay | B14: ='Assessed Value All Property'!B14 -> R-NVAB | C14: ='Assessed Value All Property'!C14 -> 18261337269 | D14: =((C14-E14)/E14) -> 0.11548868 | E14: 16370706032 | F14: =((E14-G14)/G14) -> 0.062045204 | G14: 15414321318
A15: Collier | B15: ='Assessed Value All Property'!B15 -> R-NVAB | C15: ='Assessed Value All Property'!C15 -> 131498501684 | D15: =((C15-E15)/E15) -> 0.15894427 | E15: 113464042185 | F15: =((E15-G15)/G15) -> 0.055228537 | G15: 107525562696
A16: Columbia | B16: ='Assessed Value All Property'!B16 -> R-NVAB | C16: ='Assessed Value All Property'!C16 -> 4309602274 | D16: =((C16-E16)/E16) -> 0.084415229 | E16: 3974125555 | F16: =((E16-G16)/G16) -> 0.049187861 | G16: 3787811223
... A71: Washington | B71: ='Assessed Value All Property'!B71 -> R-Final | C71: ='Assessed Value All Property'!C71 -> 1297713936 | D71: =((C71-E71)/E71) -> 0.093195205 | E71: 1187083451 | F71: =((E71-G71)/G71) -> 0.060788253 | G71: 1119057878
A73: Statewide | C73: =SUM(C5:C72) -> 2952234078391 | D73: =((C73-E73)/E73) -> 0.1346799 | E73: =SUM(E5:E72) -> 2601821085158 | F73: =((E73-G73)/G73) -> #DIV/0!
A75: Data Extract:

Sheet Personal Prop Assessed Value
A1: Personal Property Assessed Value and Growth Rate
A2: 2020-2022
A4: County | B4: Status | C4: 2022 Value | D4: Percent increase 2021-2022 | E4: 2021 Value | F4: Percent increase 2020-2021 | G4: 2020 Value
A5: Alachua | B5: ='Assessed Value All Property'!B5 -> R-NVAB | C5: ='Assessed Value All Property'!D5 -> 4017481347 | D5: =((C5-E5)/E5) -> 0.022495772 | E5: 3929093360 | F5: =((E5-G5)/G5) -> -0.003976749 | G5: 3944780763
A6: Baker | B6: ='Assessed Value All Property'!B6 -> R-Final | C6: ='Assessed Value All Property'!D6 -> 232449160 | D6: =((C6-E6)/E6) -> 0.093541373 | E6: 212565492 | F6: =((E6-G6)/G6) -> 0.13163094 | G6: 187839944
A7: Bay | B7: ='Assessed Value All Property'!B7 -> R-NVAB | C7: ='Assessed Value All Property'!D7 -> 2150454429 | D7: =((C7-E7)/E7) -> 0.023855392 | E7: 2100349763 | F7: =((E7-G7)/G7) -> 0.033270699 | G7: 2032719755
A8: Bradford | B8: ='Assessed Value All Property'!B8 -> R-Final | C8: ='Assessed Value All Property'!D8 -> 339661189 | D8: =((C8-E8)/E8) -> 0.21174313 | E8: 280307914 | F8: =((E8-G8)/G8) -> 0.061932637 | G8: 263960165
A9: Brevard | B9: ='Assessed Value All Property'!B9 -> R-NVAB | C9: ='Assessed Value All Property'!D9 -> 10577764678 | D9: =((C9-E9)/E9) -> 0.035121514 | E9: 10218862749 | F9: =((E9-G9)/G9) -> 0.028740356 | G9: 9933374044
A10: Broward | B10: ='Assessed Value All Property'!B10 -> R-NVAB | C10: ='Assessed Value All Property'!D10 -> 10480265271 | D10: =((C10-E10)/E10) -> 0.043196927 | E10: 10046296150 | F10: =((E10-G10)/G10) -> -0.0069915514 | G10: 10117029884
A11: Calhoun | B11: ='Assessed Value All Property'!B11 -> R-Final | C11: ='Assessed Value All Property'!D11 -> 135274404 | D11: =((C11-E11)/E11) -> 0.014178651 | E11: 133383210 | F11: =((E11-G11)/G11) -> 0.062443871 | G11: 125543771
A12: Charlotte | B12: ='Assessed Value All Property'!B12 -> R-NVAB | C12: ='Assessed Value All Property'!D12 -> 1570192818 | D12: =((C12-E12)/E12) -> 0.10345296 | E12: 1422981203 | F12: =((E12-G12)/G12) -> -0.042823319 | G12: 1486644244
A13: Citrus | B13: ='Assessed Value All Property'!B13 -> R-NVAB | C13: ='Assessed Value All Property'!D13 -> 1966400804 | D13: =((C13-E13)/E13) -> -0.096372617 | E13: 2176119097 | F13: =((E13-G13)/G13) -> -0.013885829 | G13: 2206761814
A14: Clay | B14: ='Assessed Value All Property'!B14 -> R-NVAB | C14: ='Assessed Value All Property'!D14 -> 1623346507 | D14: =((C14-E14)/E14) -> 0.055341713 | E14: 1538218841 | F14: =((E14-G14)/G14) -> 0.047547827 | G14: 1468399630
A15: Collier | B15: ='Assessed Value All Property'!B15 -> R-NVAB | C15: ='Assessed Value All Property'!D15 -> 3052292848 | D15: =((C15-E15)/E15) -> 0.076559136 | E15: 2835230083 | F15: =((E15-G15)/G15) -> 0.02911798 | G15: 2755009764
A16: Columbia | B16: ='Assessed Value All Property'!B16 -> R-NVAB | C16: ='Assessed Value All Property'!D16 -> 828685808 | D16: =((C16-E16)/E16) -> 0.20035187 | E16: 690369074 | F16: =((E16-G16)/G16) -> 0.23663241 | G16: 558265388
... A71: Washington | B71: ='Assessed Value All Property'!B71 -> R-Final | C71: ='Assessed Value All Property'!D71 -> 277904053 | D71: =((C71-E71)/E71) -> 0.056514296 | E71: 263038611 | F71: =((E71-G71)/G71) -> 0.010435634 | G71: 260321986
A73: Statewide | C73: =SUM(C5:C71) -> 201202778147 | D73: =((C73-E73)/E73) -> 0.062703746 | E73: =SUM(E5:E71) -> 189331014256 | F73: =((E73-G73)/G73) -> 0.025437222 | G73: =SUM(G5:G71) -> 184634427409
A75: Data Extract:

Sheet Centrally Prop Assessed Value 
A1: Centrally Assessed Property Assessed Value and Growth Rate
A2: 2020-2022
A4: County | B4: Status | C4: 2022 Value | D4: Percent increase 2021-2022 | E4: 2021 Value | F4: Percent increase 2020-2021 | G4: 2020 Value
A5: Alachua | B5: ='Assessed Value All Property'!B5 -> R-NVAB | C5: ='Assessed Value All Property'!E5 -> 34378880 | D5: =((C5-E5)/E5) -> 0.22723876 | E5: 28013196 | F5: =((E5-G5)/G5) -> -0.070114404 | G5: 30125422
A6: Baker | B6: ='Assessed Value All Property'!B6 -> R-Final | C6: ='Assessed Value All Property'!E6 -> 15120905 | D6: =((C6-E6)/E6) -> 0.061827528 | E6: 14240453 | F6: =((E6-G6)/G6) -> 0.095626619 | G6: 12997542
A7: Bay | B7: ='Assessed Value All Property'!B7 -> R-NVAB | C7: ='Assessed Value All Property'!E7 -> 36413543 | D7: =((C7-E7)/E7) -> 0.21175863 | E7: 30050162 | F7: =((E7-G7)/G7) -> -0.010408438 | G7: 30366227
A8: Bradford | B8: ='Assessed Value All Property'!B8 -> R-Final | C8: ='Assessed Value All Property'!E8 -> 18871537 | D8: =((C8-E8)/E8) -> 0.069648208 | E8: 17642751 | F8: =((E8-G8)/G8) -> 0.0083875733 | G8: 17496002
A9: Brevard | B9: ='Assessed Value All Property'!B9 -> R-NVAB | C9: ='Assessed Value All Property'!E9 -> 91053009 | D9: =((C9-E9)/E9) -> 0.076402524 | E9: 84590111 | F9: =((E9-G9)/G9) -> 0.021474644 | G9: 82811758
A10: Broward | B10: ='Assessed Value All Property'!B10 -> R-NVAB | C10: ='Assessed Value All Property'!E10 -> 102789696 | D10: =((C10-E10)/E10) -> 0.047274673 | E10: 98149701 | F10: =((E10-G10)/G10) -> -0.070719468 | G10: 105619022
A11: Calhoun | B11: ='Assessed Value All Property'!B11 -> R-Final | C11: 0 | D11: n/a | E11: 0 | F11: n/a | G11: 0
A12: Charlotte | B12: ='Assessed Value All Property'!B12 -> R-NVAB | C12: ='Assessed Value All Property'!E12 -> 3156640 | D12: =((C12-E12)/E12) -> 0.049644852 | E12: 3007341 | F12: =((E12-G12)/G12) -> -0.12285544 | G12: 3428558
A13: Citrus | B13: ='Assessed Value All Property'!B13 -> R-NVAB | C13: ='Assessed Value All Property'!E13 -> 1979472 | D13: =((C13-E13)/E13) -> 0.07640021 | E13: 1838974 | F13: =((E13-G13)/G13) -> 0.17127551 | G13: 1570061
A14: Clay | B14: ='Assessed Value All Property'!B14 -> R-NVAB | C14: ='Assessed Value All Property'!E14 -> 17164212 | D14: =((C14-E14)/E14) -> 0.070938237 | E14: 16027266 | F14: =((E14-G14)/G14) -> 0.014301368 | G14: 15801286
A15: Collier | B15: ='Assessed Value All Property'!B15 -> R-NVAB | C15: ='Assessed Value All Property'!E15 -> 200286 | D15: =((C15-E15)/E15) -> 0.038273122 | E15: 192903 | F15: =((E15-G15)/G15) -> -0.12715944 | G15: 221006
A16: Columbia | B16: ='Assessed Value All Property'!B16 -> R-NVAB | C16: ='Assessed Value All Property'!E16 -> 15263179 | D16: =((C16-E16)/E16) -> 0.062987338 | E16: 14358759 | F16: =((E16-G16)/G16) -> 0.099803206 | G16: 13055753
A17: Miami-Dade | B17: ='Assessed Value All Property'!B17 -> R-NVAB | C17: ='Assessed Value All Property'!E17 -> 153207013 | D17: =((C17-E17)/E17) -> 0.034091191 | E17: 148156192 | F17: =((E17-G17)/G17) -> -0.011877951 | G17: 149937138
A18: DeSoto | B18: ='Assessed Value All Property'!B18 -> R-NVAB | C18: ='Assessed Value All Property'!E18 -> 4692164 | D18: =((C18-E18)/E18) -> 0.056362821 | E18: 4441811 | F18: =((E18-G18)/G18) -> -0.19991314 | G18: 5551661
A19: Dixie | B19: ='Assessed Value All Property'!B19 -> R-Final | C19: 0 | D19: n/a | E19: 0 | F19: n/a | G19: 0
A20: Duval | B20: ='Assessed Value All Property'!B20 -> R-NVAB | C20: ='Assessed Value All Property'!E20 -> 225501073 | D20: =((C20-E20)/E20) -> 0.013709158 | E20: 222451451 | F20: =((E20-G20)/G20) -> 0.014376381 | G20: 219298729
A21: Escambia | B21: ='Assessed Value All Property'!B21 -> R-NVAB | C21: ='Assessed Value All Property'!E21 -> 31416961 | D21: =((C21-E21)/E21) -> 0.081534709 | E21: 29048500 | F21: =((E21-G21)/G21) -> 0.0062902799 | G21: 28866919
A22: Flagler | B22: ='Assessed Value All Property'!B22 -> R-NVAB | C22: ='Assessed Value All Property'!E22 -> 27574003 | D22: =((C22-E22)/E22) -> 0.08094965 | E22: 25509054 | F22: =((E22-G22)/G22) -> 0.024603239 | G22: 24896519
A23: Franklin | B23: ='Assessed Value All Property'!B23 -> R-Final | C23: ='Assessed Value All Property'!E23 -> 573997 | D23: =((C23-E23)/E23) -> 0.1670662 | E23: 491829 | F23: =((E23-G23)/G23) -> -0.053302946 | G23: 519521
A24: Gadsden | B24: ='Assessed Value All Property'!B24 -> R-Final | C24: ='Assessed Value All Property'!E24 -> 8102682 | D24: =((C24-E24)/E24) -> 0.04973637 | E24: 7718778 | F24: =((E24-G24)/G24) -> 0.03143364 | G24: 7483543
A25: Gilchrist | B25: ='Assessed Value All Property'!B25 -> R-Final | C25: 0 | D25: n/a | E25: 0 | F25: n/a | G25: 0
A26: Glades | B26: ='Assessed Value All Property'!B26 -> R-Final | C26: ='Assessed Value All Property'!E26 -> 18394116 | D26: =((C26-E26)/E26) -> -0.036218496 | E26: 19085359 | F26: =((E26-G26)/G26) -> 0.038248158 | G26: 18382271
A27: Gulf | B27: ='Assessed Value All Property'!B27 -> R-Final | C27: ='Assessed Value All Property'!E27 -> 431138 | D27: =((C27-E27)/E27) -> -0.048722475 | E27: 453220 | F27: =((E27-G27)/G27) -> -0.22097432 | G27: 581778
A28: Hamilton | B28: ='Assessed Value All Property'!B28 -> R-Final | C28: ='Assessed Value All Property'!E28 -> 27559235 | D28: =((C28-E28)/E28) -> 0.069379513 | E28: 25771239 | F28: =((E28-G28)/G28) -> 0.11817418 | G28: 23047607
A29: Hardee | B29: ='Assessed Value All Property'!B29 -> R-NVAB | C29: ='Assessed Value All Property'!E29 -> 9367098 | D29: =((C29-E29)/E29) -> 0.073092568 | E29: 8729068 | F29: =((E29-G29)/G29) -> 0.012120656 | G29: 8624533
A30: Hendry | B30: ='Assessed Value All Property'!B30 -> R-NVAB | C30: ='Assessed Value All Property'!E30 -> 5944780 | D30: =((C30-E30)/E30) -> -0.033742097 | E30: 6152374 | F30: =((E30-G30)/G30) -> 0.035148839 | G30: 5943468
A31: Hernando | B31: ='Assessed Value All Property'!B31 -> R-NVAB | C31: ='Assessed Value All Property'!E31 -> 11986078 | D31: =((C31-E31)/E31) -> 0.092790194 | E31: 10968325 | F31: =((E31-G31)/G31) -> 0.02974309 | G31: 10651516
A32: Highlands | B32: ='Assessed Value All Property'!B32 -> R-NVAB | C32: ='Assessed Value All Property'!E32 -> 38593326 | D32: =((C32-E32)/E32) -> 0.012794675 | E32: 38105775 | F32: =((E32-G32)/G32) -> 0.033742761 | G32: 36861951
A33: Hillsborough | B33: ='Assessed Value All Property'!B33 -> R-NVAB | C33: ='Assessed Value All Property'!E33 -> 133838824 | D33: =((C33-E33)/E33) -> 0.023828338 | E33: 130723891 | F33: =((E33-G33)/G33) -> 0.018383329 | G33: 128364131
A34: Holmes | B34: ='Assessed Value All Property'!B34 -> R-Final | C34: ='Assessed Value All Property'!E34 -> 3710945 | D34: =((C34-E34)/E34) -> 0.04211487 | E34: 3560975 | F34: =((E34-G34)/G34) -> 0.034132117 | G34: 3443443
A35: Indian River | B35: ='Assessed Value All Property'!B35 -> R-NVAB | C35: ='Assessed Value All Property'!E35 -> 26551338 | D35: =((C35-E35)/E35) -> 0.081436363 | E35: 24551919 | F35: =((E35-G35)/G35) -> 0.14252513 | G35: 21489172
A36: Jackson | B36: ='Assessed Value All Property'!B36 -> R-Final | C36: ='Assessed Value All Property'!E36 -> 29027063 | D36: =((C36-E36)/E36) -> 0.16342566 | E36: 24949650 | F36: =((E36-G36)/G36) -> 0.0059224059 | G36: 24802758
A37: Jefferson | B37: ='Assessed Value All Property'!B37 -> R-NVAB | C37: ='Assessed Value All Property'!E37 -> 3032986 | D37: =((C37-E37)/E37) -> 0.04211318 | E37: 2910419 | F37: =((E37-G37)/G37) -> -0.20927955 | G37: 3680718
A38: Lafayette | B38: ='Assessed Value All Property'!B38 -> R-Final | C38: 0 | D38: n/a | E38: 0 | F38: n/a | G38: 0
A39: Lake | B39: ='Assessed Value All Property'!B39 -> R-NVAB | C39: ='Assessed Value All Property'!E39 -> 13139054 | D39: =((C39-E39)/E39) -> -0.34621697 | E39: 20096964 | F39: =((E39-G39)/G39) -> 3.0957106 | G39: 4906832
A40: Lee | B40: ='Assessed Value All Property'!B40 -> R-NVAB | C40: ='Assessed Value All Property'!E40 -> 5393643 | D40: =((C40-E40)/E40) -> 0.038931498 | E40: 5191529 | F40: =((E40-G40)/G40) -> -0.11585858 | G40: 5871831
A41: Leon | B41: ='Assessed Value All Property'!B41 -> R-NVAB | C41: ='Assessed Value All Property'!E41 -> 5757017 | D41: =((C41-E41)/E41) -> 0.039929602 | E41: 5535968 | F41: =((E41-G41)/G41) -> 0.042128515 | G41: 5312174
...
