Workbook

Sheet Report Index
A2: Statewide Just Value Summary Information by County
B4: Just Value is the value of the property without regard to a possible agricultural classification or Save Our Homes Deferred Amount. Just Value is the reflection of the value of land if it were not classified as agricultural and had no SOH deferred amount.
B11: Just Value All Property Types
B13: All Property Types Just Value and Growth Rate
B15: Real Property Just Value and Growth Rate
B17: Personal Property Just Value and Growth Rate
B19: Centrally Assessed Property Just Value and Growth Rate
A25: Contact Information: | D25: Property Tax Oversight, Research & Analysis
D26: PTOResearchAnalysis@floridarevenue.com

Sheet Just Value All Property Types
A1: Just Value All Property Types
A2: 2022
A4: County | B4: Status | C4: 2022 Real Property Just Value | D4: 2022 Personal Property Just Value | E4: 2022 Central Assessment Just Value | F4: 2022 Total Just Value
A5: Alachua | B5: R-NVAB | C5: 33750997228 | D5: 4038801731 | E5: 34378880 | F5: 37824177839
A6: Baker | B6: R-Final | C6: 2570338150 | D6: 232958932 | E6: 15120905 | F6: 2818417987
A7: Bay | B7: R-NVAB | C7: 31391778014 | D7: 2303008079 | E7: 36709300 | F7: 33731495393
A8: Bradford | B8: R-Final | C8: 1923529122 | D8: 342691925 | E8: 18871537 | F8: 2285092584
A9: Brevard | B9: R-NVAB | C9: 96380495090 | D9: 10579694118 | E9: 91053009 | F9: 107051242217
A10: Broward | B10: R-NVAB | C10: 362030883200 | D10: 10606161209 | E10: 102789696 | F10: 372739834105
A11: Calhoun | B11: R-Final | C11: 925699903 | D11: 135274404 | E11: 0 | F11: 1060974307
A12: Charlotte | B12: R-NVAB | C12: 39422846849 | D12: 1570192818 | E12: 3156640 | F12: 40996196307
A13: Citrus | B13: R-NVAB | C13: 19494692315 | D13: 3776194445 | E13: 1979472 | F13: 23272866232
A14: Clay | B14: R-NVAB | C14: 24408288014 | D14: 1626212946 | E14: 17164212 | F14: 26051665172
A15: Collier | B15: R-NVAB | C15: 182257754189 | D15: 3052589486 | E15: 200286 | F15: 185310543961
A16: Columbia | B16: R-NVAB | C16: 5731284880 | D16: 828919195 | E16: 15263179 | F16: 6575467254
... A71: Washington | B71: R-Final | C71: 1916439095 | D71: 277904053 | E71: 2026994 | F71: 2196370142
A73: Statewide | C73: =SUM(C5:C71) -> 3965291697543 | D73: =SUM(D5:D71) -> 207201492799 | E73: =SUM(E5:E71) -> 1975592579 | F73: =SUM(F5:F71) -> 4174468782921
A75: Data Extract: November 2022

Sheet All Property Just Value
A1: All Property Types Just Value and Growth Rate
A2: 2020-2022
A4: County | B4: Status | C4: 2022 Value | D4: Percent increase 2021-2022 | E4: 2021 Value | F4: Percent increase 2020-2021 | G4: 2020 Value
A5: Alachua | B5: ='Just Value All Property Types'!B5 -> R-NVAB | C5: 37824177839 | D5: =((C5-E5)/E5) -> 0.14837885 | E5: 32937020651 | F5: =((E5-G5)/G5) -> 0.066256228 | G5: 30890343028
A6: Baker | B6: ='Just Value All Property Types'!B6 -> R-Final | C6: 2818417987 | D6: =((C6-E6)/E6) -> 0.26015266 | E6: 2236568700 | F6: =((E6-G6)/G6) -> 0.074294972 | G6: 2081894413
A7: Bay | B7: ='Just Value All Property Types'!B7 -> R-NVAB | C7: 33731495393 | D7: =((C7-E7)/E7) -> 0.25552443 | E7: 26866458882 | F7: =((E7-G7)/G7) -> 0.11828328 | G7: 24024734435
A8: Bradford | B8: ='Just Value All Property Types'!B8 -> R-Final | C8: 2285092584 | D8: =((C8-E8)/E8) -> 0.15980653 | E8: 1970236013 | F8: =((E8-G8)/G8) -> 0.090300251 | G8: 1807058203
A9: Brevard | B9: ='Just Value All Property Types'!B9 -> R-NVAB | C9: 107051242217 | D9: =((C9-E9)/E9) -> 0.28793964 | E9: 83118213459 | F9: =((E9-G9)/G9) -> 0.063823788 | G9: 78131561232
A10: Broward | B10: ='Just Value All Property Types'!B10 -> R-NVAB | C10: 372739834105 | D10: =((C10-E10)/E10) -> 0.17281063 | E10: 317817578136 | F10: =((E10-G10)/G10) -> 0.050857103 | G10: 302436532229
A11: Calhoun | B11: ='Just Value All Property Types'!B11 -> R-Final | C11: 1060974307 | D11: =((C11-E11)/E11) -> 0.083182776 | E11: 979497025 | F11: =((E11-G11)/G11) -> 0.025652311 | G11: 954999091
A12: Charlotte | B12: ='Just Value All Property Types'!B12 -> R-NVAB | C12: 40996196307 | D12: =((C12-E12)/E12) -> 0.38216764 | E12: 29660798912 | F12: =((E12-G12)/G12) -> 0.06892393 | G12: 27748278508
A13: Citrus | B13: ='Just Value All Property Types'!B13 -> R-NVAB | C13: 23272866232 | D13: =((C13-E13)/E13) -> 0.18946985 | E13: 19565747150 | F13: =((E13-G13)/G13) -> 0.064042796 | G13: 18388120502
A14: Clay | B14: ='Just Value All Property Types'!B14 -> R-NVAB | C14: 26051665172 | D14: =((C14-E14)/E14) -> 0.2305217 | E14: 21171235899 | F14: =((E14-G14)/G14) -> 0.074907587 | G14: 19695866101
A15: Collier | B15: ='Just Value All Property Types'!B15 -> R-NVAB | C15: 185310543961 | D15: =((C15-E15)/E15) -> 0.40729607 | E15: 131678435379 | F15: =((E15-G15)/G15) -> 0.053965161 | G15: 124936231514
A16: Columbia | B16: ='Just Value All Property Types'!B16 -> R-NVAB | C16: 6575467254 | D16: =((C16-E16)/E16) -> 0.15917646 | E16: 5672533454 | F16: =((E16-G16)/G16) -> 0.08668669 | G16: 5220026625
... A71: Washington | B71: ='Just Value All Property Types'!B71 -> R-Final | C71: 2196370142 | D71: =((C71-E71)/E71) -> 0.1854071 | E71: 1852840377 | F71: =((E71-G71)/G71) -> 0.079797307 | G71: 1715914983
A73: Statewide | C73: =SUM(C5:C71) -> 4174468782921 | D73: =((C73-E73)/E73) -> 0.26217519 | E73: =SUM(E5:E71) -> 3307360841906 | F73: =((E73-G73)/G73) -> 0.068422161 | G73: =SUM(G5:G71) -> 3095556196387
A75: Data Extract:

Sheet Real Property Just Value
A1: Real Property Just Value and Growth Rate
A2: 2020-2022
A4: County | B4: Status | C4: 2022 Value | D4: Percent increase 2021-2022 | E4: 2021 Value | F4: Percent increase 2020-2021 | G4: 2020 Value
A5: Alachua | B5: ='Just Value All Property Types'!B5 -> R-NVAB | C5: 33750997228 | D5: =((C5-E5)/E5) -> 0.16656507 | E5: 28931945787 | F5: =((E5-G5)/G5) -> 0.07619918 | G5: 26883449013
A6: Baker | B6: ='Just Value All Property Types'!B6 -> R-Final | C6: 2570338150 | D6: =((C6-E6)/E6) -> 0.27966986 | E6: 2008594733 | F6: =((E6-G6)/G6) -> 0.067988164 | G6: 1880727522
A7: Bay | B7: ='Just Value All Property Types'!B7 -> R-NVAB | C7: 31391778014 | D7: =((C7-E7)/E7) -> 0.27712325 | E7: 24580069249 | F7: =((E7-G7)/G7) -> 0.12648566 | G7: 21820135130
A8: Bradford | B8: ='Just Value All Property Types'!B8 -> R-Final | C8: 1923529122 | D8: =((C8-E8)/E8) -> 0.15216242 | E8: 1669494760 | F8: =((E8-G8)/G8) -> 0.096975078 | G8: 1521907647
A9: Brevard | B9: ='Just Value All Property Types'!B9 -> R-NVAB | C9: 96380495090 | D9: =((C9-E9)/E9) -> 0.32367712 | E9: 72812692660 | F9: =((E9-G9)/G9) -> 0.068999848 | G9: 68112912060
A10: Broward | B10: ='Just Value All Property Types'!B10 -> R-NVAB | C10: 362030883200 | D10: =((C10-E10)/E10) -> 0.17670211 | E10: 307665704950 | F10: =((E10-G10)/G10) -> 0.052908754 | G10: 292205477290
A11: Calhoun | B11: ='Just Value All Property Types'!B11 -> R-Final | C11: 925699903 | D11: =((C11-E11)/E11) -> 0.094060736 | E11: 846113815 | F11: =((E11-G11)/G11) -> 0.020083656 | G11: 829455320
A12: Charlotte | B12: ='Just Value All Property Types'!B12 -> R-NVAB | C12: 39422846849 | D12: =((C12-E12)/E12) -> 0.39624975 | E12: 28234810368 | F12: =((E12-G12)/G12) -> 0.075275694 | G12: 26258205706
A13: Citrus | B13: ='Just Value All Property Types'!B13 -> R-NVAB | C13: 19494692315 | D13: =((C13-E13)/E13) -> 0.25086744 | E13: 15584938605 | F13: =((E13-G13)/G13) -> 0.080782297 | G13: 14420053551
A14: Clay | B14: ='Just Value All Property Types'!B14 -> R-NVAB | C14: 24408288014 | D14: =((C14-E14)/E14) -> 0.24439622 | E14: 19614563016 | F14: =((E14-G14)/G14) -> 0.077168154 | G14: 18209378858
A15: Collier | B15: ='Just Value All Property Types'!B15 -> R-NVAB | C15: 182257754189 | D15: =((C15-E15)/E15) -> 0.41457448 | E15: 128842811942 | F15: =((E15-G15)/G15) -> 0.054526297 | G15: 122180748172
A16: Columbia | B16: ='Just Value All Property Types'!B16 -> R-NVAB | C16: 5731284880 | D16: =((C16-E16)/E16) -> 0.1538522 | E16: 4967087515 | F16: =((E16-G16)/G16) -> 0.068543334 | G16: 4648466148
... A71: Washington | B71: ='Just Value All Property Types'!B71 -> R-Final | C71: 1916439095 | D71: =((C71-E71)/E71) -> 0.20693607 | E71: 1587854688 | F71: =((E71-G71)/G71) -> 0.092278957 | G71: 1453708027
A73: Statewide | C73: =SUM(C5:C71) -> 3965291697543 | D73: =((C73-E73)/E73) -> 0.27492486 | E73: =SUM(E5:E71) -> 3110216008992 | F73: =((E73-G73)/G73) -> 0.071217111 | G73: =SUM(G5:G71) -> 2903441308463
A75: Data Extract:

Sheet Personal Property Just Value
A1: Personal Property Just Value and Growth Rate
A2: 2020-2022
A4: County | B4: Status | C4: 2022 Value | D4: Percent increase 2021-2022 | E4: 2021 Value | F4: Percent increase 2020-2021 | G4: 2020 Value
A5: Alachua | B5: R-NVAB | C5: 4038801731 | D5: =((C5-E5)/E5) -> 0.01552404 | E5: 3977061668 | F5: =((E5-G5)/G5) -> 7.369677e-05 | G5: 3976768593
A6: Baker | B6: R-Final | C6: 232958932 | D6: =((C6-E6)/E6) -> 0.092222391 | E6: 213288918 | F6: =((E6-G6)/G6) -> 0.13349448 | G6: 188169349
A7: Bay | B7: R-NVAB | C7: 2303008079 | D7: =((C7-E7)/E7) -> 0.022067134 | E7: 2253284548 | F7: =((E7-G7)/G7) -> 0.036358324 | G7: 2174233078
A8: Bradford | B8: R-Final | C8: 342691925 | D8: =((C8-E8)/E8) -> 0.2105042 | E8: 283098502 | F8: =((E8-G8)/G8) -> 0.057701047 | G8: 267654554
A9: Brevard | B9: R-NVAB | C9: 10579694118 | D9: =((C9-E9)/E9) -> 0.035113266 | E9: 10220808159 | F9: =((E9-G9)/G9) -> 0.0286811 | G9: 9935837414
A10: Broward | B10: R-NVAB | C10: 10606161209 | D10: =((C10-E10)/E10) -> 0.05494857 | E10: 10053723485 | F10: =((E10-G10)/G10) -> -0.0070824044 | G10: 10125435917
A11: Calhoun | B11: R-Final | C11: 135274404 | D11: =((C11-E11)/E11) -> 0.014178651 | E11: 133383210 | F11: =((E11-G11)/G11) -> 0.062443871 | G11: 125543771
A12: Charlotte | B12: R-NVAB | C12: 1570192818 | D12: =((C12-E12)/E12) -> 0.10345296 | E12: 1422981203 | F12: =((E12-G12)/G12) -> -0.042823319 | G12: 1486644244
A13: Citrus | B13: R-NVAB | C13: 3776194445 | D13: =((C13-E13)/E13) -> -0.050961718 | E13: 3978969571 | F13: =((E13-G13)/G13) -> 0.0031445079 | G13: 3966496890
A14: Clay | B14: R-NVAB | C14: 1626212946 | D14: =((C14-E14)/E14) -> 0.055539917 | E14: 1540645617 | F14: =((E14-G14)/G14) -> 0.047569408 | G14: 1470685957
A15: Collier | B15: R-NVAB | C15: 3052589486 | D15: =((C15-E15)/E15) -> 0.076587647 | E15: 2835430534 | F15: =((E15-G15)/G15) -> 0.029096394 | G15: 2755262336
A16: Columbia | B16: R-NVAB | C16: 828919195 | D16: =((C16-E16)/E16) -> 0.20027382 | E16: 690608410 | F16: =((E16-G16)/G16) -> 0.23653101 | G16: 558504724
... A71: Washington | B71: R-Final | C71: 277904053 | D71: =((C71-E71)/E71) -> 0.056514296 | E71: 263038611 | F71: =((E71-G71)/G71) -> 0.010435634 | G71: 260321986
A73: Statewide | C73: =SUM(C5:C71) -> 207201492799 | D73: =((C73-E73)/E73) -> 0.061301189 | E73: =SUM(E5:E71) -> 195233450092 | F73: =((E73-G73)/G73) -> 0.026066167 | G73: =SUM(G5:G71) -> 190273742844
A75: Data Extract:

Sheet Centrally Assessed Just Value 
A1: Centrally Assessed Property Just Value and Growth Rate
A2: 2020-2022
A4: County | B4: Status | C4: 2022 Value | D4: Percent increase 2021-2022 | E4: 2021 Value | F4: Percent increase 2020-2021 | G4: 2020 Value
A5: Alachua | B5: R-NVAB | C5: 34378880 | D5: =((C5-E5)/E5) -> 0.22723876 | E5: 28013196 | F5: =((E5-G5)/G5) -> -0.070114404 | G5: 30125422
A6: Baker | B6: R-Final | C6: 15120905 | D6: =((C6-E6)/E6) -> 0.029680255 | E6: 14685049 | F6: =((E6-G6)/G6) -> 0.12983278 | G6: 12997542
A7: Bay | B7: R-NVAB | C7: 36709300 | D7: =((C7-E7)/E7) -> 0.10887195 | E7: 33105085 | F7: =((E7-G7)/G7) -> 0.090194215 | G7: 30366227
A8: Bradford | B8: R-Final | C8: 18871537 | D8: =((C8-E8)/E8) -> 0.069648208 | E8: 17642751 | F8: =((E8-G8)/G8) -> 0.0083875733 | G8: 17496002
A9: Brevard | B9: R-NVAB | C9: 91053009 | D9: =((C9-E9)/E9) -> 0.074845607 | E9: 84712640 | F9: =((E9-G9)/G9) -> 0.022954252 | G9: 82811758
A10: Broward | B10: R-NVAB | C10: 102789696 | D10: =((C10-E10)/E10) -> 0.047274673 | E10: 98149701 | F10: =((E10-G10)/G10) -> -0.070719468 | G10: 105619022
A11: Calhoun | B11: R-Final | C11: 0 | D11: n/a | E11: 0 | F11: n/a | G11: 0
A12: Charlotte | B12: R-NVAB | C12: 3156640 | D12: =((C12-E12)/E12) -> 0.049644852 | E12: 3007341 | F12: =((E12-G12)/G12) -> -0.12285544 | G12: 3428558
A13: Citrus | B13: R-NVAB | C13: 1979472 | D13: =((C13-E13)/E13) -> 0.07640021 | E13: 1838974 | F13: =((E13-G13)/G13) -> 0.17127551 | G13: 1570061
A14: Clay | B14: R-NVAB | C14: 17164212 | D14: =((C14-E14)/E14) -> 0.070938237 | E14: 16027266 | F14: =((E14-G14)/G14) -> 0.014301368 | G14: 15801286
A15: Collier | B15: R-NVAB | C15: 200286 | D15: =((C15-E15)/E15) -> 0.038273122 | E15: 192903 | F15: =((E15-G15)/G15) -> -0.12715944 | G15: 221006
A16: Columbia | B16: R-NVAB | C16: 15263179 | D16: =((C16-E16)/E16) -> 0.028687391 | E16: 14837529 | F16: =((E16-G16)/G16) -> 0.1364744 | G16: 13055753
A17: Miami-Dade | B17: R-NVAB | C17: 153207013 | D17: =((C17-E17)/E17) -> 0.033890479 | E17: 148184954 | F17: =((E17-G17)/G17) -> -0.011686124 | G17: 149937138
A18: DeSoto | B18: R-NVAB | C18: 4692164 | D18: =((C18-E18)/E18) -> 0.056362821 | E18: 4441811 | F18: =((E18-G18)/G18) -> -0.19991314 | G18: 5551661
A19: Dixie | B19: R-Final | C19: 0 | D19: n/a | E19: 0 | F19: n/a | G19: 0
A20: Duval | B20: R-NVAB | C20: 225918484 | D20: =((C20-E20)/E20) -> 0.0075878448 | E20: 224217159 | F20: =((E20-G20)/G20) -> 0.022427991 | G20: 219298729
A21: Escambia | B21: R-NVAB | C21: 31416961 | D21: =((C21-E21)/E21) -> 0.081534709 | E21: 29048500 | F21: =((E21-G21)/G21) -> 0.0062902799 | G21: 28866919
A22: Flagler | B22: R-NVAB | C22: 27574003 | D22: =((C22-E22)/E22) -> 0.08094965 | E22: 25509054 | F22: =((E22-G22)/G22) -> 0.024603239 | G22: 24896519
A23: Franklin | B23: R-Final | C23: 696583 | D23: =((C23-E23)/E23) -> 0.33031144 | E23: 523624 | F23: =((E23-G23)/G23) -> 0.0078976596 | G23: 519521
A24: Gadsden | B24: R-Final | C24: 8192564 | D24: =((C24-E24)/E24) -> 0.058184927 | E24: 7742091 | F24: =((E24-G24)/G24) -> 0.034548876 | G24: 7483543
A25: Gilchrist | B25: R-Final | C25: 0 | D25: n/a | E25: 0 | F25: n/a | G25: 0
A26: Glades | B26: R-Final | C26: 18394116 | D26: =((C26-E26)/E26) -> -0.036218496 | E26: 19085359 | F26: =((E26-G26)/G26) -> 0.038248101 | G26: 18382272
A27: Gulf | B27: R-Final | C27: 695174 | D27: =((C27-E27)/E27) -> 0.18361739 | E27: 587330 | F27: =((E27-G27)/G27) -> 0.0095431591 | G27: 581778
A28: Hamilton | B28: R-Final | C28: 27559235 | D28: =((C28-E28)/E28) -> 0.026443039 | E28: 26849259 | F28: =((E28-G28)/G28) -> 0.1649478 | G28: 23047607
A29: Hardee | B29: R-NVAB | C29: 9367098 | D29: =((C29-E29)/E29) -> 0.073092568 | E29: 8729068 | F29: =((E29-G29)/G29) -> 0.012120656 | G29: 8624533
A30: Hendry | B30: R-NVAB | C30: 5944780 | D30: =((C30-E30)/E30) -> -0.033742097 | E30: 6152374 | F30: =((E30-G30)/G30) -> 0.035148839 | G30: 5943468
A31: Hernando | B31: R-NVAB | C31: 11986078 | D31: =((C31-E31)/E31) -> 0.092790194 | E31: 10968325 | F31: =((E31-G31)/G31) -> 0.02974309 | G31: 10651516
A32: Highlands | B32: R-NVAB | C32: 38593326 | D32: =((C32-E32)/E32) -> 0.012794675 | E32: 38105775 | F32: =((E32-G32)/G32) -> 0.033742761 | G32: 36861951
A33: Hillsborough | B33: R-NVAB | C33: 133838824 | D33: =((C33-E33)/E33) -> 0.023828338 | E33: 130723891 | F33: =((E33-G33)/G33) -> 0.018383329 | G33: 128364131
A34: Holmes | B34: R-Final | C34: 3710945 | D34: =((C34-E34)/E34) -> 0.04211487 | E34: 3560975 | F34: =((E34-G34)/G34) -> 0.034132117 | G34: 3443443
A35: Indian River | B35: R-NVAB | C35: 26551338 | D35: =((C35-E35)/E35) -> 0.081436363 | E35: 24551919 | F35: =((E35-G35)/G35) -> 0.14252513 | G35: 21489172
A36: Jackson | B36: R-Final | C36: 29214746 | D36: =((C36-E36)/E36) -> 0.086519058 | E36: 26888388 | F36: =((E36-G36)/G36) -> 0.084088501 | G36: 24802761
A37: Jefferson | B37: R-NVAB | C37: 3032986 | D37: =((C37-E37)/E37) -> 0.04211318 | E37: 2910419 | F37: =((E37-G37)/G37) -> -0.20927955 | G37: 3680718
A38: Lafayette | B38: R-Final | C38: 0 | D38: n/a | E38: 0 | F38: n/a | G38: 0
A39: Lake | B39: R-NVAB | C39: 13139054 | D39: =((C39-E39)/E39) -> -0.34621697 | E39: 20096964 | F39: =((E39-G39)/G39) -> 1.8955754 | G39: 6940577
A40: Lee | B40: R-NVAB | C40: 5393643 | D40: =((C40-E40)/E40) -> 0.038931498 | E40: 5191529 | F40: =((E40-G40)/G40) -> -0.11585858 | G40: 5871831
A41: Leon | B41: R-NVAB | C41: 5757017 | D41: =((C41-E41)/E41) -> 0.039929602 | E41: 5535968 | F41: =((E41-G41)/G41) -> 0.042128515 | G41: 5312174
...
